Workbook
Name SegmentaciónDeDatos_Split: #N/A
Name SegmentaciónDeDatos_Split1: #N/A
Name SegmentaciónDeDatos_Split11: #N/A
Name SegmentaciónDeDatos_Split2: #N/A
Name SegmentaciónDeDatos_Station: #N/A
Name SegmentaciónDeDatos_Station1: #N/A
Name SegmentaciónDeDatos_Station11: #N/A

Sheet Dynamic Split
AD1: Alphabetical Order
A2: From: Split-Station: | AD2: Site
I3: Searched Site: | L3: Serached Site: | M3: (AS) Koons Tysons Toyota - UC Recon (NO TOURS) | O3: FRIDAY Monitoring Split | AD3: (AS) Coggin Honda of Orlando (NO TOURS)
AD4: (AS) Kahlo CDJR (NO TOURS)
I5: Its On: | L5: Station | M5: =+L5 -> Station | AD5: (AS) Koons Arlington Toyota - New Car (NO TOURS)
L6: 1 | M6: =+L6 -> 1 | AD6: (AS) Koons Baltimore Ford - Main Dealership (NO TOURS)
AD7: (AS) Koons Chevrolet Buick GMC - Tysons Remote Lot (NO TOURS)
AD8: (AS) Koons Easton Toyota - Main Dealership (NO TOURS)
AD9: (AS) Koons Volvo Cars White Marsh (NO TOURS)
AD10: (DT) Modesto
AD11: (LT) Landers Kia of Little Rock
AD12: (LT) Luther Bloomington Subaru - Acura
AD13: (LT) Luther Hopkins Honda (NO TOURS)
AD14: (LT) Luther North Country Ford
A15: Split | B15: Station | C15: Total Sites | G15: Log Out from | H15: Total New Sites | AD15: (SCH) Schumacher of Delray I & III
A16: 4 | B16: 4 | C16: 13 | G16: =+COUNTIF('Dynamic Split'!G19:G75,"Log Out") -> 13 | H16: =+GETPIVOTDATA("Site",$C$15)-G16 -> 0
A18: Split | B18: Log Time | C18: Sites | D18: Drop time | E18: ID | F18: Suma de Station | G18: Log Out | H18: SIG Tools | J18: Split | K18: Log Time | L18: Sites | M18: Drop time | N18: Time Zone | O18: SUNDAY (D.T.) | P18: Gates | Q18: Entrances | R18: LPR | S18: PTZ | T18: Important Cameras | U18: Sum of Station
A19: 4 | B19: 8:00 P.M. | C19: (LT) Luther Bloomington Subaru - Acura | D19: 4:00 A.M. | E19: 289 | F19: 4 | G19: =+IF(C19="","",IFERROR(IF(Maestra!A16="#N/D","Log Out",""),"Log Out")) -> Log Out | H19: =IFERROR(HYPERLINK(VLOOKUP(C19,'Flat Base'!D:J,6,0),"SIG TOOLS"),"") -> SIG TOOLS | I19: =IFERROR(HYPERLINK(VLOOKUP(C19,'Flat Base'!D:J,4,0),"SITE MAP"),"") -> SITE MAP | J19: 4 | K19: 8:00 P.M. | L19: (LT) Luther Bloomington Subaru - Acura | M19: 4:00 A.M. | N19: CT | O19: - | P19: 29 | Q19: 5, 8, 33 | R19: 4, 7, 35 | S19: - | T19: 1, 2, 14, 24, 34 | U19: 4
C20: (LT) Luther Hopkins Honda (NO TOURS) | D20: 6:00 A.M. | E20: 288 | F20: 4 | G20: =+IF(C20="","",IFERROR(IF(Maestra!A17="#N/D","Log Out",""),"Log Out")) -> Log Out | H20: =IFERROR(HYPERLINK(VLOOKUP(C20,'Flat Base'!D:J,6,0),"SIG TOOLS"),"") -> SIG TOOLS | I20: =IFERROR(HYPERLINK(VLOOKUP(C20,'Flat Base'!D:J,4,0),"SITE MAP"),"") -> SITE MAP | L20: (LT) Luther Hopkins Honda (NO TOURS) | M20: 6:00 A.M. | N20: CT | O20: - | P20: - | Q20: 9, 36 | R20: 38, 39 | S20: 3, 26 | T20: 1, 4, 11, 18, 23, 25, 31 | U20: 4
B21: 9:00 P.M. | C21: (AS) Koons Baltimore Ford - Main Dealership (NO TOURS) | D21: 5:00 A.M. | E21: 335 | F21: 4 | G21: =+IF(C21="","",IFERROR(IF(Maestra!A18="#N/D","Log Out",""),"Log Out")) -> Log Out | H21: =IFERROR(HYPERLINK(VLOOKUP(C21,'Flat Base'!D:J,6,0),"SIG TOOLS"),"") -> SIG TOOLS | I21: =IFERROR(HYPERLINK(VLOOKUP(C21,'Flat Base'!D:J,4,0),"SITE MAP"),"") -> SITE MAP | K21: 9:00 P.M. | L21: (AS) Koons Baltimore Ford - Main Dealership (NO TOURS) | M21: 5:00 A.M. | N21: ET | O21: - | P21: 21, 22, 24, 32, 45 | Q21: 1 | R21: - | S21: 1, 8 | T21: 5, 28, 38 | U21: 4
C22: (AS) Koons Chevrolet Buick GMC - Tysons Remote Lot (NO TOURS) | D22: 5:00 A.M. | E22: 333 | F22: 4 | G22: =+IF(C22="","",IFERROR(IF(Maestra!A19="#N/D","Log Out",""),"Log Out")) -> Log Out | H22: =IFERROR(HYPERLINK(VLOOKUP(C22,'Flat Base'!D:J,6,0),"SIG TOOLS"),"") -> SIG TOOLS | I22: =IFERROR(HYPERLINK(VLOOKUP(C22,'Flat Base'!D:J,4,0),"SITE MAP"),"") -> SITE MAP | L22: (AS) Koons Chevrolet Buick GMC - Tysons Remote Lot (NO TOURS) | M22: 5:00 A.M. | N22: ET | O22: - | P22: - | Q22: 6 | R22: 1, 2, 3 | S22: 7, 10, 16, 29 | T22: 14, 17, 30 | U22: 4
C23: (AS) Koons Arlington Toyota - New Car (NO TOURS) | D23: 5:00 A.M. | E23: 334 | F23: 4 | G23: =+IF(C23="","",IFERROR(IF(Maestra!A20="#N/D","Log Out",""),"Log Out")) -> Log Out | H23: =IFERROR(HYPERLINK(VLOOKUP(C23,'Flat Base'!D:J,6,0),"SIG TOOLS"),"") -> SIG TOOLS | I23: =IFERROR(HYPERLINK(VLOOKUP(C23,'Flat Base'!D:J,4,0),"SITE MAP"),"") -> SITE MAP | L23: (AS) Koons Arlington Toyota - New Car (NO TOURS) | M23: 5:00 A.M. | N23: ET | O23: 10:00 A.M. | P23: - | Q23: 1, 3, 12, 15, 17 | R23: - | S23: - | T23: 2, 6, 18, 20 | U23: 4
C24: (AS) Koons Volvo Cars White Marsh (NO TOURS) | D24: 5:00 A.M. | E24: 338 | F24: 4 | G24: =+IF(C24="","",IFERROR(IF(Maestra!A21="#N/D","Log Out",""),"Log Out")) -> Log Out | H24: =IFERROR(HYPERLINK(VLOOKUP(C24,'Flat Base'!D:J,6,0),"SIG TOOLS"),"") -> SIG TOOLS | I24: =IFERROR(HYPERLINK(VLOOKUP(C24,'Flat Base'!D:J,4,0),"SITE MAP"),"") -> SITE MAP | L24: (AS) Koons Volvo Cars White Marsh (NO TOURS) | M24: 5:00 A.M. | N24: ET | O24: - | P24: - | Q24: 5, 7, 9 | R24: - | S24: - | T24: 6, 10, 1 | U24: 4
C25: (AS) Coggin Honda of Orlando (NO TOURS) | D25: 5:00 A.M. | E25: 324 | F25: 4 | G25: =+IF(C25="","",IFERROR(IF(Maestra!A22="#N/D","Log Out",""),"Log Out")) -> Log Out | H25: =IFERROR(HYPERLINK(VLOOKUP(C25,'Flat Base'!D:J,6,0),"SIG TOOLS"),"") -> SIG TOOLS | I25: =IFERROR(HYPERLINK(VLOOKUP(C25,'Flat Base'!D:J,4,0),"SITE MAP"),"") -> SITE MAP | L25: (AS) Coggin Honda of Orlando (NO TOURS) | M25: 5:00 A.M. | N25: ET | O25: 11:00 A.M. | P25: 2, 10, 12B, 14, 38 | Q25: - | R25: - | S25: 12, 31 | T25: 12B, 26, 37, 19 | U25: 4
C26: (AS) Kahlo CDJR (NO TOURS) | D26: 5:00 A.M. | E26: 282 | F26: 4 | G26: =+IF(C26="","",IFERROR(IF(Maestra!A23="#N/D","Log Out",""),"Log Out")) -> Log Out | H26: =IFERROR(HYPERLINK(VLOOKUP(C26,'Flat Base'!D:J,6,0),"SIG TOOLS"),"") -> SIG TOOLS | I26: =IFERROR(HYPERLINK(VLOOKUP(C26,'Flat Base'!D:J,4,0),"SITE MAP"),"") -> SITE MAP | L26: (AS) Kahlo CDJR (NO TOURS) | M26: 5:00 A.M. | N26: ET | O26: - | P26: - | Q26: 12, 25 | R26: 15, 16 | S26: 20 | T26: 1, 2, 9, 22, 31, 57 | U26: 4
C27: (SCH) Schumacher of Delray I & III | D27: 5:00 A.M. | E27: 159 | F27: 4 | G27: =+IF(C27="","",IFERROR(IF(Maestra!A24="#N/D","Log Out",""),"Log Out")) -> Log Out | H27: =IFERROR(HYPERLINK(VLOOKUP(C27,'Flat Base'!D:J,6,0),"SIG TOOLS"),"") -> SIG TOOLS | I27: =IFERROR(HYPERLINK(VLOOKUP(C27,'Flat Base'!D:J,4,0),"SITE MAP"),"") -> SITE MAP | L27: (SCH) Schumacher of Delray I & III | M27: 5:00 A.M. | N27: ET | O27: 11:00 A.M. | P27: 11, 21, 22, 57, 69 | Q27: 2, 16, 46 | R27: - | S27: - | T27: 24, 39 | U27: 4
C28: (AS) Koons Easton Toyota - Main Dealership (NO TOURS) | D28: 5:00 A.M. | E28: 340 | F28: 4 | G28: =+IF(C28="","",IFERROR(IF(Maestra!A25="#N/D","Log Out",""),"Log Out")) -> Log Out | H28: =IFERROR(HYPERLINK(VLOOKUP(C28,'Flat Base'!D:J,6,0),"SIG TOOLS"),"") -> SIG TOOLS | I28: =IFERROR(HYPERLINK(VLOOKUP(C28,'Flat Base'!D:J,4,0),"SITE MAP"),"") -> SITE MAP | L28: (AS) Koons Easton Toyota - Main Dealership (NO TOURS) | M28: 5:00 A.M. | N28: ET | O28: - | P28: - | Q28: 4, 5 | R28: - | S28: - | T28: 8, 15 | U28: 4
B29: 10:00 P.M. | C29: (LT) Luther North Country Ford | D29: 6:00 A.M. | E29: 292 | F29: 4 | G29: =+IF(C29="","",IFERROR(IF(Maestra!A26="#N/D","Log Out",""),"Log Out")) -> Log Out | H29: =IFERROR(HYPERLINK(VLOOKUP(C29,'Flat Base'!D:J,6,0),"SIG TOOLS"),"") -> SIG TOOLS | I29: =IFERROR(HYPERLINK(VLOOKUP(C29,'Flat Base'!D:J,4,0),"SITE MAP"),"") -> SITE MAP | K29: 10:00 P.M. | L29: (LT) Luther North Country Ford | M29: 6:00 A.M. | N29: CT | O29: - | P29: - | Q29: 7, 14, 19 | R29: 30, 31, 32 | S29: - | T29: 1, 4, 9, 13, 15, 16B, 25 | U29: 4
C30: (LT) Landers Kia of Little Rock | D30: 6:00 A.M. | E30: 322 | F30: 4 | G30: =+IF(C30="","",IFERROR(IF(Maestra!A27="#N/D","Log Out",""),"Log Out")) -> Log Out | H30: =IFERROR(HYPERLINK(VLOOKUP(C30,'Flat Base'!D:J,6,0),"SIG TOOLS"),"") -> SIG TOOLS | I30: =IFERROR(HYPERLINK(VLOOKUP(C30,'Flat Base'!D:J,4,0),"SITE MAP"),"") -> SITE MAP | L30: (LT) Landers Kia of Little Rock | M30: 6:00 A.M. | N30: CT | O30: - | P30: 5, 9, 33, 19 | Q30: - | R30: 4, 10 | S30: 1, 35 | T30: 5, 9, 12, 14, 18, 26, 29 | U30: 4
B31: 12:00 A.M. | C31: (DT) Modesto | D31: 8:00 A.M. | E31: 267 | F31: 4 | G31: =+IF(C31="","",IFERROR(IF(Maestra!A28="#N/D","Log Out",""),"Log Out")) -> Log Out | H31: =IFERROR(HYPERLINK(VLOOKUP(C31,'Flat Base'!D:J,6,0),"SIG TOOLS"),"") -> SIG TOOLS | I31: =IFERROR(HYPERLINK(VLOOKUP(C31,'Flat Base'!D:J,4,0),"SITE MAP"),"") -> SITE MAP | K31: 12:00 A.M. | L31: (DT) Modesto | M31: 8:00 A.M. | N31: PT | O31: - | P31: 10 | Q31: 5, 6 | R31: - | S31: - | T31: 2, 3, 5, 10 | U31: 4
G32: =+IF(C32="","",IFERROR(IF(Maestra!A29="#N/D","Log Out",""),"Log Out")) | H32: =IFERROR(HYPERLINK(VLOOKUP(C32,'Flat Base'!D:J,6,0),"SIG TOOLS"),"") | I32: =IFERROR(HYPERLINK(VLOOKUP(C32,'Flat Base'!D:J,4,0),"SITE MAP"),"")
G33: =+IF(C33="","",IFERROR(IF(Maestra!A30="#N/D","Log Out",""),"Log Out")) | H33: =IFERROR(HYPERLINK(VLOOKUP(C33,'Flat Base'!D:J,6,0),"SIG TOOLS"),"") | I33: =IFERROR(HYPERLINK(VLOOKUP(C33,'Flat Base'!D:J,4,0),"SITE MAP"),"")
G34: =+IF(C34="","",IFERROR(IF(Maestra!A31="#N/D","Log Out",""),"Log Out")) | H34: =IFERROR(HYPERLINK(VLOOKUP(C34,'Flat Base'!D:J,6,0),"SIG TOOLS"),"") | I34: =IFERROR(HYPERLINK(VLOOKUP(C34,'Flat Base'!D:J,4,0),"SITE MAP"),"")
G35: =+IF(C35="","",IFERROR(IF(Maestra!A32="#N/D","Log Out",""),"Log Out")) | H35: =IFERROR(HYPERLINK(VLOOKUP(C35,'Flat Base'!D:J,6,0),"SIG TOOLS"),"") | I35: =IFERROR(HYPERLINK(VLOOKUP(C35,'Flat Base'!D:J,4,0),"SITE MAP"),"")
G36: =+IF(C36="","",IFERROR(IF(Maestra!A33="#N/D","Log Out",""),"Log Out")) | H36: =IFERROR(HYPERLINK(VLOOKUP(C36,'Flat Base'!D:J,6,0),"SIG TOOLS"),"") | I36: =IFERROR(HYPERLINK(VLOOKUP(C36,'Flat Base'!D:J,4,0),"SITE MAP"),"")
G37: =+IF(C37="","",IFERROR(IF(Maestra!A34="#N/D","Log Out",""),"Log Out")) | H37: =IFERROR(HYPERLINK(VLOOKUP(C37,'Flat Base'!D:J,6,0),"SIG TOOLS"),"") | I37: =IFERROR(HYPERLINK(VLOOKUP(C37,'Flat Base'!D:J,4,0),"SITE MAP"),"")
G38: =+IF(C38="","",IFERROR(IF(Maestra!A35="#N/D","Log Out",""),"Log Out")) | H38: =IFERROR(HYPERLINK(VLOOKUP(C38,'Flat Base'!D:J,6,0),"SIG TOOLS"),"") | I38: =IFERROR(HYPERLINK(VLOOKUP(C38,'Flat Base'!D:J,4,0),"SITE MAP"),"")
G39: =+IF(C39="","",IFERROR(IF(Maestra!A36="#N/D","Log Out",""),"Log Out")) | H39: =IFERROR(HYPERLINK(VLOOKUP(C39,'Flat Base'!D:J,6,0),"SIG TOOLS"),"") | I39: =IFERROR(HYPERLINK(VLOOKUP(C39,'Flat Base'!D:J,4,0),"SITE MAP"),"")
G40: =+IF(C40="","",IFERROR(IF(Maestra!A37="#N/D","Log Out",""),"Log Out")) | H40: =IFERROR(HYPERLINK(VLOOKUP(C40,'Flat Base'!D:J,6,0),"SIG TOOLS"),"") | I40: =IFERROR(HYPERLINK(VLOOKUP(C40,'Flat Base'!D:J,4,0),"SITE MAP"),"")
G41: =+IF(C41="","",IFERROR(IF(Maestra!A38="#N/D","Log Out",""),"Log Out")) | H41: =IFERROR(HYPERLINK(VLOOKUP(C41,'Flat Base'!D:J,6,0),"SIG TOOLS"),"") | I41: =IFERROR(HYPERLINK(VLOOKUP(C41,'Flat Base'!D:J,4,0),"SITE MAP"),"")
...

Sheet Cambio de Split
A1: Changes: Split-Station:
A15: New Sites | G15: Log In to
A16: 60 | G16: =+COUNTIF('Dynamic Split'!W25:W75,"Log iN") -> 0
A19: Split | B19: Log Time | C19: Site | D19: Drop time | E19: Suma de Station | F19: Log In | G19: Split | H19: Log Time | I19: Site | J19: Drop time | K19: Suma de Station
A20: 1 | B20: 8:00 P.M. | C20: (PE) BMW Service Center (NO TOURS) | D20: 5:00 A.M. | E20: 1 | F20: =IF('Cambio de Split'!C20="","",IFERROR(IF(Maestra!C16="#N/D","Log In",""),"Log In")) -> Log In | G20: 1 | H20: 8:00 P.M. | I20: (PE) BMW Service Center (NO TOURS) | J20: 5:00 A.M. | K20: 1
C21: (PE) JLR Darien (NO TOURS) | D21: 5:00 A.M. | E21: 1 | F21: =IF('Cambio de Split'!C21="","",IFERROR(IF(Maestra!C17="#N/D","Log In",""),"Log In")) -> Log In | I21: (PE) JLR Darien (NO TOURS) | J21: 5:00 A.M. | K21: 1
C22: (PE) JLR Englewood (NO TOURS) | D22: 5:00 A.M. | E22: 1 | F22: =IF('Cambio de Split'!C22="","",IFERROR(IF(Maestra!C18="#N/D","Log In",""),"Log In")) -> Log In | I22: (PE) JLR Englewood (NO TOURS) | J22: 5:00 A.M. | K22: 1
C23: (PE) JLR Paramus (NO TOURS) | D23: 5:00 A.M. | E23: 1 | F23: =IF('Cambio de Split'!C23="","",IFERROR(IF(Maestra!C19="#N/D","Log In",""),"Log In")) -> Log In | I23: (PE) JLR Paramus (NO TOURS) | J23: 5:00 A.M. | K23: 1
C24: (PE) Porsche Audi Fairfield (NO TOURS) | D24: 5:00 A.M. | E24: 1 | F24: =IF('Cambio de Split'!C24="","",IFERROR(IF(Maestra!C20="#N/D","Log In",""),"Log In")) -> Log In | I24: (PE) Porsche Audi Fairfield (NO TOURS) | J24: 5:00 A.M. | K24: 1
C25: (PE) MB of Greenwich | D25: 5:00 A.M. | E25: 1 | F25: =IF('Dynamic Split'!T24="","",IFERROR(IF(Maestra!C21="#N/D","Log In",""),"Log In")) -> Log In | I25: (PE) MB of Greenwich | J25: 5:00 A.M. | K25: 1
C26: (LT) Luther Bloomington Subaru - Acura | D26: 4:00 A.M. | E26: 1 | I26: (LT) Luther Bloomington Subaru - Acura | J26: 4:00 A.M. | K26: 1
C27: (LT) Luther Hopkins Honda (NO TOURS) | D27: 6:00 A.M. | E27: 1 | I27: (LT) Luther Hopkins Honda (NO TOURS) | J27: 6:00 A.M. | K27: 1
B28: 9:00 P.M. | C28: (AS) Coggin BMW Ft. Pierce (NO TOURS) | D28: 5:00 A.M. | E28: 1 | H28: 9:00 P.M. | I28: (AS) Coggin BMW Ft. Pierce (NO TOURS) | J28: 5:00 A.M. | K28: 1
C29: (DT) Charlotte | D29: 5:00 A.M. | E29: 1 | I29: (DT) Charlotte | J29: 5:00 A.M. | K29: 1
C30: (AS) Koons MB of Catonsville (NO TOURS) | D30: 5:00 A.M. | E30: 1 | I30: (AS) Koons MB of Catonsville (NO TOURS) | J30: 5:00 A.M. | K30: 1
C31: (TC) Lamborghini South Dade | D31: 5:00 A.M. | E31: 1 | I31: (TC) Lamborghini South Dade | J31: 5:00 A.M. | K31: 1
C32: (AS) Coggin Collision Center of Kissimmee (NO TOURS) | D32: 5:00 A.M. | E32: 1 | I32: (AS) Coggin Collision Center of Kissimmee (NO TOURS) | J32: 5:00 A.M. | K32: 1
C33: (AS) Koons Baltimore Ford - Main Dealership (NO TOURS) | D33: 5:00 A.M. | E33: 1 | I33: (AS) Koons Baltimore Ford - Main Dealership (NO TOURS) | J33: 5:00 A.M. | K33: 1
C34: (AS) Koons Woodbridge GMC (NO TOURS) | D34: 5:00 A.M. | E34: 1 | I34: (AS) Koons Woodbridge GMC (NO TOURS) | J34: 5:00 A.M. | K34: 1
C35: (AS) Koons Woodbridge Ford (NO TOURS) | D35: 5:00 A.M. | E35: 1 | I35: (AS) Koons Woodbridge Ford (NO TOURS) | J35: 5:00 A.M. | K35: 1
C36: (AS) Koons Chevrolet Buick GMC - Tysons Remote Lot (NO TOURS) | D36: 5:00 A.M. | E36: 1 | I36: (AS) Koons Chevrolet Buick GMC - Tysons Remote Lot (NO TOURS) | J36: 5:00 A.M. | K36: 1
C37: (AS) Koons Arlington Toyota - New Car (NO TOURS) | D37: 5:00 A.M. | E37: 1 | I37: (AS) Koons Arlington Toyota - New Car (NO TOURS) | J37: 5:00 A.M. | K37: 1
C38: (AS) Koons Volvo Cars White Marsh (NO TOURS) | D38: 5:00 A.M. | E38: 1 | I38: (AS) Koons Volvo Cars White Marsh (NO TOURS) | J38: 5:00 A.M. | K38: 1
C39: (AS) Koons Chevrolet Buick GMC - Tysons (NO TOURS) | D39: 5:00 A.M. | E39: 1 | I39: (AS) Koons Chevrolet Buick GMC - Tysons (NO TOURS) | J39: 5:00 A.M. | K39: 1
C40: (AS) Coggin Honda of Orlando (NO TOURS) | D40: 5:00 A.M. | E40: 1 | I40: (AS) Coggin Honda of Orlando (NO TOURS) | J40: 5:00 A.M. | K40: 1
... C57: (AS) Koons Tysons Toyota - UC Recon (NO TOURS) | D57: 5:00 A.M. | E57: 1 | I57: (AS) Koons Tysons Toyota - UC Recon (NO TOURS) | J57: 5:00 A.M. | K57: 1
B58: 10:00 P.M. | C58: (DT) Arlington | D58: 6:00 A.M. | E58: 1 | H58: 10:00 P.M. | I58: (DT) Arlington | J58: 6:00 A.M. | K58: 1
C59: (ML) Joe Machens Hyundai | D59: 6:00 A.M. | E59: 1 | I59: (ML) Joe Machens Hyundai | J59: 6:00 A.M. | K59: 1
C60: (KG) Big Star Cadillac | D60: 6:00 A.M. | E60: 1 | I60: (KG) Big Star Cadillac | J60: 6:00 A.M. | K60: 1
C61: (LT) Luther North Country Ford | D61: 6:00 A.M. | E61: 1 | I61: (LT) Luther North Country Ford | J61: 6:00 A.M. | K61: 1
C62: (LT) Luther St. Cloud Subaru | D62: 5:30 A.M. | E62: 1 | I62: (LT) Luther St. Cloud Subaru | J62: 5:30 A.M. | K62: 1
C63: (KG) Big Star Hyundai Houston | D63: 6:00 A.M. | E63: 1 | I63: (KG) Big Star Hyundai Houston | J63: 6:00 A.M. | K63: 1
C64: (LT) Landers Kia of Little Rock | D64: 6:00 A.M. | E64: 1 | I64: (LT) Landers Kia of Little Rock | J64: 6:00 A.M. | K64: 1
C65: (LT) Luther Landers Recon Center | D65: 6:00 A.M. | E65: 1 | I65: (LT) Luther Landers Recon Center | J65: 6:00 A.M. | K65: 1
C66: (LT) Luther Genesis of Minneapolis | D66: 6:00 A.M. | E66: 1 | I66: (LT) Luther Genesis of Minneapolis | J66: 6:00 A.M. | K66: 1
C67: (LT) Luther Burnsville Hyundai | D67: 6:00 A.M. | E67: 1 | I67: (LT) Luther Burnsville Hyundai | J67: 6:00 A.M. | K67: 1
C68: (AS) 3281 Storage Lot (NO TOURS) | D68: 6:00 A.M. | E68: 1 | I68: (AS) 3281 Storage Lot (NO TOURS) | J68: 6:00 A.M. | K68: 1
C69: (AS) Plaza Mercedes Benz West (NO TOURS) | D69: 6:00 A.M. | E69: 1 | I69: (AS) Plaza Mercedes Benz West (NO TOURS) | J69: 6:00 A.M. | K69: 1
C70: (AS) Plaza Collision ST Louis (NO TOURS) | D70: 6:00 A.M. | E70: 1 | I70: (AS) Plaza Collision ST Louis (NO TOURS) | J70: 6:00 A.M. | K70: 1
C71: (LT) Luther Bloomington Hyundai (NO TOURS) | D71: 4:00 A.M. | E71: 1 | I71: (LT) Luther Bloomington Hyundai (NO TOURS) | J71: 4:00 A.M. | K71: 1
...

Sheet Maestra
A16: =+VLOOKUP('Dynamic Split'!C19,'Dynamic Split'!T:T,1,0) -> #N/A | C16: =VLOOKUP('Cambio de Split'!C20,'Dynamic Split'!C:C,1,0) -> #N/A
A17: =+VLOOKUP('Dynamic Split'!C20,'Dynamic Split'!T:T,1,0) -> #N/A | C17: =VLOOKUP('Cambio de Split'!C21,'Dynamic Split'!C:C,1,0) -> #N/A
A18: =+VLOOKUP('Dynamic Split'!C21,'Dynamic Split'!T:T,1,0) -> #N/A | C18: =VLOOKUP('Cambio de Split'!C22,'Dynamic Split'!C:C,1,0) -> #N/A
A19: =+VLOOKUP('Dynamic Split'!C22,'Dynamic Split'!T:T,1,0) -> #N/A | C19: =VLOOKUP('Cambio de Split'!C23,'Dynamic Split'!C:C,1,0) -> #N/A
A20: =+VLOOKUP('Dynamic Split'!C23,'Dynamic Split'!T:T,1,0) -> #N/A | C20: =VLOOKUP('Cambio de Split'!C24,'Dynamic Split'!C:C,1,0) -> #N/A
A21: =+VLOOKUP('Dynamic Split'!C24,'Dynamic Split'!T:T,1,0) -> #N/A | C21: =VLOOKUP('Dynamic Split'!T24,'Dynamic Split'!C:C,1,0) -> #N/A
A22: =+VLOOKUP('Dynamic Split'!C25,'Dynamic Split'!T:T,1,0) -> #N/A | C22: =VLOOKUP('Dynamic Split'!T25,'Dynamic Split'!C:C,1,0) -> #N/A
A23: =+VLOOKUP('Dynamic Split'!C26,'Dynamic Split'!T:T,1,0) -> #N/A | C23: =VLOOKUP('Dynamic Split'!T26,'Dynamic Split'!C:C,1,0) -> #N/A
A24: =+VLOOKUP('Dynamic Split'!C27,'Dynamic Split'!T:T,1,0) -> #N/A | C24: =VLOOKUP('Dynamic Split'!T27,'Dynamic Split'!C:C,1,0) -> #N/A
A25: =+VLOOKUP('Dynamic Split'!C28,'Dynamic Split'!T:T,1,0) -> #N/A | C25: =VLOOKUP('Dynamic Split'!T28,'Dynamic Split'!C:C,1,0) -> #N/A
A26: =+VLOOKUP('Dynamic Split'!C29,'Dynamic Split'!T:T,1,0) -> #N/A | C26: =VLOOKUP('Dynamic Split'!T29,'Dynamic Split'!C:C,1,0) -> #N/A
A27: =+VLOOKUP('Dynamic Split'!C30,'Dynamic Split'!T:T,1,0) -> #N/A | C27: =VLOOKUP('Dynamic Split'!T30,'Dynamic Split'!C:C,1,0) -> #N/A
A28: =+VLOOKUP('Dynamic Split'!C31,'Dynamic Split'!T:T,1,0) -> #N/A | C28: =VLOOKUP('Dynamic Split'!T31,'Dynamic Split'!C:C,1,0) -> #N/A
A29: =+VLOOKUP('Dynamic Split'!C32,'Dynamic Split'!T:T,1,0) -> #N/A | C29: =VLOOKUP('Dynamic Split'!T32,'Dynamic Split'!C:C,1,0) -> #N/A
A30: =+VLOOKUP('Dynamic Split'!C33,'Dynamic Split'!T:T,1,0) -> #N/A | C30: =VLOOKUP('Dynamic Split'!T33,'Dynamic Split'!C:C,1,0) -> #N/A
A31: =+VLOOKUP('Dynamic Split'!C34,'Dynamic Split'!T:T,1,0) -> #N/A | C31: =VLOOKUP('Dynamic Split'!T34,'Dynamic Split'!C:C,1,0) -> #N/A
A32: =+VLOOKUP('Dynamic Split'!C35,'Dynamic Split'!T:T,1,0) -> #N/A | C32: =VLOOKUP('Dynamic Split'!T35,'Dynamic Split'!C:C,1,0) -> #N/A
... A72: =+VLOOKUP('Dynamic Split'!C75,'Dynamic Split'!T:T,1,0) -> #N/A | C72: =VLOOKUP('Dynamic Split'!T75,'Dynamic Split'!C:C,1,0) -> #N/A

Sheet Flat Base
A1: Key | B1: Split | C1: Station | D1: Site | E1: Hour | F1: Time | G1: Drop time | H1: SUNDAY (D.T.) | I1: SIG Tools | J1: Map | K1: Notes* | L1: Gates | M1: Entrances | N1: LPR | O1: PTZ | P1: Important Cameras | Q1: ID
A2: =+Tabla3[[#This Row],[Site]]&Tabla3[[#This Row],[Split]] -> (AS) 3281 Storage Lot (NO TOURS)1 | B2: 1 | C2: 1 | D2: (AS) 3281 Storage Lot (NO TOURS) | E2: =VLOOKUP(Tabla3[[#This Row],[Site]],Table35[],10,FALSE) -> 10:00 P.M. | F2: =VLOOKUP(Tabla3[[#This Row],[Site]],Table35[],11,FALSE) -> CT | G2: =VLOOKUP(Tabla3[[#This Row],[Site]],Table35[],12,FALSE) -> 6:00 A.M. | H2: =VLOOKUP(Tabla3[[#This Row],[Site]],Table35[],13,FALSE) -> - | I2: =HYPERLINK(VLOOKUP(Tabla3[[#This Row],[Site]],Table35[#All],9,FALSE)) -> https://tools.sig.systems/site/details/305 | J2: =VLOOKUP(Tabla3[[#This Row],[Site]],Table35[],14,FALSE) -> https://www.google.com/maps/d/edit?hl=es&mid=1uPmsRMsXnp74hPFW2t-sp2totVWF_xY&ll=32.83050137713022%2C-96.83197783061323&z=17 | L2: =VLOOKUP(Tabla3[[#This Row],[Site]],Table35[#All],2,FALSE) -> - | M2: =VLOOKUP(Tabla3[[#This Row],[Site]],Table35[#All],3,FALSE) -> 2, 14 | N2: =VLOOKUP(Tabla3[[#This Row],[Site]],Table35[#All],4,FALSE) -> - | O2: =VLOOKUP(Tabla3[[#This Row],[Site]],Table35[#All],5,FALSE) -> - | P2: =VLOOKUP(Tabla3[[#This Row],[Site]],Table35[#All],6,FALSE) -> 1, 3, 9, 10, 14 | Q2: =VLOOKUP(Tabla3[[#This Row],[Site]],Table35[#All],8,FALSE) -> 305
A3: =+Tabla3[[#This Row],[Site]]&Tabla3[[#This Row],[Split]] -> (AS) Coggin BMW Ft. Pierce (NO TOURS)1 | B3: 1 | C3: 1 | D3: (AS) Coggin BMW Ft. Pierce (NO TOURS) | E3: =VLOOKUP(Tabla3[[#This Row],[Site]],Table35[],10,FALSE) -> 9:00 P.M. | F3: =VLOOKUP(Tabla3[[#This Row],[Site]],Table35[],11,FALSE) -> ET | G3: =VLOOKUP(Tabla3[[#This Row],[Site]],Table35[],12,FALSE) -> 5:00 A.M. | H3: =VLOOKUP(Tabla3[[#This Row],[Site]],Table35[],13,FALSE) -> - | I3: =HYPERLINK(VLOOKUP(Tabla3[[#This Row],[Site]],Table35[#All],9,FALSE)) -> https://tools.sig.systems/site/details/119 | J3: =VLOOKUP(Tabla3[[#This Row],[Site]],Table35[],14,FALSE) -> https://www.google.com/maps/d/viewer?mid=1AyViBuyeq7iwDua1SVudJ2A1BYi3IBA&ll=27.38181516363982%2C-80.32568845000002&z=18 | L3: =VLOOKUP(Tabla3[[#This Row],[Site]],Table35[#All],2,FALSE) -> 3, 10, 13 | M3: =VLOOKUP(Tabla3[[#This Row],[Site]],Table35[#All],3,FALSE) -> - | N3: =VLOOKUP(Tabla3[[#This Row],[Site]],Table35[#All],4,FALSE) -> - | O3: =VLOOKUP(Tabla3[[#This Row],[Site]],Table35[#All],5,FALSE) -> 2 | P3: =VLOOKUP(Tabla3[[#This Row],[Site]],Table35[#All],6,FALSE) -> 1, 20, 27 | Q3: =VLOOKUP(Tabla3[[#This Row],[Site]],Table35[#All],8,FALSE) -> 119
A4: =+Tabla3[[#This Row],[Site]]&Tabla3[[#This Row],[Split]] -> (AS) Coggin Collision Center of Kissimmee (NO TOURS)1 | B4: 1 | C4: 1 | D4: (AS) Coggin Collision Center of Kissimmee (NO TOURS) | E4: =VLOOKUP(Tabla3[[#This Row],[Site]],Table35[],10,FALSE) -> 9:00 P.M. | F4: =VLOOKUP(Tabla3[[#This Row],[Site]],Table35[],11,FALSE) -> ET | G4: =VLOOKUP(Tabla3[[#This Row],[Site]],Table35[],12,FALSE) -> 5:00 A.M. | H4: =VLOOKUP(Tabla3[[#This Row],[Site]],Table35[],13,FALSE) -> - | I4: =HYPERLINK(VLOOKUP(Tabla3[[#This Row],[Site]],Table35[#All],9,FALSE)) -> https://tools.sig.systems/site/details/331 | J4: =VLOOKUP(Tabla3[[#This Row],[Site]],Table35[],14,FALSE) -> 0 | L4: =VLOOKUP(Tabla3[[#This Row],[Site]],Table35[#All],2,FALSE) -> 1, 12 | M4: =VLOOKUP(Tabla3[[#This Row],[Site]],Table35[#All],3,FALSE) -> - | N4: =VLOOKUP(Tabla3[[#This Row],[Site]],Table35[#All],4,FALSE) -> - | O4: =VLOOKUP(Tabla3[[#This Row],[Site]],Table35[#All],5,FALSE) -> - | P4: =VLOOKUP(Tabla3[[#This Row],[Site]],Table35[#All],6,FALSE) -> 2, 7, 9 | Q4: =VLOOKUP(Tabla3[[#This Row],[Site]],Table35[#All],8,FALSE) -> 331
A5: =+Tabla3[[#This Row],[Site]]&Tabla3[[#This Row],[Split]] -> (AS) Coggin Honda of Orlando (NO TOURS)1 | B5: 1 | C5: 1 | D5: (AS) Coggin Honda of Orlando (NO TOURS) | E5: =VLOOKUP(Tabla3[[#This Row],[Site]],Table35[],10,FALSE) -> 9:00 P.M. | F5: =VLOOKUP(Tabla3[[#This Row],[Site]],Table35[],11,FALSE) -> ET | G5: =VLOOKUP(Tabla3[[#This Row],[Site]],Table35[],12,FALSE) -> 5:00 A.M. | H5: =VLOOKUP(Tabla3[[#This Row],[Site]],Table35[],13,FALSE) -> 11:00 A.M. | I5: =HYPERLINK(VLOOKUP(Tabla3[[#This Row],[Site]],Table35[#All],9,FALSE)) -> https://tools.sig.systems/site/details/324 | J5: =VLOOKUP(Tabla3[[#This Row],[Site]],Table35[],14,FALSE) -> 0 | L5: =VLOOKUP(Tabla3[[#This Row],[Site]],Table35[#All],2,FALSE) -> 2, 10, 12B, 14, 38 | M5: =VLOOKUP(Tabla3[[#This Row],[Site]],Table35[#All],3,FALSE) -> - | N5: =VLOOKUP(Tabla3[[#This Row],[Site]],Table35[#All],4,FALSE) -> - | O5: =VLOOKUP(Tabla3[[#This Row],[Site]],Table35[#All],5,FALSE) -> 12, 31 | P5: =VLOOKUP(Tabla3[[#This Row],[Site]],Table35[#All],6,FALSE) -> 12B, 26, 37, 19 | Q5: =VLOOKUP(Tabla3[[#This Row],[Site]],Table35[#All],8,FALSE) -> 324
A6: =+Tabla3[[#This Row],[Site]]&Tabla3[[#This Row],[Split]] -> (AS) Hare Chevrolet (NO TOURS)1 | B6: 1 | C6: 1 | D6: (AS) Hare Chevrolet (NO TOURS) | E6: =VLOOKUP(Tabla3[[#This Row],[Site]],Table35[],10,FALSE) -> 9:00 P.M. | F6: =VLOOKUP(Tabla3[[#This Row],[Site]],Table35[],11,FALSE) -> ET | G6: =VLOOKUP(Tabla3[[#This Row],[Site]],Table35[],12,FALSE) -> 5:00 A.M. | H6: =VLOOKUP(Tabla3[[#This Row],[Site]],Table35[],13,FALSE) -> - | I6: =HYPERLINK(VLOOKUP(Tabla3[[#This Row],[Site]],Table35[#All],9,FALSE)) -> https://tools.sig.systems/site/details/301 | J6: =VLOOKUP(Tabla3[[#This Row],[Site]],Table35[],14,FALSE) -> https://www.google.com/maps/d/edit?mid=1hsX5GGrNcCQgAuzDCDz1OWgEkhsAc78&usp=sharing | L6: =VLOOKUP(Tabla3[[#This Row],[Site]],Table35[#All],2,FALSE) -> 18, 24 | M6: =VLOOKUP(Tabla3[[#This Row],[Site]],Table35[#All],3,FALSE) -> 2, 3 | N6: =VLOOKUP(Tabla3[[#This Row],[Site]],Table35[#All],4,FALSE) -> - | O6: =VLOOKUP(Tabla3[[#This Row],[Site]],Table35[#All],5,FALSE) -> 5 | P6: =VLOOKUP(Tabla3[[#This Row],[Site]],Table35[#All],6,FALSE) -> 1, 5, 7, 8, 21, 29 | Q6: =VLOOKUP(Tabla3[[#This Row],[Site]],Table35[#All],8,FALSE) -> 301
A7: =+Tabla3[[#This Row],[Site]]&Tabla3[[#This Row],[Split]] -> (AS) Hare Truck Center (NO TOURS)1 | B7: 1 | C7: 1 | D7: (AS) Hare Truck Center (NO TOURS) | E7: =VLOOKUP(Tabla3[[#This Row],[Site]],Table35[],10,FALSE) -> 9:00 P.M. | F7: =VLOOKUP(Tabla3[[#This Row],[Site]],Table35[],11,FALSE) -> ET | G7: =VLOOKUP(Tabla3[[#This Row],[Site]],Table35[],12,FALSE) -> 5:00 A.M. | H7: =VLOOKUP(Tabla3[[#This Row],[Site]],Table35[],13,FALSE) -> - | I7: =HYPERLINK(VLOOKUP(Tabla3[[#This Row],[Site]],Table35[#All],9,FALSE)) -> https://tools.sig.systems/site/details/300 | J7: =VLOOKUP(Tabla3[[#This Row],[Site]],Table35[],14,FALSE) -> https://www.google.com/maps/d/edit?mid=1hsX5GGrNcCQgAuzDCDz1OWgEkhsAc78&usp=sharing | L7: =VLOOKUP(Tabla3[[#This Row],[Site]],Table35[#All],2,FALSE) -> - | M7: =VLOOKUP(Tabla3[[#This Row],[Site]],Table35[#All],3,FALSE) -> 1, 5 | N7: =VLOOKUP(Tabla3[[#This Row],[Site]],Table35[#All],4,FALSE) -> - | O7: =VLOOKUP(Tabla3[[#This Row],[Site]],Table35[#All],5,FALSE) -> - | P7: =VLOOKUP(Tabla3[[#This Row],[Site]],Table35[#All],6,FALSE) -> 2, 6, 10, 12, 17 | Q7: =VLOOKUP(Tabla3[[#This Row],[Site]],Table35[#All],8,FALSE) -> 300
A8: =+Tabla3[[#This Row],[Site]]&Tabla3[[#This Row],[Split]] -> (AS) Kahlo CDJR (NO TOURS)1 | B8: 1 | C8: 1 | D8: (AS) Kahlo CDJR (NO TOURS) | E8: =VLOOKUP(Tabla3[[#This Row],[Site]],Table35[],10,FALSE) -> 9:00 P.M. | F8: =VLOOKUP(Tabla3[[#This Row],[Site]],Table35[],11,FALSE) -> ET | G8: =VLOOKUP(Tabla3[[#This Row],[Site]],Table35[],12,FALSE) -> 5:00 A.M. | H8: =VLOOKUP(Tabla3[[#This Row],[Site]],Table35[],13,FALSE) -> - | I8: =HYPERLINK(VLOOKUP(Tabla3[[#This Row],[Site]],Table35[#All],9,FALSE)) -> https://tools.sig.systems/site/details/282 | J8: =VLOOKUP(Tabla3[[#This Row],[Site]],Table35[],14,FALSE) -> https://www.google.com/maps/d/edit?mid=1hsX5GGrNcCQgAuzDCDz1OWgEkhsAc78&usp=sharing | L8: =VLOOKUP(Tabla3[[#This Row],[Site]],Table35[#All],2,FALSE) -> - | M8: =VLOOKUP(Tabla3[[#This Row],[Site]],Table35[#All],3,FALSE) -> 12, 25 | N8: =VLOOKUP(Tabla3[[#This Row],[Site]],Table35[#All],4,FALSE) -> 15, 16 | O8: =VLOOKUP(Tabla3[[#This Row],[Site]],Table35[#All],5,FALSE) -> 20 | P8: =VLOOKUP(Tabla3[[#This Row],[Site]],Table35[#All],6,FALSE) -> 1, 2, 9, 22, 31, 57 | Q8: =VLOOKUP(Tabla3[[#This Row],[Site]],Table35[#All],8,FALSE) -> 282
A9: =+Tabla3[[#This Row],[Site]]&Tabla3[[#This Row],[Split]] -> (AS) Koons Annapolis Toyota (NO TOURS)1 | B9: 1 | C9: 1 | D9: (AS) Koons Annapolis Toyota (NO TOURS) | E9: =VLOOKUP(Tabla3[[#This Row],[Site]],Table35[],10,FALSE) -> 9:00 P.M. | F9: =VLOOKUP(Tabla3[[#This Row],[Site]],Table35[],11,FALSE) -> ET | G9: =VLOOKUP(Tabla3[[#This Row],[Site]],Table35[],12,FALSE) -> 5:00 A.M. | H9: =VLOOKUP(Tabla3[[#This Row],[Site]],Table35[],13,FALSE) -> 0 | I9: =HYPERLINK(VLOOKUP(Tabla3[[#This Row],[Site]],Table35[#All],9,FALSE)) -> https://tools.sig.systems/site/details/337 | J9: =VLOOKUP(Tabla3[[#This Row],[Site]],Table35[],14,FALSE) -> - | L9: =VLOOKUP(Tabla3[[#This Row],[Site]],Table35[#All],2,FALSE) -> 6 | M9: =VLOOKUP(Tabla3[[#This Row],[Site]],Table35[#All],3,FALSE) -> 1, 6, 21 | N9: =VLOOKUP(Tabla3[[#This Row],[Site]],Table35[#All],4,FALSE) -> - | O9: =VLOOKUP(Tabla3[[#This Row],[Site]],Table35[#All],5,FALSE) -> - | P9: =VLOOKUP(Tabla3[[#This Row],[Site]],Table35[#All],6,FALSE) -> 3, 5, 7, 19 | Q9: =VLOOKUP(Tabla3[[#This Row],[Site]],Table35[#All],8,FALSE) -> 337
A10: =+Tabla3[[#This Row],[Site]]&Tabla3[[#This Row],[Split]] -> (AS) Koons Arlington Toyota - New Car (NO TOURS)1 | B10: 1 | C10: 1 | D10: (AS) Koons Arlington Toyota - New Car (NO TOURS) | E10: =VLOOKUP(Tabla3[[#This Row],[Site]],Table35[],10,FALSE) -> 9:00 P.M. | F10: =VLOOKUP(Tabla3[[#This Row],[Site]],Table35[],11,FALSE) -> ET | G10: =VLOOKUP(Tabla3[[#This Row],[Site]],Table35[],12,FALSE) -> 5:00 A.M. | H10: =VLOOKUP(Tabla3[[#This Row],[Site]],Table35[],13,FALSE) -> 10:00 A.M. | I10: =HYPERLINK(VLOOKUP(Tabla3[[#This Row],[Site]],Table35[#All],9,FALSE)) -> https://tools.sig.systems/site/details/334 | J10: =VLOOKUP(Tabla3[[#This Row],[Site]],Table35[],14,FALSE) -> - | L10: =VLOOKUP(Tabla3[[#This Row],[Site]],Table35[#All],2,FALSE) -> - | M10: =VLOOKUP(Tabla3[[#This Row],[Site]],Table35[#All],3,FALSE) -> 1, 3, 12, 15, 17 | N10: =VLOOKUP(Tabla3[[#This Row],[Site]],Table35[#All],4,FALSE) -> - | O10: =VLOOKUP(Tabla3[[#This Row],[Site]],Table35[#All],5,FALSE) -> - | P10: =VLOOKUP(Tabla3[[#This Row],[Site]],Table35[#All],6,FALSE) -> 2, 6, 18, 20 | Q10: =VLOOKUP(Tabla3[[#This Row],[Site]],Table35[#All],8,FALSE) -> 334
A11: =+Tabla3[[#This Row],[Site]]&Tabla3[[#This Row],[Split]] -> (AS) Koons Baltimore Ford - Main Dealership (NO TOURS)1 | B11: 1 | C11: 1 | D11: (AS) Koons Baltimore Ford - Main Dealership (NO TOURS) | E11: =VLOOKUP(Tabla3[[#This Row],[Site]],Table35[],10,FALSE) -> 9:00 P.M. | F11: =VLOOKUP(Tabla3[[#This Row],[Site]],Table35[],11,FALSE) -> ET | G11: =VLOOKUP(Tabla3[[#This Row],[Site]],Table35[],12,FALSE) -> 5:00 A.M. | H11: =VLOOKUP(Tabla3[[#This Row],[Site]],Table35[],13,FALSE) -> - | I11: =HYPERLINK(VLOOKUP(Tabla3[[#This Row],[Site]],Table35[#All],9,FALSE)) -> https://tools.sig.systems/site/details/335 | J11: =VLOOKUP(Tabla3[[#This Row],[Site]],Table35[],14,FALSE) -> - | L11: =VLOOKUP(Tabla3[[#This Row],[Site]],Table35[#All],2,FALSE) -> 21, 22, 24, 32, 45 | M11: =VLOOKUP(Tabla3[[#This Row],[Site]],Table35[#All],3,FALSE) -> 1 | N11: =VLOOKUP(Tabla3[[#This Row],[Site]],Table35[#All],4,FALSE) -> - | O11: =VLOOKUP(Tabla3[[#This Row],[Site]],Table35[#All],5,FALSE) -> 1, 8 | P11: =VLOOKUP(Tabla3[[#This Row],[Site]],Table35[#All],6,FALSE) -> 5, 28, 38 | Q11: =VLOOKUP(Tabla3[[#This Row],[Site]],Table35[#All],8,FALSE) -> 335
A12: =+Tabla3[[#This Row],[Site]]&Tabla3[[#This Row],[Split]] -> (AS) Koons Chevrolet Buick GMC - Clarksville (NO TOURS)1 | B12: 1 | C12: 1 | D12: (AS) Koons Chevrolet Buick GMC - Clarksville (NO TOURS) | E12: =VLOOKUP(Tabla3[[#This Row],[Site]],Table35[],10,FALSE) -> 9:00 P.M. | F12: =VLOOKUP(Tabla3[[#This Row],[Site]],Table35[],11,FALSE) -> ET | G12: =VLOOKUP(Tabla3[[#This Row],[Site]],Table35[],12,FALSE) -> 5:00 A.M. | H12: =VLOOKUP(Tabla3[[#This Row],[Site]],Table35[],13,FALSE) -> 10:00 A.M. | I12: =HYPERLINK(VLOOKUP(Tabla3[[#This Row],[Site]],Table35[#All],9,FALSE)) -> https://tools.sig.systems/site/details/306 | J12: =VLOOKUP(Tabla3[[#This Row],[Site]],Table35[],14,FALSE) -> https://www.google.com/maps/d/edit?hl=es&mid=11XB1lTSP7EcDCDvzypdUPWP6bWCNAEI&ll=39.21145022420528%2C-76.94003711910554&z=17 | L12: =VLOOKUP(Tabla3[[#This Row],[Site]],Table35[#All],2,FALSE) -> - | M12: =VLOOKUP(Tabla3[[#This Row],[Site]],Table35[#All],3,FALSE) -> 1, 22, 26, 28, 29 | N12: =VLOOKUP(Tabla3[[#This Row],[Site]],Table35[#All],4,FALSE) -> - | O12: =VLOOKUP(Tabla3[[#This Row],[Site]],Table35[#All],5,FALSE) -> - | P12: =VLOOKUP(Tabla3[[#This Row],[Site]],Table35[#All],6,FALSE) -> 3, 11, 15, 23 | Q12: =VLOOKUP(Tabla3[[#This Row],[Site]],Table35[#All],8,FALSE) -> 306
A13: =+Tabla3[[#This Row],[Site]]&Tabla3[[#This Row],[Split]] -> (AS) Koons Chevrolet Buick GMC - Clarksville Remote Lot (NO TOURS)1 | B13: 1 | C13: 1 | D13: (AS) Koons Chevrolet Buick GMC - Clarksville Remote Lot (NO TOURS) | E13: =VLOOKUP(Tabla3[[#This Row],[Site]],Table35[],10,FALSE) -> 9:00 P.M. | F13: =VLOOKUP(Tabla3[[#This Row],[Site]],Table35[],11,FALSE) -> ET | G13: =VLOOKUP(Tabla3[[#This Row],[Site]],Table35[],12,FALSE) -> 5:00 A.M. | H13: =VLOOKUP(Tabla3[[#This Row],[Site]],Table35[],13,FALSE) -> 10:00 A.M. | I13: =HYPERLINK(VLOOKUP(Tabla3[[#This Row],[Site]],Table35[#All],9,FALSE)) -> https://tools.sig.systems/site/details/308 | J13: =VLOOKUP(Tabla3[[#This Row],[Site]],Table35[],14,FALSE) -> https://www.google.com/maps/d/edit?hl=es&mid=11XB1lTSP7EcDCDvzypdUPWP6bWCNAEI&ll=39.21145022420528%2C-76.94003711910554&z=21 | L13: =VLOOKUP(Tabla3[[#This Row],[Site]],Table35[#All],2,FALSE) -> - | M13: =VLOOKUP(Tabla3[[#This Row],[Site]],Table35[#All],3,FALSE) -> 1, 5 | N13: =VLOOKUP(Tabla3[[#This Row],[Site]],Table35[#All],4,FALSE) -> - | O13: =VLOOKUP(Tabla3[[#This Row],[Site]],Table35[#All],5,FALSE) -> - | P13: =VLOOKUP(Tabla3[[#This Row],[Site]],Table35[#All],6,FALSE) -> 14, 16 | Q13: =VLOOKUP(Tabla3[[#This Row],[Site]],Table35[#All],8,FALSE) -> 308
... A284: =+Tabla3[[#This Row],[Site]]&Tabla3[[#This Row],[Split]] -> (PE) JLR Englewood (NO TOURS)5 | B284: 5 | C284: 4 | D284: (PE) JLR Englewood (NO TOURS) | E284: =VLOOKUP(Tabla3[[#This Row],[Site]],Table35[],10,FALSE) -> 8:00 P.M. | F284: =VLOOKUP(Tabla3[[#This Row],[Site]],Table35[],11,FALSE) -> ET | G284: =VLOOKUP(Tabla3[[#This Row],[Site]],Table35[],12,FALSE) -> 5:00 A.M. | H284: =VLOOKUP(Tabla3[[#This Row],[Site]],Table35[],13,FALSE) -> - | I284: =HYPERLINK(VLOOKUP(Tabla3[[#This Row],[Site]],Table35[#All],9,FALSE)) -> https://tools.sig.systems/site/details/178 | J284: =VLOOKUP(Tabla3[[#This Row],[Site]],Table35[],14,FALSE) -> https://www.google.com/maps/d/viewer?mid=1ubI2iKs1JyYXssuT4oLPnVvFnyLPi_s&ll=40.878808846788026%2C-73.98560655&z=17 | L284: =VLOOKUP(Tabla3[[#This Row],[Site]],Table35[#All],2,FALSE) -> 1, 2 | M284: =VLOOKUP(Tabla3[[#This Row],[Site]],Table35[#All],3,FALSE) -> - | N284: =VLOOKUP(Tabla3[[#This Row],[Site]],Table35[#All],4,FALSE) -> - | O284: =VLOOKUP(Tabla3[[#This Row],[Site]],Table35[#All],5,FALSE) -> - | P284: =VLOOKUP(Tabla3[[#This Row],[Site]],Table35[#All],6,FALSE) -> - | Q284: =VLOOKUP(Tabla3[[#This Row],[Site]],Table35[#All],8,FALSE) -> 178
A285: =+Tabla3[[#This Row],[Site]]&Tabla3[[#This Row],[Split]] -> (AS) 3281 Storage Lot (NO TOURS)5 | B285: 5 | C285: 5 | D285: (AS) 3281 Storage Lot (NO TOURS) | E285: =VLOOKUP(Tabla3[[#This Row],[Site]],Table35[],10,FALSE) -> 10:00 P.M. | F285: =VLOOKUP(Tabla3[[#This Row],[Site]],Table35[],11,FALSE) -> CT | G285: =VLOOKUP(Tabla3[[#This Row],[Site]],Table35[],12,FALSE) -> 6:00 A.M. | I285: =HYPERLINK(VLOOKUP(Tabla3[[#This Row],[Site]],Table35[#All],9,FALSE)) -> https://tools.sig.systems/site/details/305 | J285: =VLOOKUP(Tabla3[[#This Row],[Site]],Table35[],14,FALSE) -> https://www.google.com/maps/d/edit?hl=es&mid=1uPmsRMsXnp74hPFW2t-sp2totVWF_xY&ll=32.83050137713022%2C-96.83197783061323&z=17 | L285: =VLOOKUP(Tabla3[[#This Row],[Site]],Table35[#All],2,FALSE) -> - | M285: =VLOOKUP(Tabla3[[#This Row],[Site]],Table35[#All],3,FALSE) -> 2, 14 | N285: =VLOOKUP(Tabla3[[#This Row],[Site]],Table35[#All],4,FALSE) -> - | O285: =VLOOKUP(Tabla3[[#This Row],[Site]],Table35[#All],5,FALSE) -> - | P285: =VLOOKUP(Tabla3[[#This Row],[Site]],Table35[#All],6,FALSE) -> 1, 3, 9, 10, 14 | Q285: =VLOOKUP(Tabla3[[#This Row],[Site]],Table35[#All],8,FALSE) -> 305
A286: =+Tabla3[[#This Row],[Site]]&Tabla3[[#This Row],[Split]] -> (AS) Hare Chevrolet (NO TOURS)5 | B286: 5 | C286: 5 | D286: (AS) Hare Chevrolet (NO TOURS) | E286: =VLOOKUP(Tabla3[[#This Row],[Site]],Table35[],10,FALSE) -> 9:00 P.M. | F286: =VLOOKUP(Tabla3[[#This Row],[Site]],Table35[],11,FALSE) -> ET | G286: =VLOOKUP(Tabla3[[#This Row],[Site]],Table35[],12,FALSE) -> 5:00 A.M. | H286: - | I286: =HYPERLINK(VLOOKUP(Tabla3[[#This Row],[Site]],Table35[#All],9,FALSE)) -> https://tools.sig.systems/site/details/301 | J286: =VLOOKUP(Tabla3[[#This Row],[Site]],Table35[],14,FALSE) -> https://www.google.com/maps/d/edit?mid=1hsX5GGrNcCQgAuzDCDz1OWgEkhsAc78&usp=sharing | L286: =VLOOKUP(Tabla3[[#This Row],[Site]],Table35[#All],2,FALSE) -> 18, 24 | M286: =VLOOKUP(Tabla3[[#This Row],[Site]],Table35[#All],3,FALSE) -> 2, 3 | N286: =VLOOKUP(Tabla3[[#This Row],[Site]],Table35[#All],4,FALSE) -> - | O286: =VLOOKUP(Tabla3[[#This Row],[Site]],Table35[#All],5,FALSE) -> 5 | P286: =VLOOKUP(Tabla3[[#This Row],[Site]],Table35[#All],6,FALSE) -> 1, 5, 7, 8, 21, 29 | Q286: =VLOOKUP(Tabla3[[#This Row],[Site]],Table35[#All],8,FALSE) -> 301
A287: =+Tabla3[[#This Row],[Site]]&Tabla3[[#This Row],[Split]] -> (AS) Koons Arlington Toyota - New Car (NO TOURS)5 | B287: 5 | C287: 5 | D287: (AS) Koons Arlington Toyota - New Car (NO TOURS) | E287: =VLOOKUP(Tabla3[[#This Row],[Site]],Table35[],10,FALSE) -> 9:00 P.M. | F287: =VLOOKUP(Tabla3[[#This Row],[Site]],Table35[],11,FALSE) -> ET | G287: =VLOOKUP(Tabla3[[#This Row],[Site]],Table35[],12,FALSE) -> 5:00 A.M. | H287: 11:00 A.M. | I287: =HYPERLINK(VLOOKUP(Tabla3[[#This Row],[Site]],Table35[#All],9,FALSE)) -> https://tools.sig.systems/site/details/334 | J287: =VLOOKUP(Tabla3[[#This Row],[Site]],Table35[],14,FALSE) -> - | L287: =VLOOKUP(Tabla3[[#This Row],[Site]],Table35[#All],2,FALSE) -> - | M287: =VLOOKUP(Tabla3[[#This Row],[Site]],Table35[#All],3,FALSE) -> 1, 3, 12, 15, 17 | N287: =VLOOKUP(Tabla3[[#This Row],[Site]],Table35[#All],4,FALSE) -> - | O287: =VLOOKUP(Tabla3[[#This Row],[Site]],Table35[#All],5,FALSE) -> - | P287: =VLOOKUP(Tabla3[[#This Row],[Site]],Table35[#All],6,FALSE) -> 2, 6, 18, 20 | Q287: =VLOOKUP(Tabla3[[#This Row],[Site]],Table35[#All],8,FALSE) -> 334
A288: =+Tabla3[[#This Row],[Site]]&Tabla3[[#This Row],[Split]] -> (AS) Koons Chevrolet Buick GMC - Tysons Remote Lot (NO TOURS)5 | B288: 5 | C288: 5 | D288: (AS) Koons Chevrolet Buick GMC - Tysons Remote Lot (NO TOURS) | E288: =VLOOKUP(Tabla3[[#This Row],[Site]],Table35[],10,FALSE) -> 9:00 P.M. | F288: =VLOOKUP(Tabla3[[#This Row],[Site]],Table35[],11,FALSE) -> ET | G288: =VLOOKUP(Tabla3[[#This Row],[Site]],Table35[],12,FALSE) -> 5:00 A.M. | H288: - | I288: =HYPERLINK(VLOOKUP(Tabla3[[#This Row],[Site]],Table35[#All],9,FALSE)) -> https://tools.sig.systems/site/details/333 | J288: =VLOOKUP(Tabla3[[#This Row],[Site]],Table35[],14,FALSE) -> - | L288: =VLOOKUP(Tabla3[[#This Row],[Site]],Table35[#All],2,FALSE) -> - | M288: =VLOOKUP(Tabla3[[#This Row],[Site]],Table35[#All],3,FALSE) -> 6 | N288: =VLOOKUP(Tabla3[[#This Row],[Site]],Table35[#All],4,FALSE) -> 1, 2, 3 | O288: =VLOOKUP(Tabla3[[#This Row],[Site]],Table35[#All],5,FALSE) -> 7, 10, 16, 29 | P288: =VLOOKUP(Tabla3[[#This Row],[Site]],Table35[#All],6,FALSE) -> 14, 17, 30 | Q288: =VLOOKUP(Tabla3[[#This Row],[Site]],Table35[#All],8,FALSE) -> 333
A289: =+Tabla3[[#This Row],[Site]]&Tabla3[[#This Row],[Split]] -> (AS) Koons Volvo Cars White Marsh (NO TOURS)5 | B289: 5 | C289: 5 | D289: (AS) Koons Volvo Cars White Marsh (NO TOURS) | E289: =VLOOKUP(Tabla3[[#This Row],[Site]],Table35[],10,FALSE) -> 9:00 P.M. | F289: =VLOOKUP(Tabla3[[#This Row],[Site]],Table35[],11,FALSE) -> ET | G289: =VLOOKUP(Tabla3[[#This Row],[Site]],Table35[],12,FALSE) -> 5:00 A.M. | H289: 10:00 A.M. | I289: =HYPERLINK(VLOOKUP(Tabla3[[#This Row],[Site]],Table35[#All],9,FALSE)) -> https://tools.sig.systems/site/details/338 | J289: =VLOOKUP(Tabla3[[#This Row],[Site]],Table35[],14,FALSE) -> 0 | L289: =VLOOKUP(Tabla3[[#This Row],[Site]],Table35[#All],2,FALSE) -> - | M289: =VLOOKUP(Tabla3[[#This Row],[Site]],Table35[#All],3,FALSE) -> 5, 7, 9 | N289: =VLOOKUP(Tabla3[[#This Row],[Site]],Table35[#All],4,FALSE) -> - | O289: =VLOOKUP(Tabla3[[#This Row],[Site]],Table35[#All],5,FALSE) -> - | P289: =VLOOKUP(Tabla3[[#This Row],[Site]],Table35[#All],6,FALSE) -> 6, 10, 1 | Q289: =VLOOKUP(Tabla3[[#This Row],[Site]],Table35[#All],8,FALSE) -> 338
A290: =+Tabla3[[#This Row],[Site]]&Tabla3[[#This Row],[Split]] -> (BRL) Shoemakersville5 | B290: 5 | C290: 5 | D290: (BRL) Shoemakersville | E290: =VLOOKUP(Tabla3[[#This Row],[Site]],Table35[],10,FALSE) -> 24H | F290: =VLOOKUP(Tabla3[[#This Row],[Site]],Table35[],11,FALSE) -> ET | G290: =VLOOKUP(Tabla3[[#This Row],[Site]],Table35[],12,FALSE) -> - | H290: - | I290: =HYPERLINK(VLOOKUP(Tabla3[[#This Row],[Site]],Table35[#All],9,FALSE)) -> https://tools.sig.systems/site/details/302 | J290: =VLOOKUP(Tabla3[[#This Row],[Site]],Table35[],14,FALSE) -> 0 | L290: =VLOOKUP(Tabla3[[#This Row],[Site]],Table35[#All],2,FALSE) -> - | M290: =VLOOKUP(Tabla3[[#This Row],[Site]],Table35[#All],3,FALSE) -> 8, 11 | N290: =VLOOKUP(Tabla3[[#This Row],[Site]],Table35[#All],4,FALSE) -> - | O290: =VLOOKUP(Tabla3[[#This Row],[Site]],Table35[#All],5,FALSE) -> 1, 6, 13A, 15, 18A | P290: =VLOOKUP(Tabla3[[#This Row],[Site]],Table35[#All],6,FALSE) -> 13B, 23 | Q290: =VLOOKUP(Tabla3[[#This Row],[Site]],Table35[#All],8,FALSE) -> 302
A291: =+Tabla3[[#This Row],[Site]]&Tabla3[[#This Row],[Split]] -> (DT) Arlington5 | B291: 5 | C291: 5 | D291: (DT) Arlington | E291: =VLOOKUP(Tabla3[[#This Row],[Site]],Table35[],10,FALSE) -> 10:00 P.M. | F291: =VLOOKUP(Tabla3[[#This Row],[Site]],Table35[],11,FALSE) -> CT | G291: =VLOOKUP(Tabla3[[#This Row],[Site]],Table35[],12,FALSE) -> 6:00 A.M. | H291: - | I291: =HYPERLINK(VLOOKUP(Tabla3[[#This Row],[Site]],Table35[#All],9,FALSE)) -> https://tools.sig.systems/site/details/199 | J291: =VLOOKUP(Tabla3[[#This Row],[Site]],Table35[],14,FALSE) -> - | L291: =VLOOKUP(Tabla3[[#This Row],[Site]],Table35[#All],2,FALSE) -> 3,8 | M291: =VLOOKUP(Tabla3[[#This Row],[Site]],Table35[#All],3,FALSE) -> - | N291: =VLOOKUP(Tabla3[[#This Row],[Site]],Table35[#All],4,FALSE) -> - | O291: =VLOOKUP(Tabla3[[#This Row],[Site]],Table35[#All],5,FALSE) -> - | P291: =VLOOKUP(Tabla3[[#This Row],[Site]],Table35[#All],6,FALSE) -> 3, 8, 7 | Q291: =VLOOKUP(Tabla3[[#This Row],[Site]],Table35[#All],8,FALSE) -> 199
A292: =+Tabla3[[#This Row],[Site]]&Tabla3[[#This Row],[Split]] -> (LT) Luther Bloomington Hyundai (NO TOURS)5 | B292: 5 | C292: 5 | D292: (LT) Luther Bloomington Hyundai (NO TOURS) | E292: =VLOOKUP(Tabla3[[#This Row],[Site]],Table35[],10,FALSE) -> 10:00 P.M. | F292: =VLOOKUP(Tabla3[[#This Row],[Site]],Table35[],11,FALSE) -> CT | G292: =VLOOKUP(Tabla3[[#This Row],[Site]],Table35[],12,FALSE) -> 4:00 A.M. | H292: - | I292: =HYPERLINK(VLOOKUP(Tabla3[[#This Row],[Site]],Table35[#All],9,FALSE)) -> https://tools.sig.systems/site/details/318 | J292: =VLOOKUP(Tabla3[[#This Row],[Site]],Table35[],14,FALSE) -> 0 | L292: =VLOOKUP(Tabla3[[#This Row],[Site]],Table35[#All],2,FALSE) -> - | M292: =VLOOKUP(Tabla3[[#This Row],[Site]],Table35[#All],3,FALSE) -> 6, 9, 13 | N292: =VLOOKUP(Tabla3[[#This Row],[Site]],Table35[#All],4,FALSE) -> 58, 59 | O292: =VLOOKUP(Tabla3[[#This Row],[Site]],Table35[#All],5,FALSE) -> 10 | P292: =VLOOKUP(Tabla3[[#This Row],[Site]],Table35[#All],6,FALSE) -> 11, 18 | Q292: =VLOOKUP(Tabla3[[#This Row],[Site]],Table35[#All],8,FALSE) -> 318
A293: =+Tabla3[[#This Row],[Site]]&Tabla3[[#This Row],[Split]] -> (LT) Luther Landers Recon Center5 | B293: 5 | C293: 5 | D293: (LT) Luther Landers Recon Center | E293: =VLOOKUP(Tabla3[[#This Row],[Site]],Table35[],10,FALSE) -> 10:00 P.M. | F293: =VLOOKUP(Tabla3[[#This Row],[Site]],Table35[],11,FALSE) -> CT | G293: =VLOOKUP(Tabla3[[#This Row],[Site]],Table35[],12,FALSE) -> 6:00 A.M. | H293: - | I293: =HYPERLINK(VLOOKUP(Tabla3[[#This Row],[Site]],Table35[#All],9,FALSE)) -> https://tools.sig.systems/site/details/323 | J293: =VLOOKUP(Tabla3[[#This Row],[Site]],Table35[],14,FALSE) -> https://www.google.com/maps/d/u/1/edit?mid=1-zEzsc6U6nZom08edp0XAd3_HYFvAyk&usp=sharing | L293: =VLOOKUP(Tabla3[[#This Row],[Site]],Table35[#All],2,FALSE) -> 2, 4 | M293: =VLOOKUP(Tabla3[[#This Row],[Site]],Table35[#All],3,FALSE) -> - | N293: =VLOOKUP(Tabla3[[#This Row],[Site]],Table35[#All],4,FALSE) -> - | O293: =VLOOKUP(Tabla3[[#This Row],[Site]],Table35[#All],5,FALSE) -> - | P293: =VLOOKUP(Tabla3[[#This Row],[Site]],Table35[#All],6,FALSE) -> 3, 9, 11 | Q293: =VLOOKUP(Tabla3[[#This Row],[Site]],Table35[#All],8,FALSE) -> 323
A294: =+Tabla3[[#This Row],[Site]]&Tabla3[[#This Row],[Split]] -> (LT) Luther St. Cloud Subaru5 | B294: 5 | C294: 5 | D294: (LT) Luther St. Cloud Subaru | E294: =VLOOKUP(Tabla3[[#This Row],[Site]],Table35[],10,FALSE) -> 10:00 P.M. | F294: =VLOOKUP(Tabla3[[#This Row],[Site]],Table35[],11,FALSE) -> CT | G294: =VLOOKUP(Tabla3[[#This Row],[Site]],Table35[],12,FALSE) -> 5:30 A.M. | H294: - | I294: =HYPERLINK(VLOOKUP(Tabla3[[#This Row],[Site]],Table35[#All],9,FALSE)) -> https://tools.sig.systems/site/details/295 | J294: =VLOOKUP(Tabla3[[#This Row],[Site]],Table35[],14,FALSE) -> 0 | L294: =VLOOKUP(Tabla3[[#This Row],[Site]],Table35[#All],2,FALSE) -> 25, 31 | M294: =VLOOKUP(Tabla3[[#This Row],[Site]],Table35[#All],3,FALSE) -> 9, 13, 20 | N294: =VLOOKUP(Tabla3[[#This Row],[Site]],Table35[#All],4,FALSE) -> 38, 39, 40, 41 | O294: =VLOOKUP(Tabla3[[#This Row],[Site]],Table35[#All],5,FALSE) -> 27 | P294: =VLOOKUP(Tabla3[[#This Row],[Site]],Table35[#All],6,FALSE) -> 2, 6, 8, 11, 14, 19, 23, 26 | Q294: =VLOOKUP(Tabla3[[#This Row],[Site]],Table35[#All],8,FALSE) -> 295
A295: =+Tabla3[[#This Row],[Site]]&Tabla3[[#This Row],[Split]] -> (SCH) Schumacher of Delray I & III5 | B295: 5 | C295: 5 | D295: (SCH) Schumacher of Delray I & III | E295: =VLOOKUP(Tabla3[[#This Row],[Site]],Table35[],10,FALSE) -> 9:00 P.M. | F295: =VLOOKUP(Tabla3[[#This Row],[Site]],Table35[],11,FALSE) -> ET | G295: =VLOOKUP(Tabla3[[#This Row],[Site]],Table35[],12,FALSE) -> 5:00 A.M. | H295: - | I295: =HYPERLINK(VLOOKUP(Tabla3[[#This Row],[Site]],Table35[#All],9,FALSE)) -> https://tools.sig.systems/site/details/159 | J295: =VLOOKUP(Tabla3[[#This Row],[Site]],Table35[],14,FALSE) -> https://www.google.com/maps/d/viewer?mid=1ZLGV-cDM9aCfovhmXHIAXgVOKts0dEI&ll=26.438859950088858%2C-80.07968125000001&z=16 | L295: =VLOOKUP(Tabla3[[#This Row],[Site]],Table35[#All],2,FALSE) -> 11, 21, 22, 57, 69 | M295: =VLOOKUP(Tabla3[[#This Row],[Site]],Table35[#All],3,FALSE) -> 2, 16, 46 | N295: =VLOOKUP(Tabla3[[#This Row],[Site]],Table35[#All],4,FALSE) -> - | O295: =VLOOKUP(Tabla3[[#This Row],[Site]],Table35[#All],5,FALSE) -> - | P295: =VLOOKUP(Tabla3[[#This Row],[Site]],Table35[#All],6,FALSE) -> 24, 39 | Q295: =VLOOKUP(Tabla3[[#This Row],[Site]],Table35[#All],8,FALSE) -> 159
A296: =+Tabla3[[#This Row],[Site]]&Tabla3[[#This Row],[Split]] -> (TC) Lamborghini South Dade5 | B296: 5 | C296: 5 | D296: (TC) Lamborghini South Dade | E296: =VLOOKUP(Tabla3[[#This Row],[Site]],Table35[],10,FALSE) -> 9:00 P.M. | F296: =VLOOKUP(Tabla3[[#This Row],[Site]],Table35[],11,FALSE) -> ET | G296: =VLOOKUP(Tabla3[[#This Row],[Site]],Table35[],12,FALSE) -> 5:00 A.M. | H296: - | I296: =HYPERLINK(VLOOKUP(Tabla3[[#This Row],[Site]],Table35[#All],9,FALSE)) -> https://tools.sig.systems/site/details/313 | J296: =VLOOKUP(Tabla3[[#This Row],[Site]],Table35[],14,FALSE) -> 0 | L296: =VLOOKUP(Tabla3[[#This Row],[Site]],Table35[#All],2,FALSE) -> - | M296: =VLOOKUP(Tabla3[[#This Row],[Site]],Table35[#All],3,FALSE) -> 9, 11 | N296: =VLOOKUP(Tabla3[[#This Row],[Site]],Table35[#All],4,FALSE) -> - | O296: =VLOOKUP(Tabla3[[#This Row],[Site]],Table35[#All],5,FALSE) -> - | P296: =VLOOKUP(Tabla3[[#This Row],[Site]],Table35[#All],6,FALSE) -> - | Q296: =VLOOKUP(Tabla3[[#This Row],[Site]],Table35[#All],8,FALSE) -> 313
A297: =+Tabla3[[#This Row],[Site]]&Tabla3[[#This Row],[Split]] -> (AS) 3281 Storage Lot (NO TOURS)6 | B297: 6 | C297: 1 | D297: (AS) 3281 Storage Lot (NO TOURS) | E297: =VLOOKUP(Tabla3[[#This Row],[Site]],Table35[],10,FALSE) -> 10:00 P.M. | F297: =VLOOKUP(Tabla3[[#This Row],[Site]],Table35[],11,FALSE) -> CT | G297: =VLOOKUP(Tabla3[[#This Row],[Site]],Table35[],12,FALSE) -> 6:00 A.M. | H297: 10:00 A.M. | I297: =HYPERLINK(VLOOKUP(Tabla3[[#This Row],[Site]],Table35[#All],9,FALSE)) -> https://tools.sig.systems/site/details/305 | J297: =VLOOKUP(Tabla3[[#This Row],[Site]],Table35[],14,FALSE) -> https://www.google.com/maps/d/edit?hl=es&mid=1uPmsRMsXnp74hPFW2t-sp2totVWF_xY&ll=32.83050137713022%2C-96.83197783061323&z=17 | L297: =VLOOKUP(Tabla3[[#This Row],[Site]],Table35[#All],2,FALSE) -> - | M297: =VLOOKUP(Tabla3[[#This Row],[Site]],Table35[#All],3,FALSE) -> 2, 14 | N297: =VLOOKUP(Tabla3[[#This Row],[Site]],Table35[#All],4,FALSE) -> - | O297: =VLOOKUP(Tabla3[[#This Row],[Site]],Table35[#All],5,FALSE) -> - | P297: =VLOOKUP(Tabla3[[#This Row],[Site]],Table35[#All],6,FALSE) -> 1, 3, 9, 10, 14 | Q297: =VLOOKUP(Tabla3[[#This Row],[Site]],Table35[#All],8,FALSE) -> 305
... A327: =+Tabla3[[#This Row],[Site]]&Tabla3[[#This Row],[Split]] -> (PE) MB of Greenwich6 | B327: 6 | C327: 3 | D327: (PE) MB of Greenwich | E327: =VLOOKUP(Tabla3[[#This Row],[Site]],Table35[],10,FALSE) -> 8:00 P.M. | F327: =VLOOKUP(Tabla3[[#This Row],[Site]],Table35[],11,FALSE) -> ET | G327: =VLOOKUP(Tabla3[[#This Row],[Site]],Table35[],12,FALSE) -> 5:00 A.M. | H327: - | I327: =HYPERLINK(VLOOKUP(Tabla3[[#This Row],[Site]],Table35[#All],9,FALSE)) -> https://tools.sig.systems/site/details/188 | J327: =VLOOKUP(Tabla3[[#This Row],[Site]],Table35[],14,FALSE) -> https://www.google.com/maps/d/edit?hl=en&mid=1UHmt7tH1ihTa85i0MfQIcTfVvIQg_vM&ll=41.02423447529239%2C-73.63721502222738&z=18 | L327: =VLOOKUP(Tabla3[[#This Row],[Site]],Table35[#All],2,FALSE) -> 1, 2, 8 | M327: =VLOOKUP(Tabla3[[#This Row],[Site]],Table35[#All],3,FALSE) -> 13, 14, 20, 26, 40 | N327: =VLOOKUP(Tabla3[[#This Row],[Site]],Table35[#All],4,FALSE) -> - | O327: =VLOOKUP(Tabla3[[#This Row],[Site]],Table35[#All],5,FALSE) -> - | P327: =VLOOKUP(Tabla3[[#This Row],[Site]],Table35[#All],6,FALSE) -> 29 | Q327: =VLOOKUP(Tabla3[[#This Row],[Site]],Table35[#All],8,FALSE) -> 188
A328: =+Tabla3[[#This Row],[Site]]&Tabla3[[#This Row],[Split]] -> Mario Residence6 | B328: 6 | C328: 3 | D328: Mario Residence | E328: =VLOOKUP(Tabla3[[#This Row],[Site]],Table35[],10,FALSE) -> 24H | F328: =VLOOKUP(Tabla3[[#This Row],[Site]],Table35[],11,FALSE) -> ET | G328: =VLOOKUP(Tabla3[[#This Row],[Site]],Table35[],12,FALSE) -> - | I328: =HYPERLINK(VLOOKUP(Tabla3[[#This Row],[Site]],Table35[#All],9,FALSE)) -> https://tools.sig.systems/site/details/148 | J328: =VLOOKUP(Tabla3[[#This Row],[Site]],Table35[],14,FALSE) -> https://www.google.com/maps/d/edit?hl=es&mid=13OmECPqyeB7fXgZmEoM9cnG34HU_v5g&ll=26.046837034777553%2C-80.38753458591658&z=19 | L328: =VLOOKUP(Tabla3[[#This Row],[Site]],Table35[#All],2,FALSE) -> 7, 8 | M328: =VLOOKUP(Tabla3[[#This Row],[Site]],Table35[#All],3,FALSE) -> 7, 8 | N328: =VLOOKUP(Tabla3[[#This Row],[Site]],Table35[#All],4,FALSE) -> - | O328: =VLOOKUP(Tabla3[[#This Row],[Site]],Table35[#All],5,FALSE) -> - | P328: =VLOOKUP(Tabla3[[#This Row],[Site]],Table35[#All],6,FALSE) -> 4,12,13 | Q328: =VLOOKUP(Tabla3[[#This Row],[Site]],Table35[#All],8,FALSE) -> 148
A329: =+Tabla3[[#This Row],[Site]]&Tabla3[[#This Row],[Split]] -> (AS) Coggin Honda of Orlando (NO TOURS)6 | B329: 6 | C329: 4 | D329: (AS) Coggin Honda of Orlando (NO TOURS) | E329: =VLOOKUP(Tabla3[[#This Row],[Site]],Table35[],10,FALSE) -> 9:00 P.M. | F329: =VLOOKUP(Tabla3[[#This Row],[Site]],Table35[],11,FALSE) -> ET | G329: =VLOOKUP(Tabla3[[#This Row],[Site]],Table35[],12,FALSE) -> 5:00 A.M. | H329: - | I329: =HYPERLINK(VLOOKUP(Tabla3[[#This Row],[Site]],Table35[#All],9,FALSE)) -> https://tools.sig.systems/site/details/324 | J329: =VLOOKUP(Tabla3[[#This Row],[Site]],Table35[],14,FALSE) -> 0 | L329: =VLOOKUP(Tabla3[[#This Row],[Site]],Table35[#All],2,FALSE) -> 2, 10, 12B, 14, 38 | M329: =VLOOKUP(Tabla3[[#This Row],[Site]],Table35[#All],3,FALSE) -> - | N329: =VLOOKUP(Tabla3[[#This Row],[Site]],Table35[#All],4,FALSE) -> - | O329: =VLOOKUP(Tabla3[[#This Row],[Site]],Table35[#All],5,FALSE) -> 12, 31 | P329: =VLOOKUP(Tabla3[[#This Row],[Site]],Table35[#All],6,FALSE) -> 12B, 26, 37, 19 | Q329: =VLOOKUP(Tabla3[[#This Row],[Site]],Table35[#All],8,FALSE) -> 324
A330: =+Tabla3[[#This Row],[Site]]&Tabla3[[#This Row],[Split]] -> (AS) Kahlo CDJR (NO TOURS)6 | B330: 6 | C330: 4 | D330: (AS) Kahlo CDJR (NO TOURS) | E330: =VLOOKUP(Tabla3[[#This Row],[Site]],Table35[],10,FALSE) -> 9:00 P.M. | F330: =VLOOKUP(Tabla3[[#This Row],[Site]],Table35[],11,FALSE) -> ET | G330: =VLOOKUP(Tabla3[[#This Row],[Site]],Table35[],12,FALSE) -> 5:00 A.M. | H330: 11:00 A.M. | I330: =HYPERLINK(VLOOKUP(Tabla3[[#This Row],[Site]],Table35[#All],9,FALSE)) -> https://tools.sig.systems/site/details/282 | J330: =VLOOKUP(Tabla3[[#This Row],[Site]],Table35[],14,FALSE) -> https://www.google.com/maps/d/edit?mid=1hsX5GGrNcCQgAuzDCDz1OWgEkhsAc78&usp=sharing | L330: =VLOOKUP(Tabla3[[#This Row],[Site]],Table35[#All],2,FALSE) -> - | M330: =VLOOKUP(Tabla3[[#This Row],[Site]],Table35[#All],3,FALSE) -> 12, 25 | N330: =VLOOKUP(Tabla3[[#This Row],[Site]],Table35[#All],4,FALSE) -> 15, 16 | O330: =VLOOKUP(Tabla3[[#This Row],[Site]],Table35[#All],5,FALSE) -> 20 | P330: =VLOOKUP(Tabla3[[#This Row],[Site]],Table35[#All],6,FALSE) -> 1, 2, 9, 22, 31, 57 | Q330: =VLOOKUP(Tabla3[[#This Row],[Site]],Table35[#All],8,FALSE) -> 282
A331: =+Tabla3[[#This Row],[Site]]&Tabla3[[#This Row],[Split]] -> (AS) Koons Baltimore Ford - Main Dealership (NO TOURS)6 | B331: 6 | C331: 4 | D331: (AS) Koons Baltimore Ford - Main Dealership (NO TOURS) | E331: =VLOOKUP(Tabla3[[#This Row],[Site]],Table35[],10,FALSE) -> 9:00 P.M. | F331: =VLOOKUP(Tabla3[[#This Row],[Site]],Table35[],11,FALSE) -> ET | G331: =VLOOKUP(Tabla3[[#This Row],[Site]],Table35[],12,FALSE) -> 5:00 A.M. | H331: - | I331: =HYPERLINK(VLOOKUP(Tabla3[[#This Row],[Site]],Table35[#All],9,FALSE)) -> https://tools.sig.systems/site/details/335 | J331: =VLOOKUP(Tabla3[[#This Row],[Site]],Table35[],14,FALSE) -> - | L331: =VLOOKUP(Tabla3[[#This Row],[Site]],Table35[#All],2,FALSE) -> 21, 22, 24, 32, 45 | M331: =VLOOKUP(Tabla3[[#This Row],[Site]],Table35[#All],3,FALSE) -> 1 | N331: =VLOOKUP(Tabla3[[#This Row],[Site]],Table35[#All],4,FALSE) -> - | O331: =VLOOKUP(Tabla3[[#This Row],[Site]],Table35[#All],5,FALSE) -> 1, 8 | P331: =VLOOKUP(Tabla3[[#This Row],[Site]],Table35[#All],6,FALSE) -> 5, 28, 38 | Q331: =VLOOKUP(Tabla3[[#This Row],[Site]],Table35[#All],8,FALSE) -> 335
A332: =+Tabla3[[#This Row],[Site]]&Tabla3[[#This Row],[Split]] -> (AS) Koons Easton Toyota - Main Dealership (NO TOURS)6 | B332: 6 | C332: 4 | D332: (AS) Koons Easton Toyota - Main Dealership (NO TOURS) | E332: =VLOOKUP(Tabla3[[#This Row],[Site]],Table35[],10,FALSE) -> 9:00 P.M. | F332: =VLOOKUP(Tabla3[[#This Row],[Site]],Table35[],11,FALSE) -> ET | G332: =VLOOKUP(Tabla3[[#This Row],[Site]],Table35[],12,FALSE) -> 5:00 A.M. | H332: - | I332: =HYPERLINK(VLOOKUP(Tabla3[[#This Row],[Site]],Table35[#All],9,FALSE)) -> https://tools.sig.systems/site/details/340 | J332: =VLOOKUP(Tabla3[[#This Row],[Site]],Table35[],14,FALSE) -> - | L332: =VLOOKUP(Tabla3[[#This Row],[Site]],Table35[#All],2,FALSE) -> - | M332: =VLOOKUP(Tabla3[[#This Row],[Site]],Table35[#All],3,FALSE) -> 4, 5 | N332: =VLOOKUP(Tabla3[[#This Row],[Site]],Table35[#All],4,FALSE) -> - | O332: =VLOOKUP(Tabla3[[#This Row],[Site]],Table35[#All],5,FALSE) -> - | P332: =VLOOKUP(Tabla3[[#This Row],[Site]],Table35[#All],6,FALSE) -> 8, 15 | Q332: =VLOOKUP(Tabla3[[#This Row],[Site]],Table35[#All],8,FALSE) -> 340
A333: =+Tabla3[[#This Row],[Site]]&Tabla3[[#This Row],[Split]] -> (AS) Plaza Mercedes Benz West (NO TOURS)6 | B333: 6 | C333: 4 | D333: (AS) Plaza Mercedes Benz West (NO TOURS) | E333: =VLOOKUP(Tabla3[[#This Row],[Site]],Table35[],10,FALSE) -> 10:00 P.M. | F333: =VLOOKUP(Tabla3[[#This Row],[Site]],Table35[],11,FALSE) -> CT | G333: =VLOOKUP(Tabla3[[#This Row],[Site]],Table35[],12,FALSE) -> 6:00 A.M. | H333: - | I333: =HYPERLINK(VLOOKUP(Tabla3[[#This Row],[Site]],Table35[#All],9,FALSE)) -> https://tools.sig.systems/site/details/349 | J333: =VLOOKUP(Tabla3[[#This Row],[Site]],Table35[],14,FALSE) -> - | L333: =VLOOKUP(Tabla3[[#This Row],[Site]],Table35[#All],2,FALSE) -> - | M333: =VLOOKUP(Tabla3[[#This Row],[Site]],Table35[#All],3,FALSE) -> 1, 7 | N333: =VLOOKUP(Tabla3[[#This Row],[Site]],Table35[#All],4,FALSE) -> - | O333: =VLOOKUP(Tabla3[[#This Row],[Site]],Table35[#All],5,FALSE) -> 17 | P333: =VLOOKUP(Tabla3[[#This Row],[Site]],Table35[#All],6,FALSE) -> 6, 21 | Q333: =VLOOKUP(Tabla3[[#This Row],[Site]],Table35[#All],8,FALSE) -> 349
A334: =+Tabla3[[#This Row],[Site]]&Tabla3[[#This Row],[Split]] -> (LT) Landers Kia of Little Rock6 | B334: 6 | C334: 4 | D334: (LT) Landers Kia of Little Rock | E334: =VLOOKUP(Tabla3[[#This Row],[Site]],Table35[],10,FALSE) -> 10:00 P.M. | F334: =VLOOKUP(Tabla3[[#This Row],[Site]],Table35[],11,FALSE) -> CT | G334: =VLOOKUP(Tabla3[[#This Row],[Site]],Table35[],12,FALSE) -> 6:00 A.M. | H334: - | I334: =HYPERLINK(VLOOKUP(Tabla3[[#This Row],[Site]],Table35[#All],9,FALSE)) -> https://tools.sig.systems/site/details/322 | J334: =VLOOKUP(Tabla3[[#This Row],[Site]],Table35[],14,FALSE) -> https://www.google.com/maps/d/u/1/edit?mid=1-zEzsc6U6nZom08edp0XAd3_HYFvAyk&usp=sharing | L334: =VLOOKUP(Tabla3[[#This Row],[Site]],Table35[#All],2,FALSE) -> 5, 9, 33, 19 | M334: =VLOOKUP(Tabla3[[#This Row],[Site]],Table35[#All],3,FALSE) -> - | N334: =VLOOKUP(Tabla3[[#This Row],[Site]],Table35[#All],4,FALSE) -> 4, 10 | O334: =VLOOKUP(Tabla3[[#This Row],[Site]],Table35[#All],5,FALSE) -> 1, 35 | P334: =VLOOKUP(Tabla3[[#This Row],[Site]],Table35[#All],6,FALSE) -> 5, 9, 12, 14, 18, 26, 29 | Q334: =VLOOKUP(Tabla3[[#This Row],[Site]],Table35[#All],8,FALSE) -> 322
A335: =+Tabla3[[#This Row],[Site]]&Tabla3[[#This Row],[Split]] -> (LT) Luther North Country Ford6 | B335: 6 | C335: 4 | D335: (LT) Luther North Country Ford | E335: =VLOOKUP(Tabla3[[#This Row],[Site]],Table35[],10,FALSE) -> 10:00 P.M. | F335: =VLOOKUP(Tabla3[[#This Row],[Site]],Table35[],11,FALSE) -> CT | G335: =VLOOKUP(Tabla3[[#This Row],[Site]],Table35[],12,FALSE) -> 6:00 A.M. | H335: - | I335: =HYPERLINK(VLOOKUP(Tabla3[[#This Row],[Site]],Table35[#All],9,FALSE)) -> https://tools.sig.systems/site/details/292 | J335: =VLOOKUP(Tabla3[[#This Row],[Site]],Table35[],14,FALSE) -> 0 | L335: =VLOOKUP(Tabla3[[#This Row],[Site]],Table35[#All],2,FALSE) -> - | M335: =VLOOKUP(Tabla3[[#This Row],[Site]],Table35[#All],3,FALSE) -> 7, 14, 19 | N335: =VLOOKUP(Tabla3[[#This Row],[Site]],Table35[#All],4,FALSE) -> 30, 31, 32 | O335: =VLOOKUP(Tabla3[[#This Row],[Site]],Table35[#All],5,FALSE) -> - | P335: =VLOOKUP(Tabla3[[#This Row],[Site]],Table35[#All],6,FALSE) -> 1, 4, 9, 13, 15, 16B, 25 | Q335: =VLOOKUP(Tabla3[[#This Row],[Site]],Table35[#All],8,FALSE) -> 292
A336: =+Tabla3[[#This Row],[Site]]&Tabla3[[#This Row],[Split]] -> (PE) JLR Darien (NO TOURS)6 | B336: 6 | C336: 4 | D336: (PE) JLR Darien (NO TOURS) | E336: =VLOOKUP(Tabla3[[#This Row],[Site]],Table35[],10,FALSE) -> 8:00 P.M. | F336: =VLOOKUP(Tabla3[[#This Row],[Site]],Table35[],11,FALSE) -> ET | G336: =VLOOKUP(Tabla3[[#This Row],[Site]],Table35[],12,FALSE) -> 5:00 A.M. | H336: - | I336: =HYPERLINK(VLOOKUP(Tabla3[[#This Row],[Site]],Table35[#All],9,FALSE)) -> https://tools.sig.systems/site/details/189 | J336: =VLOOKUP(Tabla3[[#This Row],[Site]],Table35[],14,FALSE) -> - | L336: =VLOOKUP(Tabla3[[#This Row],[Site]],Table35[#All],2,FALSE) -> 1, 13 | M336: =VLOOKUP(Tabla3[[#This Row],[Site]],Table35[#All],3,FALSE) -> - | N336: =VLOOKUP(Tabla3[[#This Row],[Site]],Table35[#All],4,FALSE) -> - | O336: =VLOOKUP(Tabla3[[#This Row],[Site]],Table35[#All],5,FALSE) -> - | P336: =VLOOKUP(Tabla3[[#This Row],[Site]],Table35[#All],6,FALSE) -> - | Q336: =VLOOKUP(Tabla3[[#This Row],[Site]],Table35[#All],8,FALSE) -> 189
