Workbook
Name SegmentaciónDeDatos_Split: #N/A
Name SegmentaciónDeDatos_Split1: #N/A
Name SegmentaciónDeDatos_Split11: #N/A
Name SegmentaciónDeDatos_Split2: #N/A
Name SegmentaciónDeDatos_Station: #N/A
Name SegmentaciónDeDatos_Station1: #N/A
Name SegmentaciónDeDatos_Station11: #N/A

Sheet Dynamic Split
AE1: Alphabetical Order
A2: From: Split-Station: | AE2: Site
J3: Searched Site: | M3: Serached Site: | N3: (DT) Wichita | AE3: (AS) Courtesy Honda Palm Harbor (NO TOURS)
AE4: (AS) Park Place Bodywerks Dallas (NO TOURS)
J5: Its On: | M5: Station | N5: =+M5 -> Station | AE5: (AS) Stevinson Porsche of Littleton (NO TOURS)
M6: 6 | N6: =+M6 -> 6 | AE6: (DT) N. Houston
AE7: (JE) Jim Ellis Ford Sandy Springs
AE8: (KG) Big Star Honda
AE9: (ML) BMW of Little Rock
AE10: (ML) Collision Center N Little Rock
AE11: (ML) Joe Machens Nissan
AE12: (PE) JLR Darien PDI (NO TOURS)
A15: Split | B15: Station | C15: Total Sites | H15: Log Out from | I15: Total New Sites
A16: 14 | B16: 8 | C16: 10 | H16: =+COUNTIF('Dynamic Split'!H19:H75,"Log Out") -> 10 | I16: =+GETPIVOTDATA("Site",$C$15)-H16 -> 0
A18: Split | B18: Log Time | C18: Sites | D18: Drop time | E18: ID | F18: Suma de Station | H18: Log Out | I18: SIG Tools | K18: Split | L18: Log Time | M18: Sites | N18: Drop time | O18: T.Z. | P18: SUNDAY (D.T.) | Q18: Gates | R18: Entrances | S18: LPR | T18: PTZ | U18: Important Cameras | V18: Notes* | W18: Sum of Station
A19: 14 | B19: 8:00 P.M. | C19: (PE) JLR Darien PDI (NO TOURS) | D19: 5:00 A.M. | E19: 187 | F19: 8 | H19: =+IF(C19="","",IFERROR(IF(Maestra!A16="#N/D","Log Out",""),"Log Out")) -> Log Out | I19: =IFERROR(HYPERLINK(VLOOKUP(C19,'Flat Base'!F:I,3,I250),"SIG TOOLS"),"") -> SIG TOOLS | J19: =IFERROR(HYPERLINK(VLOOKUP(C19,'Flat Base'!F:I,4,0),"SITE MAP"),"") -> SITE MAP | K19: 14 | L19: 8:00 P.M. | M19: (PE) JLR Darien PDI (NO TOURS) | N19: 5:00 A.M. | O19: ET | P19: N/A | Q19: 1 | R19: - | S19: - | T19: 1 | U19: 7 | V19: - | W19: 8
B20: 9:00 P.M. | C20: (AS) Courtesy Honda Palm Harbor (NO TOURS) | D20: 5:00 A.M. | E20: 176 | F20: 8 | H20: =+IF(C20="","",IFERROR(IF(Maestra!A17="#N/D","Log Out",""),"Log Out")) -> Log Out | I20: =IFERROR(HYPERLINK(VLOOKUP(C20,'Flat Base'!F:I,3,0),"SIG TOOLS"),"") -> SIG TOOLS | J20: =IFERROR(HYPERLINK(VLOOKUP(C20,'Flat Base'!F:I,4,0),"SITE MAP"),"") -> SITE MAP | L20: 9:00 P.M. | M20: (AS) Courtesy Honda Palm Harbor (NO TOURS) | N20: 5:00 A.M. | O20: ET | P20: 11:00 A.M. | Q20: 2 | R20: - | S20: - | T20: 4, 8, 21 | U20: 10 | V20: - | W20: 8
C21: (JE) Jim Ellis Ford Sandy Springs | D21: 5:00 A.M. | E21: 142 | F21: 8 | H21: =+IF(C21="","",IFERROR(IF(Maestra!A18="#N/D","Log Out",""),"Log Out")) -> Log Out | I21: =IFERROR(HYPERLINK(VLOOKUP(C21,'Flat Base'!F:I,3,0),"SIG TOOLS"),"") -> SIG TOOLS | J21: =IFERROR(HYPERLINK(VLOOKUP(C21,'Flat Base'!F:I,4,0),"SITE MAP"),"") -> SITE MAP | M21: (JE) Jim Ellis Ford Sandy Springs | N21: 5:00 A.M. | O21: ET | P21: N/A | Q21: 1, 5 | R21: - | S21: - | T21: 1, 5, 9, 26 | U21: 3, 4, 8, 28 | V21: - | W21: 8
B22: 10:00 P.M. | C22: (DT) N. Houston | D22: 6:00 A.M. | E22: 250 | F22: 8 | H22: =+IF(C22="","",IFERROR(IF(Maestra!A19="#N/D","Log Out",""),"Log Out")) -> Log Out | I22: =IFERROR(HYPERLINK(VLOOKUP(C22,'Flat Base'!F:I,3,0),"SIG TOOLS"),"") -> SIG TOOLS | J22: =IFERROR(HYPERLINK(VLOOKUP(C22,'Flat Base'!F:I,4,0),"SITE MAP"),"") -> SITE MAP | L22: 10:00 P.M. | M22: (DT) N. Houston | N22: 6:00 A.M. | O22: CT | P22: N/A | Q22: 2, 10, 18 | R22: - | S22: - | T22: 15 | U22: 2, 4, 18 | V22: - | W22: 8
C23: (KG) Big Star Honda | D23: 6:00 A.M. | E23: 231 | F23: 8 | H23: =+IF(C23="","",IFERROR(IF(Maestra!A20="#N/D","Log Out",""),"Log Out")) -> Log Out | I23: =IFERROR(HYPERLINK(VLOOKUP(C23,'Flat Base'!F:I,3,0),"SIG TOOLS"),"") -> SIG TOOLS | J23: =IFERROR(HYPERLINK(VLOOKUP(C23,'Flat Base'!F:I,4,0),"SITE MAP"),"") -> SITE MAP | M23: (KG) Big Star Honda | N23: 6:00 A.M. | O23: CT | P23: N/A | Q23: 2, 17, 33 | R23: - | S23: - | T23: 3, 11, 16, 21, 24, 31, 34 | U23: 2, 3, 17, 22, 37, 41, 42 | V23: - | W23: 8
C24: (ML) BMW of Little Rock | D24: 6:00 A.M. | E24: 217 | F24: 8 | H24: =+IF(C24="","",IFERROR(IF(Maestra!A21="#N/D","Log Out",""),"Log Out")) -> Log Out | I24: =IFERROR(HYPERLINK(VLOOKUP(C24,'Flat Base'!F:I,3,0),"SIG TOOLS"),"") -> SIG TOOLS | J24: =IFERROR(HYPERLINK(VLOOKUP(C24,'Flat Base'!F:I,4,0),"SITE MAP"),"") -> SITE MAP | M24: (ML) BMW of Little Rock | N24: 6:00 A.M. | O24: CT | P24: N/A | Q24: - | R24: 14 | S24: - | T24: - | U24: 5, 6, 7, 8, 9, 32 | V24: - | W24: 8
C25: (ML) Collision Center N Little Rock | D25: 6:00 A.M. | E25: 212 | F25: 8 | H25: =+IF(C25="","",IFERROR(IF(Maestra!A22="#N/D","Log Out",""),"Log Out")) -> Log Out | I25: =IFERROR(HYPERLINK(VLOOKUP(C25,'Flat Base'!F:I,3,0),"SIG TOOLS"),"") -> SIG TOOLS | J25: =IFERROR(HYPERLINK(VLOOKUP(C25,'Flat Base'!F:I,4,0),"SITE MAP"),"") -> SITE MAP | M25: (ML) Collision Center N Little Rock | N25: 6:00 A.M. | O25: CT | P25: N/A | Q25: - | R25: - | S25: - | T25: - | U25: 1, 3, 7, 8 | V25: - | W25: 8
C26: (ML) Joe Machens Nissan | D26: 6:00 A.M. | E26: 279 | F26: 8 | H26: =+IF(C26="","",IFERROR(IF(Maestra!A23="#N/D","Log Out",""),"Log Out")) -> Log Out | I26: =IFERROR(HYPERLINK(VLOOKUP(C26,'Flat Base'!F:I,3,0),"SIG TOOLS"),"") -> SIG TOOLS | J26: =IFERROR(HYPERLINK(VLOOKUP(C26,'Flat Base'!F:I,4,0),"SITE MAP"),"") -> SITE MAP | M26: (ML) Joe Machens Nissan | N26: 6:00 A.M. | O26: CT | P26: N/A | Q26: - | R26: 1, 3, 16 | S26: - | T26: - | U26: - | V26: - | W26: 8
C27: (AS) Park Place Bodywerks Dallas (NO TOURS) | D27: 6:00 A.M. | E27: 166 | F27: 8 | H27: =+IF(C27="","",IFERROR(IF(Maestra!A24="#N/D","Log Out",""),"Log Out")) -> Log Out | I27: =IFERROR(HYPERLINK(VLOOKUP(C27,'Flat Base'!F:I,3,0),"SIG TOOLS"),"") -> SIG TOOLS | J27: =IFERROR(HYPERLINK(VLOOKUP(C27,'Flat Base'!F:I,4,0),"SITE MAP"),"") -> SITE MAP | M27: (AS) Park Place Bodywerks Dallas (NO TOURS) | N27: 6:00 A.M. | O27: CT | P27: N/A | Q27: 3 | R27: 1 | S27: - | T27: - | U27: 1, 2, 8 | V27: - | W27: 8
B28: 11:00 P.M. | C28: (AS) Stevinson Porsche of Littleton (NO TOURS) | D28: 7:00 A.M. | E28: 242 | F28: 8 | H28: =+IF(C28="","",IFERROR(IF(Maestra!A25="#N/D","Log Out",""),"Log Out")) -> Log Out | I28: =IFERROR(HYPERLINK(VLOOKUP(C28,'Flat Base'!F:I,3,0),"SIG TOOLS"),"") -> SIG TOOLS | J28: =IFERROR(HYPERLINK(VLOOKUP(C28,'Flat Base'!F:I,4,0),"SITE MAP"),"") -> SITE MAP | L28: 11:00 P.M. | M28: (AS) Stevinson Porsche of Littleton (NO TOURS) | N28: 7:00 A.M. | O28: MT | P28: N/A | Q28: 3, 4 | R28: 2 | S28: - | T28: - | U28: 3, 4 | V28: - | W28: 8
H29: =+IF(C29="","",IFERROR(IF(Maestra!A26="#N/D","Log Out",""),"Log Out")) | I29: =IFERROR(HYPERLINK(VLOOKUP(C29,'Flat Base'!F:I,3,0),"SIG TOOLS"),"") | J29: =IFERROR(HYPERLINK(VLOOKUP(C29,'Flat Base'!F:I,4,0),"SITE MAP"),"")
H30: =+IF(C30="","",IFERROR(IF(Maestra!A27="#N/D","Log Out",""),"Log Out")) | I30: =IFERROR(HYPERLINK(VLOOKUP(C30,'Flat Base'!F:I,3,0),"SIG TOOLS"),"") | J30: =IFERROR(HYPERLINK(VLOOKUP(C30,'Flat Base'!F:I,4,0),"SITE MAP"),"")
H31: =+IF(C31="","",IFERROR(IF(Maestra!A28="#N/D","Log Out",""),"Log Out")) | I31: =IFERROR(HYPERLINK(VLOOKUP(C31,'Flat Base'!F:I,3,0),"SIG TOOLS"),"") | J31: =IFERROR(HYPERLINK(VLOOKUP(C31,'Flat Base'!F:I,4,0),"SITE MAP"),"")
H32: =+IF(C32="","",IFERROR(IF(Maestra!A29="#N/D","Log Out",""),"Log Out")) | I32: =IFERROR(HYPERLINK(VLOOKUP(C32,'Flat Base'!F:I,3,0),"SIG TOOLS"),"") | J32: =IFERROR(HYPERLINK(VLOOKUP(C32,'Flat Base'!F:I,4,0),"SITE MAP"),"")
H33: =+IF(C33="","",IFERROR(IF(Maestra!A30="#N/D","Log Out",""),"Log Out")) | I33: =IFERROR(HYPERLINK(VLOOKUP(C33,'Flat Base'!F:I,3,0),"SIG TOOLS"),"") | J33: =IFERROR(HYPERLINK(VLOOKUP(C33,'Flat Base'!F:I,4,0),"SITE MAP"),"")
H34: =+IF(C34="","",IFERROR(IF(Maestra!A31="#N/D","Log Out",""),"Log Out")) | I34: =IFERROR(HYPERLINK(VLOOKUP(C34,'Flat Base'!F:I,3,0),"SIG TOOLS"),"") | J34: =IFERROR(HYPERLINK(VLOOKUP(C34,'Flat Base'!F:I,4,0),"SITE MAP"),"")
H35: =+IF(C35="","",IFERROR(IF(Maestra!A32="#N/D","Log Out",""),"Log Out")) | I35: =IFERROR(HYPERLINK(VLOOKUP(C35,'Flat Base'!F:I,3,0),"SIG TOOLS"),"") | J35: =IFERROR(HYPERLINK(VLOOKUP(C35,'Flat Base'!F:I,4,0),"SITE MAP"),"")
H36: =+IF(C36="","",IFERROR(IF(Maestra!A33="#N/D","Log Out",""),"Log Out")) | I36: =IFERROR(HYPERLINK(VLOOKUP(C36,'Flat Base'!F:I,3,0),"SIG TOOLS"),"") | J36: =IFERROR(HYPERLINK(VLOOKUP(C36,'Flat Base'!F:I,4,0),"SITE MAP"),"")
H37: =+IF(C37="","",IFERROR(IF(Maestra!A34="#N/D","Log Out",""),"Log Out")) | I37: =IFERROR(HYPERLINK(VLOOKUP(C37,'Flat Base'!F:I,3,0),"SIG TOOLS"),"") | J37: =IFERROR(HYPERLINK(VLOOKUP(C37,'Flat Base'!F:I,4,0),"SITE MAP"),"")
H38: =+IF(C38="","",IFERROR(IF(Maestra!A35="#N/D","Log Out",""),"Log Out")) | I38: =IFERROR(HYPERLINK(VLOOKUP(C38,'Flat Base'!F:I,3,0),"SIG TOOLS"),"") | J38: =IFERROR(HYPERLINK(VLOOKUP(C38,'Flat Base'!F:I,4,0),"SITE MAP"),"")
H39: =+IF(C39="","",IFERROR(IF(Maestra!A36="#N/D","Log Out",""),"Log Out")) | I39: =IFERROR(HYPERLINK(VLOOKUP(C39,'Flat Base'!F:I,3,0),"SIG TOOLS"),"") | J39: =IFERROR(HYPERLINK(VLOOKUP(C39,'Flat Base'!F:I,4,0),"SITE MAP"),"")
H40: =+IF(C40="","",IFERROR(IF(Maestra!A37="#N/D","Log Out",""),"Log Out")) | I40: =IFERROR(HYPERLINK(VLOOKUP(C40,'Flat Base'!F:I,3,0),"SIG TOOLS"),"") | J40: =IFERROR(HYPERLINK(VLOOKUP(C40,'Flat Base'!F:I,4,0),"SITE MAP"),"")
... H46: =+IF(C46="","",IFERROR(IF(Maestra!A43="#N/D","Log Out",""),"Log Out")) | I46: =IFERROR(HYPERLINK(VLOOKUP(C46,'Flat Base'!F:I,3,0),"SIG TOOLS"),"") | J46: =IFERROR(HYPERLINK(VLOOKUP(C46,'Flat Base'!F:I,4,0),"SITE MAP"),"")
H47: =+IF(C48="","",IFERROR(IF(Maestra!A44="#N/D","Log Out",""),"Log Out")) | I47: =IFERROR(HYPERLINK(VLOOKUP(C47,'Flat Base'!F:I,3,0),"SIG TOOLS"),"") | J47: =IFERROR(HYPERLINK(VLOOKUP(C47,'Flat Base'!F:I,4,0),"SITE MAP"),"")
H48: =+IF(#REF!="","",IFERROR(IF(Maestra!A45="#N/D","Log Out",""),"Log Out")) -> #REF! | I48: =IFERROR(HYPERLINK(VLOOKUP(C48,'Flat Base'!F:I,3,0),"SIG TOOLS"),"") | J48: =IFERROR(HYPERLINK(VLOOKUP(C48,'Flat Base'!F:I,4,0),"SITE MAP"),"")
...

Sheet Cambio de Split
A1: Changes: Split-Station:
A15: New Sites | G15: Log In to
A16: 264 | G16: =+COUNTIF('Dynamic Split'!X25:X75,"Log iN") -> 0
A19: Split | B19: Log Time | C19: Site | D19: Drop time | E19: Suma de Station | F19: Log In | G19: Split | H19: Log Time | I19: Site | J19: Drop time | K19: Suma de Station
A20: 4 | B20: 24 Hrs | C20: (KG) Truck Center Remote Storage Lot | D20: N/A | E20: 1 | F20: =IF('Cambio de Split'!C20="","",IFERROR(IF(Maestra!C16="#N/D","Log In",""),"Log In")) -> Log In | G20: 4 | H20: 24 Hrs | I20: (KG) Truck Center Remote Storage Lot | J20: N/A | K20: 1
C21: (AS) Nalley Lexus & Remote Lot Roswell (NO TOURS) | D21: N/A | E21: 1 | F21: =IF('Cambio de Split'!C21="","",IFERROR(IF(Maestra!C17="#N/D","Log In",""),"Log In")) -> Log In | I21: (AS) Nalley Lexus & Remote Lot Roswell (NO TOURS) | J21: N/A | K21: 1
B22: 8:00 P.M. | C22: (PE) Fairfield Collision (NO TOURS) | D22: 5:00 A.M. | E22: 1 | F22: =IF('Cambio de Split'!C22="","",IFERROR(IF(Maestra!C18="#N/D","Log In",""),"Log In")) -> Log In | H22: 8:00 P.M. | I22: (PE) Fairfield Collision (NO TOURS) | J22: 5:00 A.M. | K22: 1
C23: (PE) Mercedes Benz & Smart Bldg. of Fairfield (NO TOURS) | D23: 5:00 A.M. | E23: 1 | F23: =IF('Cambio de Split'!C23="","",IFERROR(IF(Maestra!C19="#N/D","Log In",""),"Log In")) -> Log In | I23: (PE) Mercedes Benz & Smart Bldg. of Fairfield (NO TOURS) | J23: 5:00 A.M. | K23: 1
B24: 9:00 P.M. | C24: (HUD) Honda of Southpoint | D24: 5:00 A.M. | E24: 1 | F24: =IF('Cambio de Split'!C24="","",IFERROR(IF(Maestra!C20="#N/D","Log In",""),"Log In")) -> Log In | H24: 9:00 P.M. | I24: (HUD) Honda of Southpoint | J24: 5:00 A.M. | K24: 1
C25: (HUD) Nissan Greensboro | D25: 5:00 A.M. | E25: 1 | F25: =IF('Dynamic Split'!U24="","",IFERROR(IF(Maestra!C21="#N/D","Log In",""),"Log In")) -> Log In | I25: (HUD) Nissan Greensboro | J25: 5:00 A.M. | K25: 1
C26: (SCH) Delray I & II | D26: 5:00 A.M. | E26: 1 | I26: (SCH) Delray I & II | J26: 5:00 A.M. | K26: 1
C27: (AS) Coggin Honda Ft. Pierce (NO TOURS) | D27: 5:00 A.M. | E27: 1 | I27: (AS) Coggin Honda Ft. Pierce (NO TOURS) | J27: 5:00 A.M. | K27: 1
C28: (AS) Nalley BMW Collision Center (NO TOURS) | D28: 5:00 A.M. | E28: 1 | I28: (AS) Nalley BMW Collision Center (NO TOURS) | J28: 5:00 A.M. | K28: 1
B29: 10:00 P.M. | C29: (DT) N. Houston | D29: 6:00 A.M. | E29: 1 | H29: 10:00 P.M. | I29: (DT) N. Houston | J29: 6:00 A.M. | K29: 1
C30: (DT) W Houston | D30: 6:00 A.M. | E30: 1 | I30: (DT) W Houston | J30: 6:00 A.M. | K30: 1
C31: (KG) Texan CDJR | D31: 6:00 A.M. | E31: 1 | I31: (KG) Texan CDJR | J31: 6:00 A.M. | K31: 1
C32: (ML) Honda of Little Rock | D32: 6:00 A.M. | E32: 1 | I32: (ML) Honda of Little Rock | J32: 6:00 A.M. | K32: 1
C33: (ML) Joe Machens Capital City I & II (NO TOURS) | D33: 6:00 A.M. | E33: 1 | I33: (ML) Joe Machens Capital City I & II (NO TOURS) | J33: 6:00 A.M. | K33: 1
C34: (ML) Joe Machens Toyota | D34: 6:00 A.M. | E34: 1 | I34: (ML) Joe Machens Toyota | J34: 6:00 A.M. | K34: 1
C35: (ML) Joe Machens VW | D35: 6:00 A.M. | E35: 1 | I35: (ML) Joe Machens VW | J35: 6:00 A.M. | K35: 1
C36: (ML) Nissan of North Little Rock | D36: 6:00 A.M. | E36: 1 | I36: (ML) Nissan of North Little Rock | J36: 6:00 A.M. | K36: 1
C37: (ML) Toyota N Little Rock | D37: 6:00 A.M. | E37: 1 | I37: (ML) Toyota N Little Rock | J37: 6:00 A.M. | K37: 1
C38: (KT) Northwest CDJR (NO TOURS) | D38: 6:00 A.M. | E38: 1 | I38: (KT) Northwest CDJR (NO TOURS) | J38: 6:00 A.M. | K38: 1
C39: (AS) Lexus Plano I & II (NO TOURS) | D39: 6:00 A.M. | E39: 1 | I39: (AS) Lexus Plano I & II (NO TOURS) | J39: 6:00 A.M. | K39: 1
C40: (AS) Mercedes Benz/Porsche Dallas I,II,III (NO TOURS) | D40: 6:00 A.M. | E40: 1 | I40: (AS) Mercedes Benz/Porsche Dallas I,II,III (NO TOURS) | J40: 6:00 A.M. | K40: 1
C41: (AS) Park Place Sprinter Van Center (NO TOURS) | D41: 6:00 A.M. | E41: 1 | I41: (AS) Park Place Sprinter Van Center (NO TOURS) | J41: 6:00 A.M. | K41: 1
C42: (AS) Park Place Mercedes Benz Ft. Worth (NO TOURS) | D42: 6:00 A.M. | E42: 1 | I42: (AS) Park Place Mercedes Benz Ft. Worth (NO TOURS) | J42: 6:00 A.M. | K42: 1
B43: 11:00 P.M. | C43: (AS) Stevinson Porsche of Littleton (NO TOURS) | D43: 7:00 A.M. | E43: 1 | H43: 11:00 P.M. | I43: (AS) Stevinson Porsche of Littleton (NO TOURS) | J43: 7:00 A.M. | K43: 1
C44: (AS) Stevinson Toyota West (NO TOURS) | D44: 7:00 A.M. | E44: 1 | I44: (AS) Stevinson Toyota West (NO TOURS) | J44: 7:00 A.M. | K44: 1
B45: 12:00 A.M. | C45: (RV) Toms Camperland Avondale (NO TOURS) | D45: 8:00 A.M. | E45: 1 | H45: 12:00 A.M. | I45: (RV) Toms Camperland Avondale (NO TOURS) | J45: 8:00 A.M. | K45: 1
C46: (RV) Toms Camperland Mesa (NO TOURS) | D46: 8:00 A.M. | E46: 1 | I46: (RV) Toms Camperland Mesa (NO TOURS) | J46: 8:00 A.M. | K46: 1
A47: 5 | B47: 24 Hrs | C47: (KG) Truck Center Remote Storage Lot | D47: N/A | E47: 1 | G47: 5 | H47: 24 Hrs | I47: (KG) Truck Center Remote Storage Lot | J47: N/A | K47: 1
B48: 8:00 P.M. | C48: (PE) Scofield Service Center (NO TOURS) | D48: 5:00 A.M. | E48: 1 | H48: 8:00 P.M. | I48: (PE) Scofield Service Center (NO TOURS) | J48: 5:00 A.M. | K48: 1
B49: 9:00 P.M. | C49: (AS) Lexus Smyrna (NO TOURS) | D49: 5:00 A.M. | E49: 1 | H49: 9:00 P.M. | I49: (AS) Lexus Smyrna (NO TOURS) | J49: 5:00 A.M. | K49: 1
C50: (HUD) Honda Greensboro | D50: 5:00 A.M. | E50: 1 | I50: (HUD) Honda Greensboro | J50: 5:00 A.M. | K50: 1
C51: (HUD) Honda of Southpoint | D51: 5:00 A.M. | E51: 1 | I51: (HUD) Honda of Southpoint | J51: 5:00 A.M. | K51: 1
C52: (AS) Audi of North Atlanta (NO TOURS) | D52: 5:00 A.M. | E52: 1 | I52: (AS) Audi of North Atlanta (NO TOURS) | J52: 5:00 A.M. | K52: 1
C53: (AS) Courtesy Kia of Brandon (NO TOURS) | D53: 5:00 A.M. | E53: 1 | I53: (AS) Courtesy Kia of Brandon (NO TOURS) | J53: 5:00 A.M. | K53: 1
B54: 10:00 P.M. | C54: (DT) N. Houston | D54: 6:00 A.M. | E54: 1 | H54: 10:00 P.M. | I54: (DT) N. Houston | J54: 6:00 A.M. | K54: 1
C55: (KG) Clear Lake Pre-Owned | D55: 6:00 A.M. | E55: 1 | I55: (KG) Clear Lake Pre-Owned | J55: 6:00 A.M. | K55: 1
...

Sheet Flat Base
A1: Key | B1: Split | C1: Station | D1: Hour | E1: Time | F1: Site | G1: Drop time | H1: SIG Tools | I1: Map | J1: SUNDAY (D.T.) | K1: Notes* | L1: Gates | M1: Entrances | N1: LPR | O1: PTZ | P1: Important Cameras | Q1: ID
A2: =+Tabla3[[#This Row],[Site]]&Tabla3[[#This Row],[Split]] -> (AS) Coggin Honda Ft. Pierce (NO TOURS)4 | B2: 4 | C2: 1 | D2: 9:00 P.M. | E2: ET | F2: (AS) Coggin Honda Ft. Pierce (NO TOURS) | G2: 5:00 A.M. | H2: =VLOOKUP(Tabla3[[#This Row],[Site]],'Important Info!'!$A$1:$J$135,10,FALSE) -> https://tools.sig.systems/site/details/120 | I2: https://www.google.com/maps/d/viewer?mid=1AyViBuyeq7iwDua1SVudJ2A1BYi3IBA&ll=27.38181516363982%2C-80.32568845000002&z=18 | J2: 10:00 A.M. | K2: =VLOOKUP(Tabla3[[#This Row],[Site]],'Important Info!'!$A$1:$H$135,8,FALSE) -> - | L2: =VLOOKUP(Tabla3[[#This Row],[Site]],'Important Info!'!$A$1:$F$135,2,FALSE) -> 1, 2, 3, 4, 14 | M2: =VLOOKUP(Tabla3[[#This Row],[Site]],'Important Info!'!$A$1:$F$135,3,FALSE) -> - | N2: =VLOOKUP(Tabla3[[#This Row],[Site]],'Important Info!'!$A$1:$F$135,4,FALSE) -> - | O2: =VLOOKUP(Tabla3[[#This Row],[Site]],'Important Info!'!$A$1:$F$135,5,FALSE) -> 7, 11, 15 | P2: =VLOOKUP(Tabla3[[#This Row],[Site]],'Important Info!'!$A$1:$F$135,6,FALSE) -> 3 | Q2: =VLOOKUP(Tabla3[[#This Row],[Site]],'Important Info!'!$A$1:$J$135,9,FALSE) -> 120
A3: =+Tabla3[[#This Row],[Site]]&Tabla3[[#This Row],[Split]] -> (AS) Lexus Plano I & II (NO TOURS)4 | B3: 4 | C3: 1 | D3: 10:00 P.M. | E3: CT | F3: (AS) Lexus Plano I & II (NO TOURS) | G3: 6:00 A.M. | H3: =VLOOKUP(Tabla3[[#This Row],[Site]],'Important Info!'!$A$1:$J$135,10,FALSE) -> https://tools.sig.systems/site/details/167 | I3: https://www.google.com/maps/d/viewer?mid=1wg5suxVuxeNp_irHlvN772HcwD6W89E&ll=33.06373951220261%2C-96.82758025000001&z=18 | J3: N/A | K3: =VLOOKUP(Tabla3[[#This Row],[Site]],'Important Info!'!$A$1:$H$135,8,FALSE) -> - | L3: =VLOOKUP(Tabla3[[#This Row],[Site]],'Important Info!'!$A$1:$F$135,2,FALSE) -> 5, 9 | M3: =VLOOKUP(Tabla3[[#This Row],[Site]],'Important Info!'!$A$1:$F$135,3,FALSE) -> - | N3: =VLOOKUP(Tabla3[[#This Row],[Site]],'Important Info!'!$A$1:$F$135,4,FALSE) -> 101, 102, 103, 104 | O3: =VLOOKUP(Tabla3[[#This Row],[Site]],'Important Info!'!$A$1:$F$135,5,FALSE) -> 4, 10, 28 | P3: =VLOOKUP(Tabla3[[#This Row],[Site]],'Important Info!'!$A$1:$F$135,6,FALSE) -> 5, 9, 16 | Q3: =VLOOKUP(Tabla3[[#This Row],[Site]],'Important Info!'!$A$1:$J$135,9,FALSE) -> 167
A4: =+Tabla3[[#This Row],[Site]]&Tabla3[[#This Row],[Split]] -> (AS) Mercedes Benz/Porsche Dallas I,II,III (NO TOURS)4 | B4: 4 | C4: 1 | D4: 10:00 P.M. | E4: CT | F4: (AS) Mercedes Benz/Porsche Dallas I,II,III (NO TOURS) | G4: 6:00 A.M. | H4: =VLOOKUP(Tabla3[[#This Row],[Site]],'Important Info!'!$A$1:$J$135,10,FALSE) -> https://tools.sig.systems/site/details/168 | I4: https://www.google.com/maps/d/edit?hl=es&mid=1uPmsRMsXnp74hPFW2t-sp2totVWF_xY&ll=32.83050137713022%2C-96.83197783061323&z=17 | J4: N/A | K4: =VLOOKUP(Tabla3[[#This Row],[Site]],'Important Info!'!$A$1:$H$135,8,FALSE) -> - | L4: =VLOOKUP(Tabla3[[#This Row],[Site]],'Important Info!'!$A$1:$F$135,2,FALSE) -> 3, 4, 17, 26, 41 | M4: =VLOOKUP(Tabla3[[#This Row],[Site]],'Important Info!'!$A$1:$F$135,3,FALSE) -> - | N4: =VLOOKUP(Tabla3[[#This Row],[Site]],'Important Info!'!$A$1:$F$135,4,FALSE) -> 153, 154, 155, 156, 157, 158 | O4: =VLOOKUP(Tabla3[[#This Row],[Site]],'Important Info!'!$A$1:$F$135,5,FALSE) -> 2, 6, 10, 20, 28, 30, 36 | P4: =VLOOKUP(Tabla3[[#This Row],[Site]],'Important Info!'!$A$1:$F$135,6,FALSE) -> 31, 41, 159 | Q4: =VLOOKUP(Tabla3[[#This Row],[Site]],'Important Info!'!$A$1:$J$135,9,FALSE) -> 168
A5: =+Tabla3[[#This Row],[Site]]&Tabla3[[#This Row],[Split]] -> (AS) Nalley BMW Collision Center (NO TOURS)4 | B5: 4 | C5: 1 | D5: 9:00 P.M. | E5: ET | F5: (AS) Nalley BMW Collision Center (NO TOURS) | G5: 5:00 A.M. | H5: =VLOOKUP(Tabla3[[#This Row],[Site]],'Important Info!'!$A$1:$J$135,10,FALSE) -> https://tools.sig.systems/site/details/220 | J5: N/A | K5: =VLOOKUP(Tabla3[[#This Row],[Site]],'Important Info!'!$A$1:$H$135,8,FALSE) -> - | L5: =VLOOKUP(Tabla3[[#This Row],[Site]],'Important Info!'!$A$1:$F$135,2,FALSE) -> - | M5: =VLOOKUP(Tabla3[[#This Row],[Site]],'Important Info!'!$A$1:$F$135,3,FALSE) -> 4 | N5: =VLOOKUP(Tabla3[[#This Row],[Site]],'Important Info!'!$A$1:$F$135,4,FALSE) -> - | O5: =VLOOKUP(Tabla3[[#This Row],[Site]],'Important Info!'!$A$1:$F$135,5,FALSE) -> 12 | P5: =VLOOKUP(Tabla3[[#This Row],[Site]],'Important Info!'!$A$1:$F$135,6,FALSE) -> 13, 15 | Q5: =VLOOKUP(Tabla3[[#This Row],[Site]],'Important Info!'!$A$1:$J$135,9,FALSE) -> 220
A6: =+Tabla3[[#This Row],[Site]]&Tabla3[[#This Row],[Split]] -> (AS) Nalley Lexus & Remote Lot Roswell (NO TOURS)4 | B6: 4 | C6: 1 | D6: 24 Hrs | E6: ET | F6: (AS) Nalley Lexus & Remote Lot Roswell (NO TOURS) | G6: N/A | H6: =VLOOKUP(Tabla3[[#This Row],[Site]],'Important Info!'!$A$1:$J$135,10,FALSE) -> https://tools.sig.systems/site/details/131 | I6: https://www.google.com/maps/d/edit?mid=1jkN3DS1BhUqp_dztjjW0PDwKfo_Yxsw&usp=sharing | J6: N/A | K6: =VLOOKUP(Tabla3[[#This Row],[Site]],'Important Info!'!$A$1:$H$135,8,FALSE) -> Dealership 11PM to 5AM (Mon to Fri). Sunday Drop Time 1PM | L6: =VLOOKUP(Tabla3[[#This Row],[Site]],'Important Info!'!$A$1:$F$135,2,FALSE) -> 6, 13 | M6: =VLOOKUP(Tabla3[[#This Row],[Site]],'Important Info!'!$A$1:$F$135,3,FALSE) -> 4 | N6: =VLOOKUP(Tabla3[[#This Row],[Site]],'Important Info!'!$A$1:$F$135,4,FALSE) -> 1 | O6: =VLOOKUP(Tabla3[[#This Row],[Site]],'Important Info!'!$A$1:$F$135,5,FALSE) -> 1, 8, 19 | P6: =VLOOKUP(Tabla3[[#This Row],[Site]],'Important Info!'!$A$1:$F$135,6,FALSE) -> 4, 20 | Q6: =VLOOKUP(Tabla3[[#This Row],[Site]],'Important Info!'!$A$1:$J$135,9,FALSE) -> 131
A7: =+Tabla3[[#This Row],[Site]]&Tabla3[[#This Row],[Split]] -> (AS) Park Place Mercedes Benz Ft. Worth (NO TOURS)4 | B7: 4 | C7: 1 | D7: 10:00 P.M. | E7: CT | F7: (AS) Park Place Mercedes Benz Ft. Worth (NO TOURS) | G7: 6:00 A.M. | H7: =VLOOKUP(Tabla3[[#This Row],[Site]],'Important Info!'!$A$1:$J$135,10,FALSE) -> https://tools.sig.systems/site/details/137 | I7: https://www.google.com/maps/d/edit?mid=18OEO_KbvYcgI3N1jE4gTMXfNHTNDrFU&ll=32.66603989958274%2C-97.42021198201722&z=18 | J7: N/A | K7: - | L7: =VLOOKUP(Tabla3[[#This Row],[Site]],'Important Info!'!$A$1:$F$135,2,FALSE) -> 4, 18 | M7: =VLOOKUP(Tabla3[[#This Row],[Site]],'Important Info!'!$A$1:$F$135,3,FALSE) -> - | N7: =VLOOKUP(Tabla3[[#This Row],[Site]],'Important Info!'!$A$1:$F$135,4,FALSE) -> 54, 55 | O7: =VLOOKUP(Tabla3[[#This Row],[Site]],'Important Info!'!$A$1:$F$135,5,FALSE) -> 2, 18 | P7: =VLOOKUP(Tabla3[[#This Row],[Site]],'Important Info!'!$A$1:$F$135,6,FALSE) -> 5, 18 | Q7: =VLOOKUP(Tabla3[[#This Row],[Site]],'Important Info!'!$A$1:$J$135,9,FALSE) -> 137
A8: =+Tabla3[[#This Row],[Site]]&Tabla3[[#This Row],[Split]] -> (AS) Park Place Sprinter Van Center (NO TOURS)4 | B8: 4 | C8: 1 | D8: 10:00 P.M. | E8: CT | F8: (AS) Park Place Sprinter Van Center (NO TOURS) | G8: 6:00 A.M. | H8: =VLOOKUP(Tabla3[[#This Row],[Site]],'Important Info!'!$A$1:$J$135,10,FALSE) -> https://tools.sig.systems/site/details/138 | I8: https://www.google.com/maps/d/edit?hl=es&mid=1uPmsRMsXnp74hPFW2t-sp2totVWF_xY&ll=32.83050137713022%2C-96.83197783061323&z=17 | J8: N/A | K8: =VLOOKUP(Tabla3[[#This Row],[Site]],'Important Info!'!$A$1:$H$135,8,FALSE) -> - | L8: =VLOOKUP(Tabla3[[#This Row],[Site]],'Important Info!'!$A$1:$F$135,2,FALSE) -> 1 | M8: =VLOOKUP(Tabla3[[#This Row],[Site]],'Important Info!'!$A$1:$F$135,3,FALSE) -> - | N8: =VLOOKUP(Tabla3[[#This Row],[Site]],'Important Info!'!$A$1:$F$135,4,FALSE) -> - | O8: =VLOOKUP(Tabla3[[#This Row],[Site]],'Important Info!'!$A$1:$F$135,5,FALSE) -> - | P8: =VLOOKUP(Tabla3[[#This Row],[Site]],'Important Info!'!$A$1:$F$135,6,FALSE) -> 1, 3 | Q8: =VLOOKUP(Tabla3[[#This Row],[Site]],'Important Info!'!$A$1:$J$135,9,FALSE) -> 138
A9: =+Tabla3[[#This Row],[Site]]&Tabla3[[#This Row],[Split]] -> (AS) Stevinson Porsche of Littleton (NO TOURS)4 | B9: 4 | C9: 1 | D9: 11:00 P.M. | E9: MT | F9: (AS) Stevinson Porsche of Littleton (NO TOURS) | G9: 7:00 A.M. | H9: =VLOOKUP(Tabla3[[#This Row],[Site]],'Important Info!'!$A$1:$J$135,10,FALSE) -> https://tools.sig.systems/site/details/242 | J9: N/A | K9: =VLOOKUP(Tabla3[[#This Row],[Site]],'Important Info!'!$A$1:$H$135,8,FALSE) -> - | L9: =VLOOKUP(Tabla3[[#This Row],[Site]],'Important Info!'!$A$1:$F$135,2,FALSE) -> 3, 4 | M9: =VLOOKUP(Tabla3[[#This Row],[Site]],'Important Info!'!$A$1:$F$135,3,FALSE) -> 2 | N9: =VLOOKUP(Tabla3[[#This Row],[Site]],'Important Info!'!$A$1:$F$135,4,FALSE) -> - | O9: =VLOOKUP(Tabla3[[#This Row],[Site]],'Important Info!'!$A$1:$F$135,5,FALSE) -> - | P9: =VLOOKUP(Tabla3[[#This Row],[Site]],'Important Info!'!$A$1:$F$135,6,FALSE) -> 3, 4 | Q9: =VLOOKUP(Tabla3[[#This Row],[Site]],'Important Info!'!$A$1:$J$135,9,FALSE) -> 242
A10: =+Tabla3[[#This Row],[Site]]&Tabla3[[#This Row],[Split]] -> (AS) Stevinson Toyota West (NO TOURS)4 | B10: 4 | C10: 1 | D10: 11:00 P.M. | E10: MT | F10: (AS) Stevinson Toyota West (NO TOURS) | G10: 7:00 A.M. | H10: =VLOOKUP(Tabla3[[#This Row],[Site]],'Important Info!'!$A$1:$J$135,10,FALSE) -> https://tools.sig.systems/site/details/240 | I10: https://www.google.com/maps/d/edit?mid=1nAyK85WaWREy0lfxnmWn3USs2gC0nP0&usp=sharing | J10: N/A | K10: =VLOOKUP(Tabla3[[#This Row],[Site]],'Important Info!'!$A$1:$H$135,8,FALSE) -> - | L10: =VLOOKUP(Tabla3[[#This Row],[Site]],'Important Info!'!$A$1:$F$135,2,FALSE) -> - | M10: =VLOOKUP(Tabla3[[#This Row],[Site]],'Important Info!'!$A$1:$F$135,3,FALSE) -> 7, 18, 21 | N10: =VLOOKUP(Tabla3[[#This Row],[Site]],'Important Info!'!$A$1:$F$135,4,FALSE) -> - | O10: =VLOOKUP(Tabla3[[#This Row],[Site]],'Important Info!'!$A$1:$F$135,5,FALSE) -> 11, 24, 34 | P10: =VLOOKUP(Tabla3[[#This Row],[Site]],'Important Info!'!$A$1:$F$135,6,FALSE) -> 1, 2, 3, 12 | Q10: =VLOOKUP(Tabla3[[#This Row],[Site]],'Important Info!'!$A$1:$J$135,9,FALSE) -> 240
A11: =+Tabla3[[#This Row],[Site]]&Tabla3[[#This Row],[Split]] -> (DT) N. Houston4 | B11: 4 | C11: 1 | D11: 10:00 P.M. | E11: CT | F11: (DT) N. Houston | G11: 6:00 A.M. | H11: =VLOOKUP(Tabla3[[#This Row],[Site]],'Important Info!'!$A$1:$J$135,10,FALSE) -> https://tools.sig.systems/site/details/250 | J11: N/A | K11: =VLOOKUP(Tabla3[[#This Row],[Site]],'Important Info!'!$A$1:$H$135,8,FALSE) -> - | L11: =VLOOKUP(Tabla3[[#This Row],[Site]],'Important Info!'!$A$1:$F$135,2,FALSE) -> 2, 10, 18 | M11: =VLOOKUP(Tabla3[[#This Row],[Site]],'Important Info!'!$A$1:$F$135,3,FALSE) -> - | N11: =VLOOKUP(Tabla3[[#This Row],[Site]],'Important Info!'!$A$1:$F$135,4,FALSE) -> - | O11: =VLOOKUP(Tabla3[[#This Row],[Site]],'Important Info!'!$A$1:$F$135,5,FALSE) -> 15 | P11: =VLOOKUP(Tabla3[[#This Row],[Site]],'Important Info!'!$A$1:$F$135,6,FALSE) -> 2, 4, 18 | Q11: =VLOOKUP(Tabla3[[#This Row],[Site]],'Important Info!'!$A$1:$J$135,9,FALSE) -> 250
A12: =+Tabla3[[#This Row],[Site]]&Tabla3[[#This Row],[Split]] -> (DT) W Houston4 | B12: 4 | C12: 1 | D12: 10:00 P.M. | E12: CT | F12: (DT) W Houston | G12: 6:00 A.M. | H12: =VLOOKUP(Tabla3[[#This Row],[Site]],'Important Info!'!$A$1:$J$135,10,FALSE) -> https://tools.sig.systems/site/details/197 | J12: N/A | K12: =VLOOKUP(Tabla3[[#This Row],[Site]],'Important Info!'!$A$1:$H$135,8,FALSE) -> - | L12: =VLOOKUP(Tabla3[[#This Row],[Site]],'Important Info!'!$A$1:$F$135,2,FALSE) -> 7 | M12: =VLOOKUP(Tabla3[[#This Row],[Site]],'Important Info!'!$A$1:$F$135,3,FALSE) -> 2 | N12: =VLOOKUP(Tabla3[[#This Row],[Site]],'Important Info!'!$A$1:$F$135,4,FALSE) -> - | O12: =VLOOKUP(Tabla3[[#This Row],[Site]],'Important Info!'!$A$1:$F$135,5,FALSE) -> 14 | P12: =VLOOKUP(Tabla3[[#This Row],[Site]],'Important Info!'!$A$1:$F$135,6,FALSE) -> 2, 3, 7, 10 | Q12: =VLOOKUP(Tabla3[[#This Row],[Site]],'Important Info!'!$A$1:$J$135,9,FALSE) -> 197
A13: =+Tabla3[[#This Row],[Site]]&Tabla3[[#This Row],[Split]] -> (HUD) Honda of Southpoint4 | B13: 4 | C13: 1 | D13: 9:00 P.M. | E13: ET | F13: (HUD) Honda of Southpoint | G13: 5:00 A.M. | H13: =VLOOKUP(Tabla3[[#This Row],[Site]],'Important Info!'!$A$1:$J$135,10,FALSE) -> https://tools.sig.systems/site/details/195 | J13: 10:00 A.M. | K13: =VLOOKUP(Tabla3[[#This Row],[Site]],'Important Info!'!$A$1:$H$135,8,FALSE) -> - | L13: =VLOOKUP(Tabla3[[#This Row],[Site]],'Important Info!'!$A$1:$F$135,2,FALSE) -> 2, 12, 18 | M13: =VLOOKUP(Tabla3[[#This Row],[Site]],'Important Info!'!$A$1:$F$135,3,FALSE) -> 13 | N13: =VLOOKUP(Tabla3[[#This Row],[Site]],'Important Info!'!$A$1:$F$135,4,FALSE) -> - | O13: =VLOOKUP(Tabla3[[#This Row],[Site]],'Important Info!'!$A$1:$F$135,5,FALSE) -> 2, 15 | P13: =VLOOKUP(Tabla3[[#This Row],[Site]],'Important Info!'!$A$1:$F$135,6,FALSE) -> - | Q13: =VLOOKUP(Tabla3[[#This Row],[Site]],'Important Info!'!$A$1:$J$135,9,FALSE) -> 195
A14: =+Tabla3[[#This Row],[Site]]&Tabla3[[#This Row],[Split]] -> (HUD) Nissan Greensboro4 | B14: 4 | C14: 1 | D14: 9:00 P.M. | E14: ET | F14: (HUD) Nissan Greensboro | G14: 5:00 A.M. | H14: =VLOOKUP(Tabla3[[#This Row],[Site]],'Important Info!'!$A$1:$J$135,10,FALSE) -> https://tools.sig.systems/site/details/236 | I14: https://www.google.com/maps/d/viewer?mid=1ejOzT7-x6RWnCf83BBP7XhiOiwEX3Wk&ll=36.061264791292906%2C-79.87437695000003&z=17 | J14: N/A | K14: =VLOOKUP(Tabla3[[#This Row],[Site]],'Important Info!'!$A$1:$H$135,8,FALSE) -> - | L14: =VLOOKUP(Tabla3[[#This Row],[Site]],'Important Info!'!$A$1:$F$135,2,FALSE) -> 1, 5, 12 | M14: =VLOOKUP(Tabla3[[#This Row],[Site]],'Important Info!'!$A$1:$F$135,3,FALSE) -> - | N14: =VLOOKUP(Tabla3[[#This Row],[Site]],'Important Info!'!$A$1:$F$135,4,FALSE) -> - | O14: =VLOOKUP(Tabla3[[#This Row],[Site]],'Important Info!'!$A$1:$F$135,5,FALSE) -> - | P14: =VLOOKUP(Tabla3[[#This Row],[Site]],'Important Info!'!$A$1:$F$135,6,FALSE) -> 4 | Q14: =VLOOKUP(Tabla3[[#This Row],[Site]],'Important Info!'!$A$1:$J$135,9,FALSE) -> 236
A15: =+Tabla3[[#This Row],[Site]]&Tabla3[[#This Row],[Split]] -> (KG) Texan CDJR4 | B15: 4 | C15: 1 | D15: 10:00 P.M. | E15: CT | F15: (KG) Texan CDJR | G15: 6:00 A.M. | H15: =VLOOKUP(Tabla3[[#This Row],[Site]],'Important Info!'!$A$1:$J$135,10,FALSE) -> https://tools.sig.systems/site/details/238 | I15: https://www.google.com/maps/d/edit?mid=1FNqK4dW8Z8gtSWuQLbStrtqe7lH8DIQ&usp=sharing | J15: N/A | K15: =VLOOKUP(Tabla3[[#This Row],[Site]],'Important Info!'!$A$1:$H$135,8,FALSE) -> - | L15: =VLOOKUP(Tabla3[[#This Row],[Site]],'Important Info!'!$A$1:$F$135,2,FALSE) -> 11, 12, 13, 14, 20, 32, 34, 36, 77 | M15: =VLOOKUP(Tabla3[[#This Row],[Site]],'Important Info!'!$A$1:$F$135,3,FALSE) -> - | N15: =VLOOKUP(Tabla3[[#This Row],[Site]],'Important Info!'!$A$1:$F$135,4,FALSE) -> 67, 68, 69, 70 | O15: =VLOOKUP(Tabla3[[#This Row],[Site]],'Important Info!'!$A$1:$F$135,5,FALSE) -> 2, 10, 14, 25, 29, 35, 38 | P15: =VLOOKUP(Tabla3[[#This Row],[Site]],'Important Info!'!$A$1:$F$135,6,FALSE) -> 36, 46 | Q15: =VLOOKUP(Tabla3[[#This Row],[Site]],'Important Info!'!$A$1:$J$135,9,FALSE) -> 238
A16: =+Tabla3[[#This Row],[Site]]&Tabla3[[#This Row],[Split]] -> (KG) Truck Center Remote Storage Lot4 | B16: 4 | C16: 1 | D16: 24 Hrs | E16: MT | F16: (KG) Truck Center Remote Storage Lot | G16: N/A | H16: =VLOOKUP(Tabla3[[#This Row],[Site]],'Important Info!'!$A$1:$J$135,10,FALSE) -> https://tools.sig.systems/site/details/144 | J16: N/A | K16: =VLOOKUP(Tabla3[[#This Row],[Site]],'Important Info!'!$A$1:$H$135,8,FALSE) -> - | L16: =VLOOKUP(Tabla3[[#This Row],[Site]],'Important Info!'!$A$1:$F$135,2,FALSE) -> 4, A23, A49 | M16: =VLOOKUP(Tabla3[[#This Row],[Site]],'Important Info!'!$A$1:$F$135,3,FALSE) -> 5, 24 | N16: =VLOOKUP(Tabla3[[#This Row],[Site]],'Important Info!'!$A$1:$F$135,4,FALSE) -> - | O16: =VLOOKUP(Tabla3[[#This Row],[Site]],'Important Info!'!$A$1:$F$135,5,FALSE) -> 1, 7, 11, 15, 19, 24, 25 | P16: =VLOOKUP(Tabla3[[#This Row],[Site]],'Important Info!'!$A$1:$F$135,6,FALSE) -> 9, 20, 24, A49 | Q16: =VLOOKUP(Tabla3[[#This Row],[Site]],'Important Info!'!$A$1:$J$135,9,FALSE) -> 144
A17: =+Tabla3[[#This Row],[Site]]&Tabla3[[#This Row],[Split]] -> (KT) Northwest CDJR (NO TOURS)4 | B17: 4 | C17: 1 | D17: 10:00 P.M. | E17: CT | F17: (KT) Northwest CDJR (NO TOURS) | G17: 6:00 A.M. | H17: =VLOOKUP(Tabla3[[#This Row],[Site]],'Important Info!'!$A$1:$J$135,10,FALSE) -> https://tools.sig.systems/site/details/229 | J17: N/A | K17: =VLOOKUP(Tabla3[[#This Row],[Site]],'Important Info!'!$A$1:$H$135,8,FALSE) -> - | L17: =VLOOKUP(Tabla3[[#This Row],[Site]],'Important Info!'!$A$1:$F$135,2,FALSE) -> 1, 3, 11, 25 | M17: =VLOOKUP(Tabla3[[#This Row],[Site]],'Important Info!'!$A$1:$F$135,3,FALSE) -> - | N17: =VLOOKUP(Tabla3[[#This Row],[Site]],'Important Info!'!$A$1:$F$135,4,FALSE) -> - | O17: =VLOOKUP(Tabla3[[#This Row],[Site]],'Important Info!'!$A$1:$F$135,5,FALSE) -> 4, 12, 18 | P17: =VLOOKUP(Tabla3[[#This Row],[Site]],'Important Info!'!$A$1:$F$135,6,FALSE) -> - | Q17: =VLOOKUP(Tabla3[[#This Row],[Site]],'Important Info!'!$A$1:$J$135,9,FALSE) -> 229
A18: =+Tabla3[[#This Row],[Site]]&Tabla3[[#This Row],[Split]] -> (ML) Honda of Little Rock4 | B18: 4 | C18: 1 | D18: 10:00 P.M. | E18: CT | F18: (ML) Honda of Little Rock | G18: 6:00 A.M. | H18: =VLOOKUP(Tabla3[[#This Row],[Site]],'Important Info!'!$A$1:$J$135,10,FALSE) -> https://tools.sig.systems/site/details/249 | I18: https://www.google.com/maps/d/viewer?mid=1hvbKFMO-d5TXrKGU-g5dt_xcdArB1D0&ll=34.71147784120261%2C-92.40574350000001&z=17 | J18: N/A | K18: =VLOOKUP(Tabla3[[#This Row],[Site]],'Important Info!'!$A$1:$H$135,8,FALSE) -> - | L18: =VLOOKUP(Tabla3[[#This Row],[Site]],'Important Info!'!$A$1:$F$135,2,FALSE) -> 1, 4, 9, 14, 21 | M18: =VLOOKUP(Tabla3[[#This Row],[Site]],'Important Info!'!$A$1:$F$135,3,FALSE) -> - | N18: =VLOOKUP(Tabla3[[#This Row],[Site]],'Important Info!'!$A$1:$F$135,4,FALSE) -> - | O18: =VLOOKUP(Tabla3[[#This Row],[Site]],'Important Info!'!$A$1:$F$135,5,FALSE) -> 4, 14, 21 | P18: =VLOOKUP(Tabla3[[#This Row],[Site]],'Important Info!'!$A$1:$F$135,6,FALSE) -> 11, 12 | Q18: =VLOOKUP(Tabla3[[#This Row],[Site]],'Important Info!'!$A$1:$J$135,9,FALSE) -> 249
A19: =+Tabla3[[#This Row],[Site]]&Tabla3[[#This Row],[Split]] -> (ML) Joe Machens Capital City I & II (NO TOURS)4 | B19: 4 | C19: 1 | D19: 10:00 P.M. | E19: CT | F19: (ML) Joe Machens Capital City I & II (NO TOURS) | G19: 6:00 A.M. | H19: =VLOOKUP(Tabla3[[#This Row],[Site]],'Important Info!'!$A$1:$J$135,10,FALSE) -> https://tools.sig.systems/site/details/271 | J19: N/A | K19: =VLOOKUP(Tabla3[[#This Row],[Site]],'Important Info!'!$A$1:$H$135,8,FALSE) -> - | L19: =VLOOKUP(Tabla3[[#This Row],[Site]],'Important Info!'!$A$1:$F$135,2,FALSE) -> - | M19: =VLOOKUP(Tabla3[[#This Row],[Site]],'Important Info!'!$A$1:$F$135,3,FALSE) -> 1, 3, 4, 20, 25, 27, 28 | N19: =VLOOKUP(Tabla3[[#This Row],[Site]],'Important Info!'!$A$1:$F$135,4,FALSE) -> - | O19: =VLOOKUP(Tabla3[[#This Row],[Site]],'Important Info!'!$A$1:$F$135,5,FALSE) -> 29 | P19: =VLOOKUP(Tabla3[[#This Row],[Site]],'Important Info!'!$A$1:$F$135,6,FALSE) -> 19, 20 | Q19: =VLOOKUP(Tabla3[[#This Row],[Site]],'Important Info!'!$A$1:$J$135,9,FALSE) -> 271
A20: =+Tabla3[[#This Row],[Site]]&Tabla3[[#This Row],[Split]] -> (ML) Joe Machens Toyota4 | B20: 4 | C20: 1 | D20: 10:00 P.M. | E20: CT | F20: (ML) Joe Machens Toyota | G20: 6:00 A.M. | H20: =VLOOKUP(Tabla3[[#This Row],[Site]],'Important Info!'!$A$1:$J$135,10,FALSE) -> https://tools.sig.systems/site/details/275 | I20: https://www.google.com/maps/d/viewer?hl=es&mid=1C1oZdjH3dNvCvqdpIv_Lk0Yn1OCVn-4&ll=38.965368114274455%2C-92.3405954&z=15 | J20: N/A | K20: =VLOOKUP(Tabla3[[#This Row],[Site]],'Important Info!'!$A$1:$H$135,8,FALSE) -> - | L20: =VLOOKUP(Tabla3[[#This Row],[Site]],'Important Info!'!$A$1:$F$135,2,FALSE) -> - | M20: =VLOOKUP(Tabla3[[#This Row],[Site]],'Important Info!'!$A$1:$F$135,3,FALSE) -> 1, 4, 6 | N20: =VLOOKUP(Tabla3[[#This Row],[Site]],'Important Info!'!$A$1:$F$135,4,FALSE) -> - | O20: =VLOOKUP(Tabla3[[#This Row],[Site]],'Important Info!'!$A$1:$F$135,5,FALSE) -> 4, 10 | P20: =VLOOKUP(Tabla3[[#This Row],[Site]],'Important Info!'!$A$1:$F$135,6,FALSE) -> - | Q20: =VLOOKUP(Tabla3[[#This Row],[Site]],'Important Info!'!$A$1:$J$135,9,FALSE) -> 275
A21: =+Tabla3[[#This Row],[Site]]&Tabla3[[#This Row],[Split]] -> (ML) Joe Machens VW4 | B21: 4 | C21: 1 | D21: 10:00 P.M. | E21: CT | F21: (ML) Joe Machens VW | G21: 6:00 A.M. | H21: =VLOOKUP(Tabla3[[#This Row],[Site]],'Important Info!'!$A$1:$J$135,10,FALSE) -> https://tools.sig.systems/site/details/274 | I21: https://www.google.com/maps/d/viewer?hl=es&mid=1C1oZdjH3dNvCvqdpIv_Lk0Yn1OCVn-4&ll=38.965368114274455%2C-92.3405954&z=15 | J21: N/A | K21: =VLOOKUP(Tabla3[[#This Row],[Site]],'Important Info!'!$A$1:$H$135,8,FALSE) -> - | L21: =VLOOKUP(Tabla3[[#This Row],[Site]],'Important Info!'!$A$1:$F$135,2,FALSE) -> - | M21: =VLOOKUP(Tabla3[[#This Row],[Site]],'Important Info!'!$A$1:$F$135,3,FALSE) -> 1, 11, 18 | N21: =VLOOKUP(Tabla3[[#This Row],[Site]],'Important Info!'!$A$1:$F$135,4,FALSE) -> - | O21: =VLOOKUP(Tabla3[[#This Row],[Site]],'Important Info!'!$A$1:$F$135,5,FALSE) -> 17 | P21: =VLOOKUP(Tabla3[[#This Row],[Site]],'Important Info!'!$A$1:$F$135,6,FALSE) -> - | Q21: =VLOOKUP(Tabla3[[#This Row],[Site]],'Important Info!'!$A$1:$J$135,9,FALSE) -> 274
A22: =+Tabla3[[#This Row],[Site]]&Tabla3[[#This Row],[Split]] -> (ML) Nissan of North Little Rock4 | B22: 4 | C22: 1 | D22: 10:00 P.M. | E22: CT | F22: (ML) Nissan of North Little Rock | G22: 6:00 A.M. | H22: =VLOOKUP(Tabla3[[#This Row],[Site]],'Important Info!'!$A$1:$J$135,10,FALSE) -> https://tools.sig.systems/site/details/216 | I22: https://www.google.com/maps/d/edit?mid=1Oky35ERk_2kgyzCvDu_odQ2ZP62BtqA&usp=sharing | J22: N/A | K22: =VLOOKUP(Tabla3[[#This Row],[Site]],'Important Info!'!$A$1:$H$135,8,FALSE) -> - | L22: =VLOOKUP(Tabla3[[#This Row],[Site]],'Important Info!'!$A$1:$F$135,2,FALSE) -> 2, 4 | M22: =VLOOKUP(Tabla3[[#This Row],[Site]],'Important Info!'!$A$1:$F$135,3,FALSE) -> - | N22: =VLOOKUP(Tabla3[[#This Row],[Site]],'Important Info!'!$A$1:$F$135,4,FALSE) -> - | O22: =VLOOKUP(Tabla3[[#This Row],[Site]],'Important Info!'!$A$1:$F$135,5,FALSE) -> 5, 17, 23 | P22: =VLOOKUP(Tabla3[[#This Row],[Site]],'Important Info!'!$A$1:$F$135,6,FALSE) -> 18 | Q22: =VLOOKUP(Tabla3[[#This Row],[Site]],'Important Info!'!$A$1:$J$135,9,FALSE) -> 216
A23: =+Tabla3[[#This Row],[Site]]&Tabla3[[#This Row],[Split]] -> (ML) Toyota N Little Rock4 | B23: 4 | C23: 1 | D23: 10:00 P.M. | E23: CT | F23: (ML) Toyota N Little Rock | G23: 6:00 A.M. | H23: =VLOOKUP(Tabla3[[#This Row],[Site]],'Important Info!'!$A$1:$J$135,10,FALSE) -> https://tools.sig.systems/site/details/201 | I23: https://www.google.com/maps/d/edit?mid=1Oky35ERk_2kgyzCvDu_odQ2ZP62BtqA&usp=sharing | J23: N/A | K23: =VLOOKUP(Tabla3[[#This Row],[Site]],'Important Info!'!$A$1:$H$135,8,FALSE) -> - | L23: =VLOOKUP(Tabla3[[#This Row],[Site]],'Important Info!'!$A$1:$F$135,2,FALSE) -> 4, 15, 18, 22, 23, 26 | M23: =VLOOKUP(Tabla3[[#This Row],[Site]],'Important Info!'!$A$1:$F$135,3,FALSE) -> - | N23: =VLOOKUP(Tabla3[[#This Row],[Site]],'Important Info!'!$A$1:$F$135,4,FALSE) -> - | O23: =VLOOKUP(Tabla3[[#This Row],[Site]],'Important Info!'!$A$1:$F$135,5,FALSE) -> 2, 12, 13, 18 | P23: =VLOOKUP(Tabla3[[#This Row],[Site]],'Important Info!'!$A$1:$F$135,6,FALSE) -> - | Q23: =VLOOKUP(Tabla3[[#This Row],[Site]],'Important Info!'!$A$1:$J$135,9,FALSE) -> 201
A24: =+Tabla3[[#This Row],[Site]]&Tabla3[[#This Row],[Split]] -> (PE) Fairfield Collision (NO TOURS)4 | B24: 4 | C24: 1 | D24: 8:00 P.M. | E24: ET | F24: (PE) Fairfield Collision (NO TOURS) | G24: 5:00 A.M. | H24: =VLOOKUP(Tabla3[[#This Row],[Site]],'Important Info!'!$A$1:$J$135,10,FALSE) -> https://tools.sig.systems/site/details/191 | J24: N/A | K24: =VLOOKUP(Tabla3[[#This Row],[Site]],'Important Info!'!$A$1:$H$135,8,FALSE) -> - | L24: =VLOOKUP(Tabla3[[#This Row],[Site]],'Important Info!'!$A$1:$F$135,2,FALSE) -> 4 | M24: =VLOOKUP(Tabla3[[#This Row],[Site]],'Important Info!'!$A$1:$F$135,3,FALSE) -> - | N24: =VLOOKUP(Tabla3[[#This Row],[Site]],'Important Info!'!$A$1:$F$135,4,FALSE) -> - | O24: =VLOOKUP(Tabla3[[#This Row],[Site]],'Important Info!'!$A$1:$F$135,5,FALSE) -> - | P24: =VLOOKUP(Tabla3[[#This Row],[Site]],'Important Info!'!$A$1:$F$135,6,FALSE) -> 1, 2, 3, 4, 5, 6 | Q24: =VLOOKUP(Tabla3[[#This Row],[Site]],'Important Info!'!$A$1:$J$135,9,FALSE) -> 191
A25: =+Tabla3[[#This Row],[Site]]&Tabla3[[#This Row],[Split]] -> (PE) Mercedes Benz & Smart Bldg. of Fairfield (NO TOURS)4 | B25: 4 | C25: 1 | D25: 8:00 P.M. | E25: ET | F25: (PE) Mercedes Benz & Smart Bldg. of Fairfield (NO TOURS) | G25: 5:00 A.M. | H25: =VLOOKUP(Tabla3[[#This Row],[Site]],'Important Info!'!$A$1:$J$135,10,FALSE) -> https://tools.sig.systems/site/details/192 | I25: https://www.google.com/maps/d/viewer?mid=1FEo41PzFJQjUIXXKitX5TNCtuqR6Vbs&ll=41.1663376742533%2C-73.22955662049608&z=16 | J25: N/A | K25: =VLOOKUP(Tabla3[[#This Row],[Site]],'Important Info!'!$A$1:$H$135,8,FALSE) -> - | L25: =VLOOKUP(Tabla3[[#This Row],[Site]],'Important Info!'!$A$1:$F$135,2,FALSE) -> - | M25: =VLOOKUP(Tabla3[[#This Row],[Site]],'Important Info!'!$A$1:$F$135,3,FALSE) -> 1 | N25: =VLOOKUP(Tabla3[[#This Row],[Site]],'Important Info!'!$A$1:$F$135,4,FALSE) -> - | O25: =VLOOKUP(Tabla3[[#This Row],[Site]],'Important Info!'!$A$1:$F$135,5,FALSE) -> 11, 13 | P25: =VLOOKUP(Tabla3[[#This Row],[Site]],'Important Info!'!$A$1:$F$135,6,FALSE) -> 1 | Q25: =VLOOKUP(Tabla3[[#This Row],[Site]],'Important Info!'!$A$1:$J$135,9,FALSE) -> 192
A26: =+Tabla3[[#This Row],[Site]]&Tabla3[[#This Row],[Split]] -> (RV) Toms Camperland Avondale (NO TOURS)4 | B26: 4 | C26: 1 | D26: 12:00 A.M. | E26: MST | F26: (RV) Toms Camperland Avondale (NO TOURS) | G26: 8:00 A.M. | H26: =VLOOKUP(Tabla3[[#This Row],[Site]],'Important Info!'!$A$1:$J$135,10,FALSE) -> https://tools.sig.systems/site/details/248 | I26: https://www.google.com/maps/d/viewer?mid=1bDs0QGFZwL3vEeGKxjVMk_j4azr0-lg&ll=33.4593758581648%2C-112.28793780000001&z=18 | J26: 1:00 P.M. | K26: =VLOOKUP(Tabla3[[#This Row],[Site]],'Important Info!'!$A$1:$H$135,8,FALSE) -> - | L26: =VLOOKUP(Tabla3[[#This Row],[Site]],'Important Info!'!$A$1:$F$135,2,FALSE) -> 10 | M26: =VLOOKUP(Tabla3[[#This Row],[Site]],'Important Info!'!$A$1:$F$135,3,FALSE) -> 2, 7 | N26: =VLOOKUP(Tabla3[[#This Row],[Site]],'Important Info!'!$A$1:$F$135,4,FALSE) -> - | O26: =VLOOKUP(Tabla3[[#This Row],[Site]],'Important Info!'!$A$1:$F$135,5,FALSE) -> - | P26: =VLOOKUP(Tabla3[[#This Row],[Site]],'Important Info!'!$A$1:$F$135,6,FALSE) -> 2, 7, 8, 13, 15 | Q26: =VLOOKUP(Tabla3[[#This Row],[Site]],'Important Info!'!$A$1:$J$135,9,FALSE) -> 248
A27: =+Tabla3[[#This Row],[Site]]&Tabla3[[#This Row],[Split]] -> (RV) Toms Camperland Mesa (NO TOURS)4 | B27: 4 | C27: 1 | D27: 12:00 A.M. | E27: MST | F27: (RV) Toms Camperland Mesa (NO TOURS) | G27: 8:00 A.M. | H27: =VLOOKUP(Tabla3[[#This Row],[Site]],'Important Info!'!$A$1:$J$135,10,FALSE) -> https://tools.sig.systems/site/details/222 | J27: N/A | K27: =VLOOKUP(Tabla3[[#This Row],[Site]],'Important Info!'!$A$1:$H$135,8,FALSE) -> - | L27: =VLOOKUP(Tabla3[[#This Row],[Site]],'Important Info!'!$A$1:$F$135,2,FALSE) -> 1, 2 | M27: =VLOOKUP(Tabla3[[#This Row],[Site]],'Important Info!'!$A$1:$F$135,3,FALSE) -> - | N27: =VLOOKUP(Tabla3[[#This Row],[Site]],'Important Info!'!$A$1:$F$135,4,FALSE) -> - | O27: =VLOOKUP(Tabla3[[#This Row],[Site]],'Important Info!'!$A$1:$F$135,5,FALSE) -> - | P27: =VLOOKUP(Tabla3[[#This Row],[Site]],'Important Info!'!$A$1:$F$135,6,FALSE) -> 1, 4, 6, 8, 10, 18 | Q27: =VLOOKUP(Tabla3[[#This Row],[Site]],'Important Info!'!$A$1:$J$135,9,FALSE) -> 222
A28: =+Tabla3[[#This Row],[Site]]&Tabla3[[#This Row],[Split]] -> (SCH) Delray I & II4 | B28: 4 | C28: 1 | D28: 9:00 P.M. | E28: ET | F28: (SCH) Delray I & II | G28: 5:00 A.M. | H28: =VLOOKUP(Tabla3[[#This Row],[Site]],'Important Info!'!$A$1:$J$135,10,FALSE) -> https://tools.sig.systems/site/details/159 | J28: 11:00 A.M. | K28: =VLOOKUP(Tabla3[[#This Row],[Site]],'Important Info!'!$A$1:$H$135,8,FALSE) -> - | L28: =VLOOKUP(Tabla3[[#This Row],[Site]],'Important Info!'!$A$1:$F$135,2,FALSE) -> 5, 28, 31 | M28: =VLOOKUP(Tabla3[[#This Row],[Site]],'Important Info!'!$A$1:$F$135,3,FALSE) -> 1, 29 | N28: =VLOOKUP(Tabla3[[#This Row],[Site]],'Important Info!'!$A$1:$F$135,4,FALSE) -> 6 | O28: =VLOOKUP(Tabla3[[#This Row],[Site]],'Important Info!'!$A$1:$F$135,5,FALSE) -> - | P28: =VLOOKUP(Tabla3[[#This Row],[Site]],'Important Info!'!$A$1:$F$135,6,FALSE) -> 1, 35, 36 | Q28: =VLOOKUP(Tabla3[[#This Row],[Site]],'Important Info!'!$A$1:$J$135,9,FALSE) -> 159
A29: =+Tabla3[[#This Row],[Site]]&Tabla3[[#This Row],[Split]] -> (AS) Coggin Acura Ft Pierce (NO TOURS)4 | B29: 4 | C29: 2 | D29: 9:00 P.M. | E29: ET | F29: (AS) Coggin Acura Ft Pierce (NO TOURS) | G29: 5:00 A.M. | H29: =VLOOKUP(Tabla3[[#This Row],[Site]],'Important Info!'!$A$1:$J$135,10,FALSE) -> https://tools.sig.systems/site/details/118 | I29: https://www.google.com/maps/d/viewer?mid=1AyViBuyeq7iwDua1SVudJ2A1BYi3IBA&ll=27.38181516363982%2C-80.32568845000002&z=18 | J29: N/A | K29: =VLOOKUP(Tabla3[[#This Row],[Site]],'Important Info!'!$A$1:$H$135,8,FALSE) -> - | L29: =VLOOKUP(Tabla3[[#This Row],[Site]],'Important Info!'!$A$1:$F$135,2,FALSE) -> - | M29: =VLOOKUP(Tabla3[[#This Row],[Site]],'Important Info!'!$A$1:$F$135,3,FALSE) -> 6 | N29: =VLOOKUP(Tabla3[[#This Row],[Site]],'Important Info!'!$A$1:$F$135,4,FALSE) -> - | O29: =VLOOKUP(Tabla3[[#This Row],[Site]],'Important Info!'!$A$1:$F$135,5,FALSE) -> 4, 6 | P29: =VLOOKUP(Tabla3[[#This Row],[Site]],'Important Info!'!$A$1:$F$135,6,FALSE) -> 1 | Q29: =VLOOKUP(Tabla3[[#This Row],[Site]],'Important Info!'!$A$1:$J$135,9,FALSE) -> 118
A30: =+Tabla3[[#This Row],[Site]]&Tabla3[[#This Row],[Split]] -> (AS) Coggin Mercedes Benz Ft Pierce (NO TOURS)4 | B30: 4 | C30: 2 | D30: 9:00 P.M. | E30: ET | F30: (AS) Coggin Mercedes Benz Ft Pierce (NO TOURS) | G30: 5:00 A.M. | H30: =VLOOKUP(Tabla3[[#This Row],[Site]],'Important Info!'!$A$1:$J$135,10,FALSE) -> https://tools.sig.systems/site/details/127 | I30: https://www.google.com/maps/d/viewer?mid=1AyViBuyeq7iwDua1SVudJ2A1BYi3IBA&ll=27.38181516363982%2C-80.32568845000002&z=18 | J30: N/A | K30: =VLOOKUP(Tabla3[[#This Row],[Site]],'Important Info!'!$A$1:$H$135,8,FALSE) -> - | L30: =VLOOKUP(Tabla3[[#This Row],[Site]],'Important Info!'!$A$1:$F$135,2,FALSE) -> 18 | M30: =VLOOKUP(Tabla3[[#This Row],[Site]],'Important Info!'!$A$1:$F$135,3,FALSE) -> 1, 3 | N30: =VLOOKUP(Tabla3[[#This Row],[Site]],'Important Info!'!$A$1:$F$135,4,FALSE) -> - | O30: =VLOOKUP(Tabla3[[#This Row],[Site]],'Important Info!'!$A$1:$F$135,5,FALSE) -> 6, 10, 13 | P30: =VLOOKUP(Tabla3[[#This Row],[Site]],'Important Info!'!$A$1:$F$135,6,FALSE) -> 1, 4, 5 | Q30: =VLOOKUP(Tabla3[[#This Row],[Site]],'Important Info!'!$A$1:$J$135,9,FALSE) -> 127
A31: =+Tabla3[[#This Row],[Site]]&Tabla3[[#This Row],[Split]] -> (AS) Lexus Grapevine I & II (NO TOURS)4 | B31: 4 | C31: 2 | D31: 10:00 P.M. | E31: CT | F31: (AS) Lexus Grapevine I & II (NO TOURS) | G31: 6:00 A.M. | H31: =VLOOKUP(Tabla3[[#This Row],[Site]],'Important Info!'!$A$1:$J$135,10,FALSE) -> https://tools.sig.systems/site/details/136 | J31: N/A | K31: =VLOOKUP(Tabla3[[#This Row],[Site]],'Important Info!'!$A$1:$H$135,8,FALSE) -> - | L31: =VLOOKUP(Tabla3[[#This Row],[Site]],'Important Info!'!$A$1:$F$135,2,FALSE) -> 4, 10, 14, 18, 33 | M31: =VLOOKUP(Tabla3[[#This Row],[Site]],'Important Info!'!$A$1:$F$135,3,FALSE) -> - | N31: =VLOOKUP(Tabla3[[#This Row],[Site]],'Important Info!'!$A$1:$F$135,4,FALSE) -> 81, 82, 83 | O31: =VLOOKUP(Tabla3[[#This Row],[Site]],'Important Info!'!$A$1:$F$135,5,FALSE) -> 4, 12, 15, 20, 30 | P31: =VLOOKUP(Tabla3[[#This Row],[Site]],'Important Info!'!$A$1:$F$135,6,FALSE) -> 10 | Q31: =VLOOKUP(Tabla3[[#This Row],[Site]],'Important Info!'!$A$1:$J$135,9,FALSE) -> 136
A32: =+Tabla3[[#This Row],[Site]]&Tabla3[[#This Row],[Split]] -> (AS) Lexus Smyrna (NO TOURS)4 | B32: 4 | C32: 2 | D32: 9:00 P.M. | E32: ET | F32: (AS) Lexus Smyrna (NO TOURS) | G32: 5:00 A.M. | H32: =VLOOKUP(Tabla3[[#This Row],[Site]],'Important Info!'!$A$1:$J$135,10,FALSE) -> https://tools.sig.systems/site/details/133 | J32: N/A | K32: =VLOOKUP(Tabla3[[#This Row],[Site]],'Important Info!'!$A$1:$H$135,8,FALSE) -> - | L32: =VLOOKUP(Tabla3[[#This Row],[Site]],'Important Info!'!$A$1:$F$135,2,FALSE) -> 2, 6, 10 | M32: =VLOOKUP(Tabla3[[#This Row],[Site]],'Important Info!'!$A$1:$F$135,3,FALSE) -> - | N32: =VLOOKUP(Tabla3[[#This Row],[Site]],'Important Info!'!$A$1:$F$135,4,FALSE) -> - | O32: =VLOOKUP(Tabla3[[#This Row],[Site]],'Important Info!'!$A$1:$F$135,5,FALSE) -> 3, 5, 10, 15 | P32: =VLOOKUP(Tabla3[[#This Row],[Site]],'Important Info!'!$A$1:$F$135,6,FALSE) -> 10, 11 | Q32: =VLOOKUP(Tabla3[[#This Row],[Site]],'Important Info!'!$A$1:$J$135,9,FALSE) -> 133
A33: =+Tabla3[[#This Row],[Site]]&Tabla3[[#This Row],[Split]] -> (AS) Nalley Luxury Collision Center (NO TOURS)4 | B33: 4 | C33: 2 | D33: 9:00 P.M. | E33: ET | F33: (AS) Nalley Luxury Collision Center (NO TOURS) | G33: 5:00 A.M. | H33: =VLOOKUP(Tabla3[[#This Row],[Site]],'Important Info!'!$A$1:$J$135,10,FALSE) -> https://tools.sig.systems/site/details/263 | I33: https://www.google.com/maps/d/edit?mid=1jkN3DS1BhUqp_dztjjW0PDwKfo_Yxsw&usp=sharing | J33: N/A | K33: =VLOOKUP(Tabla3[[#This Row],[Site]],'Important Info!'!$A$1:$H$135,8,FALSE) -> - | L33: =VLOOKUP(Tabla3[[#This Row],[Site]],'Important Info!'!$A$1:$F$135,2,FALSE) -> 6, 13 | M33: =VLOOKUP(Tabla3[[#This Row],[Site]],'Important Info!'!$A$1:$F$135,3,FALSE) -> - | N33: =VLOOKUP(Tabla3[[#This Row],[Site]],'Important Info!'!$A$1:$F$135,4,FALSE) -> - | O33: =VLOOKUP(Tabla3[[#This Row],[Site]],'Important Info!'!$A$1:$F$135,5,FALSE) -> - | P33: =VLOOKUP(Tabla3[[#This Row],[Site]],'Important Info!'!$A$1:$F$135,6,FALSE) -> 6, 7, 12 | Q33: =VLOOKUP(Tabla3[[#This Row],[Site]],'Important Info!'!$A$1:$J$135,9,FALSE) -> 263
A34: =+Tabla3[[#This Row],[Site]]&Tabla3[[#This Row],[Split]] -> (AS) Park Place Acura (NO TOURS)4 | B34: 4 | C34: 2 | D34: 10:00 P.M. | E34: CT | F34: (AS) Park Place Acura (NO TOURS) | G34: 6:00 A.M. | H34: =VLOOKUP(Tabla3[[#This Row],[Site]],'Important Info!'!$A$1:$J$135,10,FALSE) -> https://tools.sig.systems/site/details/259 | I34: https://www.google.com/maps/d/viewer?mid=1wg5suxVuxeNp_irHlvN772HcwD6W89E&ll=33.06373951220261%2C-96.82758025000001&z=18 | J34: N/A | K34: =VLOOKUP(Tabla3[[#This Row],[Site]],'Important Info!'!$A$1:$H$135,8,FALSE) -> - | L34: =VLOOKUP(Tabla3[[#This Row],[Site]],'Important Info!'!$A$1:$F$135,2,FALSE) -> 1, 2, 14, 16 | M34: =VLOOKUP(Tabla3[[#This Row],[Site]],'Important Info!'!$A$1:$F$135,3,FALSE) -> - | N34: =VLOOKUP(Tabla3[[#This Row],[Site]],'Important Info!'!$A$1:$F$135,4,FALSE) -> - | O34: =VLOOKUP(Tabla3[[#This Row],[Site]],'Important Info!'!$A$1:$F$135,5,FALSE) -> 1, 7, 13 | P34: =VLOOKUP(Tabla3[[#This Row],[Site]],'Important Info!'!$A$1:$F$135,6,FALSE) -> - | Q34: =VLOOKUP(Tabla3[[#This Row],[Site]],'Important Info!'!$A$1:$J$135,9,FALSE) -> 259
A35: =+Tabla3[[#This Row],[Site]]&Tabla3[[#This Row],[Split]] -> (AS) Park Place Volvo Sales (NO TOURS)4 | B35: 4 | C35: 2 | D35: 10:00 P.M. | E35: CT | F35: (AS) Park Place Volvo Sales (NO TOURS) | G35: 6:00 A.M. | H35: =VLOOKUP(Tabla3[[#This Row],[Site]],'Important Info!'!$A$1:$J$135,10,FALSE) -> https://tools.sig.systems/site/details/139 | I35: https://www.google.com/maps/d/edit?hl=es&mid=1uPmsRMsXnp74hPFW2t-sp2totVWF_xY&ll=32.83050137713022%2C-96.83197783061323&z=17 | J35: N/A | K35: =VLOOKUP(Tabla3[[#This Row],[Site]],'Important Info!'!$A$1:$H$135,8,FALSE) -> - | L35: =VLOOKUP(Tabla3[[#This Row],[Site]],'Important Info!'!$A$1:$F$135,2,FALSE) -> 4, 6, 9, 11 | M35: =VLOOKUP(Tabla3[[#This Row],[Site]],'Important Info!'!$A$1:$F$135,3,FALSE) -> - | N35: =VLOOKUP(Tabla3[[#This Row],[Site]],'Important Info!'!$A$1:$F$135,4,FALSE) -> - | O35: =VLOOKUP(Tabla3[[#This Row],[Site]],'Important Info!'!$A$1:$F$135,5,FALSE) -> 2, 9 | P35: =VLOOKUP(Tabla3[[#This Row],[Site]],'Important Info!'!$A$1:$F$135,6,FALSE) -> 4, 10, 11 | Q35: =VLOOKUP(Tabla3[[#This Row],[Site]],'Important Info!'!$A$1:$J$135,9,FALSE) -> 139
A36: =+Tabla3[[#This Row],[Site]]&Tabla3[[#This Row],[Split]] -> (AS) Stevinson Lexus of Lakewood (NO TOURS)4 | B36: 4 | C36: 2 | D36: 11:00 P.M. | E36: MT | F36: (AS) Stevinson Lexus of Lakewood (NO TOURS) | G36: 7:00 A.M. | H36: =VLOOKUP(Tabla3[[#This Row],[Site]],'Important Info!'!$A$1:$J$135,10,FALSE) -> https://tools.sig.systems/site/details/260 | I36: https://www.google.com/maps/d/edit?mid=1nAyK85WaWREy0lfxnmWn3USs2gC0nP0&usp=sharing | J36: N/A | K36: =VLOOKUP(Tabla3[[#This Row],[Site]],'Important Info!'!$A$1:$H$135,8,FALSE) -> - | L36: =VLOOKUP(Tabla3[[#This Row],[Site]],'Important Info!'!$A$1:$F$135,2,FALSE) -> - | M36: =VLOOKUP(Tabla3[[#This Row],[Site]],'Important Info!'!$A$1:$F$135,3,FALSE) -> 2, 10 | N36: =VLOOKUP(Tabla3[[#This Row],[Site]],'Important Info!'!$A$1:$F$135,4,FALSE) -> 9, 17 | O36: =VLOOKUP(Tabla3[[#This Row],[Site]],'Important Info!'!$A$1:$F$135,5,FALSE) -> - | P36: =VLOOKUP(Tabla3[[#This Row],[Site]],'Important Info!'!$A$1:$F$135,6,FALSE) -> 1, 2 | Q36: =VLOOKUP(Tabla3[[#This Row],[Site]],'Important Info!'!$A$1:$J$135,9,FALSE) -> 260
A37: =+Tabla3[[#This Row],[Site]]&Tabla3[[#This Row],[Split]] -> (DT) Albuquerque4 | B37: 4 | C37: 2 | D37: 11:00 P.M. | E37: MT | F37: (DT) Albuquerque | G37: 7:00 A.M. | H37: =VLOOKUP(Tabla3[[#This Row],[Site]],'Important Info!'!$A$1:$J$135,10,FALSE) -> https://tools.sig.systems/site/details/237 | J37: N/A | K37: =VLOOKUP(Tabla3[[#This Row],[Site]],'Important Info!'!$A$1:$H$135,8,FALSE) -> - | L37: =VLOOKUP(Tabla3[[#This Row],[Site]],'Important Info!'!$A$1:$F$135,2,FALSE) -> 14, 16 | M37: =VLOOKUP(Tabla3[[#This Row],[Site]],'Important Info!'!$A$1:$F$135,3,FALSE) -> - | N37: =VLOOKUP(Tabla3[[#This Row],[Site]],'Important Info!'!$A$1:$F$135,4,FALSE) -> - | O37: =VLOOKUP(Tabla3[[#This Row],[Site]],'Important Info!'!$A$1:$F$135,5,FALSE) -> 14, 15 | P37: =VLOOKUP(Tabla3[[#This Row],[Site]],'Important Info!'!$A$1:$F$135,6,FALSE) -> 12, 14, 16 | Q37: =VLOOKUP(Tabla3[[#This Row],[Site]],'Important Info!'!$A$1:$J$135,9,FALSE) -> 237
A38: =+Tabla3[[#This Row],[Site]]&Tabla3[[#This Row],[Split]] -> (DT) Wichita4 | B38: 4 | C38: 2 | D38: 10:00 P.M. | E38: CT | F38: (DT) Wichita | G38: 6:00 A.M. | H38: =VLOOKUP(Tabla3[[#This Row],[Site]],'Important Info!'!$A$1:$J$135,10,FALSE) -> https://tools.sig.systems/site/details/257 | J38: N/A | K38: =VLOOKUP(Tabla3[[#This Row],[Site]],'Important Info!'!$A$1:$H$135,8,FALSE) -> - | L38: =VLOOKUP(Tabla3[[#This Row],[Site]],'Important Info!'!$A$1:$F$135,2,FALSE) -> - | M38: =VLOOKUP(Tabla3[[#This Row],[Site]],'Important Info!'!$A$1:$F$135,3,FALSE) -> 10, 11 | N38: =VLOOKUP(Tabla3[[#This Row],[Site]],'Important Info!'!$A$1:$F$135,4,FALSE) -> - | O38: =VLOOKUP(Tabla3[[#This Row],[Site]],'Important Info!'!$A$1:$F$135,5,FALSE) -> - | P38: =VLOOKUP(Tabla3[[#This Row],[Site]],'Important Info!'!$A$1:$F$135,6,FALSE) -> 1, 5, 6, 10 | Q38: =VLOOKUP(Tabla3[[#This Row],[Site]],'Important Info!'!$A$1:$J$135,9,FALSE) -> 257
A39: =+Tabla3[[#This Row],[Site]]&Tabla3[[#This Row],[Split]] -> (HUD) Honda Greensboro4 | B39: 4 | C39: 2 | D39: 9:00 P.M. | E39: ET | F39: (HUD) Honda Greensboro | G39: 5:00 A.M. | H39: =VLOOKUP(Tabla3[[#This Row],[Site]],'Important Info!'!$A$1:$J$135,10,FALSE) -> https://tools.sig.systems/site/details/230 | I39: AS/ HUD - Crown Greensboro - Google My Maps | J39: N/A | K39: =VLOOKUP(Tabla3[[#This Row],[Site]],'Important Info!'!$A$1:$H$135,8,FALSE) -> - | L39: =VLOOKUP(Tabla3[[#This Row],[Site]],'Important Info!'!$A$1:$F$135,2,FALSE) -> 1, 3, 15, 16, 22 | M39: =VLOOKUP(Tabla3[[#This Row],[Site]],'Important Info!'!$A$1:$F$135,3,FALSE) -> - | N39: =VLOOKUP(Tabla3[[#This Row],[Site]],'Important Info!'!$A$1:$F$135,4,FALSE) -> - | O39: =VLOOKUP(Tabla3[[#This Row],[Site]],'Important Info!'!$A$1:$F$135,5,FALSE) -> 3, 20 | P39: =VLOOKUP(Tabla3[[#This Row],[Site]],'Important Info!'!$A$1:$F$135,6,FALSE) -> 26 | Q39: =VLOOKUP(Tabla3[[#This Row],[Site]],'Important Info!'!$A$1:$J$135,9,FALSE) -> 230
A40: =+Tabla3[[#This Row],[Site]]&Tabla3[[#This Row],[Split]] -> (HUD) Paint and Body Center (NO TOURS)4 | B40: 4 | C40: 2 | D40: 9:00 P.M. | E40: ET | F40: (HUD) Paint and Body Center (NO TOURS) | G40: 5:00 A.M. | H40: =VLOOKUP(Tabla3[[#This Row],[Site]],'Important Info!'!$A$1:$J$135,10,FALSE) -> https://tools.sig.systems/site/details/256 | I40: https://www.google.com/maps/d/viewer?mid=1ejOzT7-x6RWnCf83BBP7XhiOiwEX3Wk&ll=36.061264791292906%2C-79.87437695000003&z=17 | J40: N/A | K40: =VLOOKUP(Tabla3[[#This Row],[Site]],'Important Info!'!$A$1:$H$135,8,FALSE) -> - | L40: =VLOOKUP(Tabla3[[#This Row],[Site]],'Important Info!'!$A$1:$F$135,2,FALSE) -> - | M40: =VLOOKUP(Tabla3[[#This Row],[Site]],'Important Info!'!$A$1:$F$135,3,FALSE) -> 1 | N40: =VLOOKUP(Tabla3[[#This Row],[Site]],'Important Info!'!$A$1:$F$135,4,FALSE) -> - | O40: =VLOOKUP(Tabla3[[#This Row],[Site]],'Important Info!'!$A$1:$F$135,5,FALSE) -> - | P40: =VLOOKUP(Tabla3[[#This Row],[Site]],'Important Info!'!$A$1:$F$135,6,FALSE) -> - | Q40: =VLOOKUP(Tabla3[[#This Row],[Site]],'Important Info!'!$A$1:$J$135,9,FALSE) -> 256
...

Sheet Important Info!
A1: SITES | B1: GATES | C1: ENTRANCES | D1: LPR GATES | E1: PTZ | F1: IMPORTANT CAMERAS | G1: BLIND SPOT | H1: NOTES | I1: ID | J1: SIG TOOLS
A2: (AS) Atwell Prep Center-Dallas (NO TOURS) | B2: 4, 6, 7 | C2: - | D2: - | E2: - | F2: 1, 2 | G2: - | H2: - | I2: 165 | J2: ="https://tools.sig.systems/site/details/" & Table3[[#This Row],[ID]] -> https://tools.sig.systems/site/details/165
A3: (AS) Audi of North Atlanta (NO TOURS) | B3: 1, 5, 16, 54 | C3: - | D3: - | E3: 3, 16 | F3: 2, 5, 6 | G3: - | H3: - | I3: 124 | J3: ="https://tools.sig.systems/site/details/" & Table3[[#This Row],[ID]] -> https://tools.sig.systems/site/details/124
A4: (AS) Bill Estes Ford (NO TOURS) | B4: - | C4: 2, 3, 13, 16 | D4: - | E4: 1, 10, 14, 19 | F4: 7, 8, 9, 10, 11, 12, 14 | G4: - | H4: - | I4: 125 | J4: ="https://tools.sig.systems/site/details/" & Table3[[#This Row],[ID]] -> https://tools.sig.systems/site/details/125
A5: (AS) Coggin Acura Ft Pierce (NO TOURS) | B5: - | C5: 6 | D5: - | E5: 4, 6 | F5: 1 | G5: - | H5: - | I5: 118 | J5: ="https://tools.sig.systems/site/details/" & Table3[[#This Row],[ID]] -> https://tools.sig.systems/site/details/118
A6: (AS) Coggin Honda Ft. Pierce (NO TOURS) | B6: 1, 2, 3, 4, 14 | C6: - | D6: - | E6: 7, 11, 15 | F6: 3 | G6: - | H6: - | I6: 120 | J6: ="https://tools.sig.systems/site/details/" & Table3[[#This Row],[ID]] -> https://tools.sig.systems/site/details/120
A7: (AS) Coggin Mercedes Benz Ft Pierce (NO TOURS) | B7: 18 | C7: 1, 3 | D7: - | E7: 6, 10, 13 | F7: 1, 4, 5 | G7: - | H7: - | I7: 127 | J7: ="https://tools.sig.systems/site/details/" & Table3[[#This Row],[ID]] -> https://tools.sig.systems/site/details/127
A8: (AS) Courtesy CDJR of Brandon (NO TOURS) | B8: 1, 14, 15 | C8: 1 | D8: - | E8: 2, 12 | F8: 1, 2, 3, 4, 14, 15, 21, 25 | G8: - | H8: - | I8: 126 | J8: ="https://tools.sig.systems/site/details/" & Table3[[#This Row],[ID]] -> https://tools.sig.systems/site/details/126
A9: (AS) Courtesy Honda Palm Harbor (NO TOURS) | B9: 2 | C9: - | D9: - | E9: 4, 8, 21 | F9: 10 | G9: - | H9: - | I9: 176 | J9: ="https://tools.sig.systems/site/details/" & Table3[[#This Row],[ID]] -> https://tools.sig.systems/site/details/176
A10: (AS) Courtesy Hyundai/Nissan Tampa (NO TOURS) | B10: 1, 16, 25, 27, 32 | C10: - | D10: - | E10: 4, 10, 16 | F10: 24, 25, 26 & Remote Lots | G10: - | H10: - | I10: 128 | J10: ="https://tools.sig.systems/site/details/" & Table3[[#This Row],[ID]] -> https://tools.sig.systems/site/details/128
A11: (AS) Courtesy Kia of Brandon (NO TOURS) | B11: - | C11: 4, 8 | D11: - | E11: 3, 11, 20, 24 | F11: 2, 8 | G11: - | H11: - | I11: 121 | J11: ="https://tools.sig.systems/site/details/" & Table3[[#This Row],[ID]] -> https://tools.sig.systems/site/details/121
A12: (AS) David McDavid Honda I & II (NO TOURS) | B12: - | C12: 3, 19, 23, 32, 35 | D12: - | E12: 2, 6, 9, 19, 25, 30, 48 | F12: 25, 26, 35, 36, 37 | G12: - | H12: - | I12: 129 | J12: ="https://tools.sig.systems/site/details/" & Table3[[#This Row],[ID]] -> https://tools.sig.systems/site/details/129
