Workbook
Name SegmentaciónDeDatos_Split: #N/A
Name SegmentaciónDeDatos_Split1: #N/A
Name SegmentaciónDeDatos_Split11: #N/A
Name SegmentaciónDeDatos_Split2: #N/A
Name SegmentaciónDeDatos_Station: #N/A
Name SegmentaciónDeDatos_Station1: #N/A
Name SegmentaciónDeDatos_Station11: #N/A

Sheet Dynamic Split
AF1: Alphabetical Order
A2: From: Split-Station: | AF2: Site
K3: Searched Site: | N3: Serached Site: | O3: (LT) Luther Bloomington Hyundai (NO TOURS) | AF3: (AS) 3281 Storage Lot (NO TOURS)
AF4: (AS) Hare Chevrolet (NO TOURS)
K5: Its On: | N5: Station | O5: =+N5 -> Station | AF5: (AS) Koons Arlington Toyota - New Car (NO TOURS)
N6: 5 | O6: =+N6 -> 5 | AF6: (AS) Koons Chevrolet Buick GMC - Tysons Remote Lot (NO TOURS)
AF7: (AS) Koons Volvo Cars White Marsh (NO TOURS)
AF8: (BRL) Shoemakersville
AF9: (DT) Arlington
AF10: (LT) Luther Bloomington Hyundai (NO TOURS)
AF11: (LT) Luther Landers Recon Center
AF12: (LT) Luther St. Cloud Subaru
AF13: (SCH) Schumacher of Delray I & III
AF14: (TC) Lamborghini South Dade
A15: Split | B15: Station | C15: Total Sites | G15: Log Out from | J15: Total New Sites
A16: 5 | B16: 5 | C16: 12 | G16: =+COUNTIF('Dynamic Split'!G19:G75,"Log Out") -> 0 | J16: =+GETPIVOTDATA("Site",$C$15)-G16 -> 12
A18: Split | B18: Log Time | C18: Sites | D18: Drop time | E18: Time | F18: ID | G18: Suma de Station | J18: SIG Tools | L18: Split | M18: Log Time | N18: Sites | O18: SUNDAY (D.T.) | P18: Gates | Q18: Entrances | R18: LPR | S18: PTZ | T18: Important Cameras | U18: Sum of Station
A19: 5 | B19: 24H | C19: (BRL) Shoemakersville | D19: - | E19: ET | F19: 302 | G19: 5 | J19: =IFERROR(HYPERLINK(VLOOKUP(C19,'Flat Base'!D:J,5,0),"SIG TOOLS"),"") -> SIG TOOLS | K19: =IFERROR(HYPERLINK(VLOOKUP(C19,'Flat Base'!D:J,4,0),"SITE MAP"),"") -> SITE MAP | L19: 5 | M19: 24H | N19: (BRL) Shoemakersville | O19: - | P19: - | Q19: 8, 11 | R19: - | S19: 1, 6, 13A, 15, 18A | T19: 13B, 23 | U19: 5
B20: 9:00 P.M. | C20: (TC) Lamborghini South Dade | D20: 5:00 A.M. | E20: ET | F20: 313 | G20: 5 | J20: =IFERROR(HYPERLINK(VLOOKUP(C20,'Flat Base'!D:J,5,0),"SIG TOOLS"),"") -> SIG TOOLS | K20: =IFERROR(HYPERLINK(VLOOKUP(C20,'Flat Base'!D:J,4,0),"SITE MAP"),"") -> SITE MAP | M20: 9:00 P.M. | N20: (TC) Lamborghini South Dade | O20: - | P20: - | Q20: 9, 11 | R20: - | S20: - | T20: - | U20: 5
C21: (AS) Hare Chevrolet (NO TOURS) | D21: 5:00 A.M. | E21: ET | F21: 301 | G21: 5 | J21: =IFERROR(HYPERLINK(VLOOKUP(C21,'Flat Base'!D:J,5,0),"SIG TOOLS"),"") -> SIG TOOLS | K21: =IFERROR(HYPERLINK(VLOOKUP(C21,'Flat Base'!D:J,4,0),"SITE MAP"),"") -> SITE MAP | N21: (AS) Hare Chevrolet (NO TOURS) | O21: - | P21: 18, 24 | Q21: 2, 3 | R21: - | S21: 5 | T21: 1, 5, 7, 8, 21, 29 | U21: 5
C22: (AS) Koons Arlington Toyota - New Car (NO TOURS) | D22: 5:00 A.M. | E22: ET | F22: 334 | G22: 5 | J22: =IFERROR(HYPERLINK(VLOOKUP(C22,'Flat Base'!D:J,5,0),"SIG TOOLS"),"") -> SIG TOOLS | K22: =IFERROR(HYPERLINK(VLOOKUP(C22,'Flat Base'!D:J,4,0),"SITE MAP"),"") -> SITE MAP | N22: (AS) Koons Arlington Toyota - New Car (NO TOURS) | O22: 10:00 A.M. | P22: - | Q22: 1, 3, 12, 15, 17 | R22: - | S22: - | T22: 2, 6, 18, 20 | U22: 5
C23: (AS) Koons Chevrolet Buick GMC - Tysons Remote Lot (NO TOURS) | D23: 5:00 A.M. | E23: ET | F23: 333 | G23: 5 | J23: =IFERROR(HYPERLINK(VLOOKUP(C23,'Flat Base'!D:J,5,0),"SIG TOOLS"),"") -> SIG TOOLS | K23: =IFERROR(HYPERLINK(VLOOKUP(C23,'Flat Base'!D:J,4,0),"SITE MAP"),"") -> SITE MAP | N23: (AS) Koons Chevrolet Buick GMC - Tysons Remote Lot (NO TOURS) | O23: - | P23: - | Q23: 6 | R23: 1, 2, 3 | S23: 7, 10, 16, 29 | T23: 14, 17, 30 | U23: 5
C24: (AS) Koons Volvo Cars White Marsh (NO TOURS) | D24: 5:00 A.M. | E24: ET | F24: 338 | G24: 5 | J24: =IFERROR(HYPERLINK(VLOOKUP(C24,'Flat Base'!D:J,5,0),"SIG TOOLS"),"") -> SIG TOOLS | K24: =IFERROR(HYPERLINK(VLOOKUP(C23,'Flat Base'!D:J,4,0),"SITE MAP"),"") -> SITE MAP | N24: (AS) Koons Volvo Cars White Marsh (NO TOURS) | O24: - | P24: - | Q24: 5, 7, 9 | R24: - | S24: - | T24: 6, 10, 1 | U24: 5
C25: (SCH) Schumacher of Delray I & III | D25: 5:00 A.M. | E25: ET | F25: 159 | G25: 5 | J25: =IFERROR(HYPERLINK(VLOOKUP(C25,'Flat Base'!D:J,5,0),"SIG TOOLS"),"") -> SIG TOOLS | K25: =IFERROR(HYPERLINK(VLOOKUP(C25,'Flat Base'!D:J,4,0),"SITE MAP"),"") -> SITE MAP | N25: (SCH) Schumacher of Delray I & III | O25: 11:00 A.M. | P25: 11, 21, 22, 57, 69 | Q25: 2, 16, 46 | R25: - | S25: - | T25: 24, 39 | U25: 5
B26: 10:00 P.M. | C26: (LT) Luther St. Cloud Subaru | D26: 5:30 A.M. | E26: CT | F26: 295 | G26: 5 | J26: =IFERROR(HYPERLINK(VLOOKUP(C26,'Flat Base'!D:J,5,0),"SIG TOOLS"),"") -> SIG TOOLS | K26: =IFERROR(HYPERLINK(VLOOKUP(C26,'Flat Base'!D:J,4,0),"SITE MAP"),"") -> SITE MAP | M26: 10:00 P.M. | N26: (LT) Luther St. Cloud Subaru | O26: - | P26: 25, 31 | Q26: 9, 13, 20 | R26: 38, 39, 40, 41 | S26: 27 | T26: 2, 6, 8, 11, 14, 19, 23, 26 | U26: 5
C27: (LT) Luther Landers Recon Center | D27: 6:00 A.M. | E27: CT | F27: 323 | G27: 5 | J27: =IFERROR(HYPERLINK(VLOOKUP(C27,'Flat Base'!D:J,5,0),"SIG TOOLS"),"") -> SIG TOOLS | K27: =IFERROR(HYPERLINK(VLOOKUP(C27,'Flat Base'!D:J,4,0),"SITE MAP"),"") -> SITE MAP | N27: (LT) Luther Landers Recon Center | O27: - | P27: 2, 4 | Q27: - | R27: - | S27: - | T27: 3, 9, 11 | U27: 5
C28: (DT) Arlington | D28: 6:00 A.M. | E28: CT | F28: 334 | G28: 5 | J28: =IFERROR(HYPERLINK(VLOOKUP(C28,'Flat Base'!D:J,5,0),"SIG TOOLS"),"") -> SIG TOOLS | K28: =IFERROR(HYPERLINK(VLOOKUP(C28,'Flat Base'!D:J,4,0),"SITE MAP"),"") -> SITE MAP | N28: (DT) Arlington | O28: - | P28: 8 | Q28: 3 | R28: - | S28: - | T28: 3, 8, 9 | U28: 5
C29: (AS) 3281 Storage Lot (NO TOURS) | D29: 6:00 A.M. | E29: CT | F29: 305 | G29: 5 | J29: =IFERROR(HYPERLINK(VLOOKUP(C29,'Flat Base'!D:J,5,0),"SIG TOOLS"),"") -> SIG TOOLS | K29: =IFERROR(HYPERLINK(VLOOKUP(C29,'Flat Base'!D:J,4,0),"SITE MAP"),"") -> SITE MAP | N29: (AS) 3281 Storage Lot (NO TOURS) | O29: - | P29: - | Q29: 2, 14 | R29: - | S29: - | T29: 1, 3, 9, 10, 14 | U29: 5
C30: (LT) Luther Bloomington Hyundai (NO TOURS) | D30: 6:00 A.M. | E30: CT | F30: 318 | G30: 5 | J30: =IFERROR(HYPERLINK(VLOOKUP(C30,'Flat Base'!D:J,5,0),"SIG TOOLS"),"") -> SIG TOOLS | K30: =IFERROR(HYPERLINK(VLOOKUP(C30,'Flat Base'!D:J,4,0),"SITE MAP"),"") -> SITE MAP | N30: (LT) Luther Bloomington Hyundai (NO TOURS) | O30: - | P30: - | Q30: 6, 9, 13 | R30: 58, 59 | S30: 10 | T30: 11, 18 | U30: 5
J31: =IFERROR(HYPERLINK(VLOOKUP(C31,'Flat Base'!D:J,5,0),"SIG TOOLS"),"") | K31: =IFERROR(HYPERLINK(VLOOKUP(C31,'Flat Base'!D:J,4,0),"SITE MAP"),"")
J32: =IFERROR(HYPERLINK(VLOOKUP(C32,'Flat Base'!D:J,5,0),"SIG TOOLS"),"") | K32: =IFERROR(HYPERLINK(VLOOKUP(C32,'Flat Base'!D:J,4,0),"SITE MAP"),"")
J33: =IFERROR(HYPERLINK(VLOOKUP(C33,'Flat Base'!D:J,5,0),"SIG TOOLS"),"") | K33: =IFERROR(HYPERLINK(VLOOKUP(C33,'Flat Base'!D:J,4,0),"SITE MAP"),"")
J34: =IFERROR(HYPERLINK(VLOOKUP(C34,'Flat Base'!D:J,5,0),"SIG TOOLS"),"") | K34: =IFERROR(HYPERLINK(VLOOKUP(C34,'Flat Base'!D:J,4,0),"SITE MAP"),"")
J35: =IFERROR(HYPERLINK(VLOOKUP(C35,'Flat Base'!D:J,5,0),"SIG TOOLS"),"") | K35: =IFERROR(HYPERLINK(VLOOKUP(C35,'Flat Base'!D:J,4,0),"SITE MAP"),"")
J36: =IFERROR(HYPERLINK(VLOOKUP(C36,'Flat Base'!D:J,5,0),"SIG TOOLS"),"") | K36: =IFERROR(HYPERLINK(VLOOKUP(C36,'Flat Base'!D:J,4,0),"SITE MAP"),"")
J37: =IFERROR(HYPERLINK(VLOOKUP(C37,'Flat Base'!D:J,5,0),"SIG TOOLS"),"") | K37: =IFERROR(HYPERLINK(VLOOKUP(C37,'Flat Base'!D:J,4,0),"SITE MAP"),"")
J38: =IFERROR(HYPERLINK(VLOOKUP(C38,'Flat Base'!D:J,5,0),"SIG TOOLS"),"") | K38: =IFERROR(HYPERLINK(VLOOKUP(C38,'Flat Base'!D:J,4,0),"SITE MAP"),"")
J39: =IFERROR(HYPERLINK(VLOOKUP(C39,'Flat Base'!D:J,5,0),"SIG TOOLS"),"") | K39: =IFERROR(HYPERLINK(VLOOKUP(C39,'Flat Base'!D:J,4,0),"SITE MAP"),"")
J40: =IFERROR(HYPERLINK(VLOOKUP(C40,'Flat Base'!D:J,5,0),"SIG TOOLS"),"") | K40: =IFERROR(HYPERLINK(VLOOKUP(C40,'Flat Base'!D:J,4,0),"SITE MAP"),"")
J41: =IFERROR(HYPERLINK(VLOOKUP(C41,'Flat Base'!D:J,5,0),"SIG TOOLS"),"") | K41: =IFERROR(HYPERLINK(VLOOKUP(C41,'Flat Base'!D:J,4,0),"SITE MAP"),"")
...

Sheet Cambio de Split
A1: Changes: Split-Station:
A15: New Sites | G15: Log In to
A16: 61 | G16: =+COUNTIF('Dynamic Split'!Y25:Y75,"Log iN") -> 0
A19: Split | B19: Log Time | C19: Site | D19: Drop time | E19: Suma de Station | F19: Log In | G19: Split | H19: Log Time | I19: Site | J19: Drop time | K19: Suma de Station
A20: 1 | B20: 8:00 P.M. | C20: (PE) BMW Service Center (NO TOURS) | D20: 5:00 A.M. | E20: 1 | F20: =IF('Cambio de Split'!C20="","",IFERROR(IF(Maestra!C16="#N/D","Log In",""),"Log In")) -> Log In | G20: 1 | H20: 8:00 P.M. | I20: (PE) BMW Service Center (NO TOURS) | J20: 5:00 A.M. | K20: 1
C21: (PE) JLR Englewood (NO TOURS) | D21: 5:00 A.M. | E21: 1 | F21: =IF('Cambio de Split'!C21="","",IFERROR(IF(Maestra!C17="#N/D","Log In",""),"Log In")) -> Log In | I21: (PE) JLR Englewood (NO TOURS) | J21: 5:00 A.M. | K21: 1
C22: (PE) JLR Paramus (NO TOURS) | D22: 5:00 A.M. | E22: 1 | F22: =IF('Cambio de Split'!C22="","",IFERROR(IF(Maestra!C18="#N/D","Log In",""),"Log In")) -> Log In | I22: (PE) JLR Paramus (NO TOURS) | J22: 5:00 A.M. | K22: 1
C23: (PE) MB of Greenwich | D23: 5:00 A.M. | E23: 1 | F23: =IF('Cambio de Split'!C23="","",IFERROR(IF(Maestra!C19="#N/D","Log In",""),"Log In")) -> Log In | I23: (PE) MB of Greenwich | J23: 5:00 A.M. | K23: 1
C24: (PE) Porsche Audi Fairfield (NO TOURS) | D24: 5:00 A.M. | E24: 1 | F24: =IF('Cambio de Split'!C24="","",IFERROR(IF(Maestra!C20="#N/D","Log In",""),"Log In")) -> Log In | I24: (PE) Porsche Audi Fairfield (NO TOURS) | J24: 5:00 A.M. | K24: 1
C25: (PE) JLR Darien (NO TOURS) | D25: 5:00 A.M. | E25: 1 | F25: =IF('Dynamic Split'!V24="","",IFERROR(IF(Maestra!C21="#N/D","Log In",""),"Log In")) | I25: (PE) JLR Darien (NO TOURS) | J25: 5:00 A.M. | K25: 1
B26: 9:00 P.M. | C26: (AS) Coggin BMW Ft. Pierce (NO TOURS) | D26: 5:00 A.M. | E26: 1 | H26: 9:00 P.M. | I26: (AS) Coggin BMW Ft. Pierce (NO TOURS) | J26: 5:00 A.M. | K26: 1
C27: (DT) Charlotte | D27: 5:00 A.M. | E27: 1 | I27: (DT) Charlotte | J27: 5:00 A.M. | K27: 1
C28: (AS) Koons MB of Catonsville (NO TOURS) | D28: 5:00 A.M. | E28: 1 | I28: (AS) Koons MB of Catonsville (NO TOURS) | J28: 5:00 A.M. | K28: 1
C29: (TC) Lamborghini South Dade | D29: 5:00 A.M. | E29: 1 | I29: (TC) Lamborghini South Dade | J29: 5:00 A.M. | K29: 1
C30: (AS) Coggin Collision Center of Kissimmee (NO TOURS) | D30: 5:00 A.M. | E30: 1 | I30: (AS) Coggin Collision Center of Kissimmee (NO TOURS) | J30: 5:00 A.M. | K30: 1
C31: (AS) Koons Baltimore Ford - Main Dealership (NO TOURS) | D31: 5:00 A.M. | E31: 1 | I31: (AS) Koons Baltimore Ford - Main Dealership (NO TOURS) | J31: 5:00 A.M. | K31: 1
C32: (AS) Coggin Honda of Orlando (NO TOURS) | D32: 5:00 A.M. | E32: 1 | I32: (AS) Coggin Honda of Orlando (NO TOURS) | J32: 5:00 A.M. | K32: 1
C33: (AS) Hare Chevrolet (NO TOURS) | D33: 5:00 A.M. | E33: 1 | I33: (AS) Hare Chevrolet (NO TOURS) | J33: 5:00 A.M. | K33: 1
C34: (AS) Hare Truck Center (NO TOURS) | D34: 5:00 A.M. | E34: 1 | I34: (AS) Hare Truck Center (NO TOURS) | J34: 5:00 A.M. | K34: 1
C35: (AS) Kahlo CDJR (NO TOURS) | D35: 5:00 A.M. | E35: 1 | I35: (AS) Kahlo CDJR (NO TOURS) | J35: 5:00 A.M. | K35: 1
C36: (AS) Koons Arlington Toyota - New Car (NO TOURS) | D36: 5:00 A.M. | E36: 1 | I36: (AS) Koons Arlington Toyota - New Car (NO TOURS) | J36: 5:00 A.M. | K36: 1
C37: (AS) Koons Chevrolet Buick GMC - Clarksville (NO TOURS) | D37: 5:00 A.M. | E37: 1 | I37: (AS) Koons Chevrolet Buick GMC - Clarksville (NO TOURS) | J37: 5:00 A.M. | K37: 1
C38: (AS) Koons Chevrolet Buick GMC - Tysons Remote Lot (NO TOURS) | D38: 5:00 A.M. | E38: 1 | I38: (AS) Koons Chevrolet Buick GMC - Tysons Remote Lot (NO TOURS) | J38: 5:00 A.M. | K38: 1
... C55: (AS) Koons Tysons Toyota - UC Recon (NO TOURS) | D55: 5:00 A.M. | E55: 1 | I55: (AS) Koons Tysons Toyota - UC Recon (NO TOURS) | J55: 5:00 A.M. | K55: 1
B56: 10:00 P.M. | C56: (ML) Joe Machens Hyundai | D56: 6:00 A.M. | E56: 1 | H56: 10:00 P.M. | I56: (ML) Joe Machens Hyundai | J56: 6:00 A.M. | K56: 1
C57: (KG) Big Star Cadillac | D57: 6:00 A.M. | E57: 1 | I57: (KG) Big Star Cadillac | J57: 6:00 A.M. | K57: 1
C58: (LT) Luther Brookdale Toyota | D58: 5:00 A.M. | E58: 1 | I58: (LT) Luther Brookdale Toyota | J58: 5:00 A.M. | K58: 1
C59: (LT) Luther North Country Ford | D59: 6:00 A.M. | E59: 1 | I59: (LT) Luther North Country Ford | J59: 6:00 A.M. | K59: 1
C60: (LT) Luther St. Cloud Subaru | D60: 5:30 A.M. | E60: 1 | I60: (LT) Luther St. Cloud Subaru | J60: 5:30 A.M. | K60: 1
C61: (LT) Landers Kia of Little Rock | D61: 6:00 A.M. | E61: 1 | I61: (LT) Landers Kia of Little Rock | J61: 6:00 A.M. | K61: 1
C62: (LT) Luther Landers Recon Center | D62: 6:00 A.M. | E62: 1 | I62: (LT) Luther Landers Recon Center | J62: 6:00 A.M. | K62: 1
C63: (LT) Luther Genesis of Minneapolis | D63: 6:00 A.M. | E63: 1 | I63: (LT) Luther Genesis of Minneapolis | J63: 6:00 A.M. | K63: 1
C64: (LT) Luther Brookdale Honda (NO TOURS) | D64: 6:00 A.M. | E64: 1 | I64: (LT) Luther Brookdale Honda (NO TOURS) | J64: 6:00 A.M. | K64: 1
C65: (LT) Luther Burnsville Hyundai | D65: 6:00 A.M. | E65: 1 | I65: (LT) Luther Burnsville Hyundai | J65: 6:00 A.M. | K65: 1
C66: (LT) Luther Hopkins Honda (NO TOURS) | D66: 6:00 A.M. | E66: 1 | I66: (LT) Luther Hopkins Honda (NO TOURS) | J66: 6:00 A.M. | K66: 1
C67: (DT) Arlington | D67: 6:00 A.M. | E67: 1 | I67: (DT) Arlington | J67: 6:00 A.M. | K67: 1
C68: (AS) 3281 Storage Lot (NO TOURS) | D68: 6:00 A.M. | E68: 1 | I68: (AS) 3281 Storage Lot (NO TOURS) | J68: 6:00 A.M. | K68: 1
... C72: (LT) Luther Bloomington Hyundai (NO TOURS) | D72: 6:00 A.M. | E72: 1 | I72: (LT) Luther Bloomington Hyundai (NO TOURS) | J72: 6:00 A.M. | K72: 1
B73: 11:00 P.M. | C73: (AS) Larry H Miller CDJR Fiat (NO TOURS) | D73: 7:00 A.M. | E73: 1 | H73: 11:00 P.M. | I73: (AS) Larry H Miller CDJR Fiat (NO TOURS) | J73: 7:00 A.M. | K73: 1
B74: 12:00 A.M. | C74: (DT) Modesto | D74: 8:00 A.M. | E74: 1 | H74: 12:00 A.M. | I74: (DT) Modesto | J74: 8:00 A.M. | K74: 1
...

Sheet Maestra
A16: =+VLOOKUP('Dynamic Split'!C19,'Dynamic Split'!V:V,1,0) -> #N/A | C16: =VLOOKUP('Cambio de Split'!C20,'Dynamic Split'!C:C,1,0) -> #N/A
A17: =+VLOOKUP('Dynamic Split'!C20,'Dynamic Split'!V:V,1,0) -> #N/A | C17: =VLOOKUP('Cambio de Split'!C21,'Dynamic Split'!C:C,1,0) -> #N/A
A18: =+VLOOKUP('Dynamic Split'!C21,'Dynamic Split'!V:V,1,0) -> #N/A | C18: =VLOOKUP('Cambio de Split'!C22,'Dynamic Split'!C:C,1,0) -> #N/A
A19: =+VLOOKUP('Dynamic Split'!C22,'Dynamic Split'!V:V,1,0) -> #N/A | C19: =VLOOKUP('Cambio de Split'!C23,'Dynamic Split'!C:C,1,0) -> #N/A
A20: =+VLOOKUP('Dynamic Split'!#REF!,'Dynamic Split'!V:V,1,0) -> #REF! | C20: =VLOOKUP('Cambio de Split'!C24,'Dynamic Split'!C:C,1,0) -> #N/A
A21: =+VLOOKUP('Dynamic Split'!C23,'Dynamic Split'!V:V,1,0) -> #N/A | C21: =VLOOKUP('Dynamic Split'!V24,'Dynamic Split'!C:C,1,0) -> #N/A
A22: =+VLOOKUP('Dynamic Split'!C25,'Dynamic Split'!V:V,1,0) -> #N/A | C22: =VLOOKUP('Dynamic Split'!V25,'Dynamic Split'!C:C,1,0) -> #N/A
A23: =+VLOOKUP('Dynamic Split'!C26,'Dynamic Split'!V:V,1,0) -> #N/A | C23: =VLOOKUP('Dynamic Split'!V26,'Dynamic Split'!C:C,1,0) -> #N/A
A24: =+VLOOKUP('Dynamic Split'!C27,'Dynamic Split'!V:V,1,0) -> #N/A | C24: =VLOOKUP('Dynamic Split'!V27,'Dynamic Split'!C:C,1,0) -> #N/A
A25: =+VLOOKUP('Dynamic Split'!C28,'Dynamic Split'!V:V,1,0) -> #N/A | C25: =VLOOKUP('Dynamic Split'!V28,'Dynamic Split'!C:C,1,0) -> #N/A
A26: =+VLOOKUP('Dynamic Split'!C29,'Dynamic Split'!V:V,1,0) -> #N/A | C26: =VLOOKUP('Dynamic Split'!V29,'Dynamic Split'!C:C,1,0) -> #N/A
A27: =+VLOOKUP('Dynamic Split'!C30,'Dynamic Split'!V:V,1,0) -> #N/A | C27: =VLOOKUP('Dynamic Split'!V30,'Dynamic Split'!C:C,1,0) -> #N/A
A28: =+VLOOKUP('Dynamic Split'!C31,'Dynamic Split'!V:V,1,0) -> #N/A | C28: =VLOOKUP('Dynamic Split'!V31,'Dynamic Split'!C:C,1,0) -> #N/A
A29: =+VLOOKUP('Dynamic Split'!C32,'Dynamic Split'!V:V,1,0) -> #N/A | C29: =VLOOKUP('Dynamic Split'!V32,'Dynamic Split'!C:C,1,0) -> #N/A
A30: =+VLOOKUP('Dynamic Split'!C33,'Dynamic Split'!V:V,1,0) -> #N/A | C30: =VLOOKUP('Dynamic Split'!V33,'Dynamic Split'!C:C,1,0) -> #N/A
A31: =+VLOOKUP('Dynamic Split'!C34,'Dynamic Split'!V:V,1,0) -> #N/A | C31: =VLOOKUP('Dynamic Split'!V34,'Dynamic Split'!C:C,1,0) -> #N/A
A32: =+VLOOKUP('Dynamic Split'!C35,'Dynamic Split'!V:V,1,0) -> #N/A | C32: =VLOOKUP('Dynamic Split'!V35,'Dynamic Split'!C:C,1,0) -> #N/A
A33: =+VLOOKUP('Dynamic Split'!C36,'Dynamic Split'!V:V,1,0) -> #N/A | C33: =VLOOKUP('Dynamic Split'!V36,'Dynamic Split'!C:C,1,0) -> #N/A
... A72: =+VLOOKUP('Dynamic Split'!C75,'Dynamic Split'!V:V,1,0) -> #N/A | C72: =VLOOKUP('Dynamic Split'!V75,'Dynamic Split'!C:C,1,0) -> #N/A

Sheet Flat Base
A1: Key | B1: Split | C1: Station | D1: Site | E1: Hour | F1: Time | G1: Drop time | H1: SIG Tools | I1: Map | J1: SUNDAY (D.T.) | K1: Notes* | L1: Gates | M1: Entrances | N1: LPR | O1: PTZ | P1: Important Cameras | Q1: ID
A2: =+Tabla3[[#This Row],[Site]]&Tabla3[[#This Row],[Split]] -> (AS) 3281 Storage Lot (NO TOURS)1 | B2: 1 | C2: 1 | D2: (AS) 3281 Storage Lot (NO TOURS) | E2: =VLOOKUP(Tabla3[[#This Row],[Site]],Table35[],10,FALSE) -> 10:00 P.M. | F2: =VLOOKUP(Tabla3[[#This Row],[Site]],Table35[],11,FALSE) -> CT | G2: =VLOOKUP(Tabla3[[#This Row],[Site]],Table35[],12,FALSE) -> 6:00 A.M. | H2: =HYPERLINK(VLOOKUP(Tabla3[[#This Row],[Site]],Table35[#All],9,FALSE)) -> https://tools.sig.systems/site/details/305 | I2: =VLOOKUP(Tabla3[[#This Row],[Site]],Table35[],13,FALSE) -> https://www.google.com/maps/d/edit?hl=es&mid=1uPmsRMsXnp74hPFW2t-sp2totVWF_xY&ll=32.83050137713022%2C-96.83197783061323&z=17 | J2: =VLOOKUP(Tabla3[[#This Row],[Site]],Table35[],14,FALSE) -> - | L2: =VLOOKUP(Tabla3[[#This Row],[Site]],Table35[#All],2,FALSE) -> - | M2: =VLOOKUP(Tabla3[[#This Row],[Site]],Table35[#All],3,FALSE) -> 2, 14 | N2: =VLOOKUP(Tabla3[[#This Row],[Site]],Table35[#All],4,FALSE) -> - | O2: =VLOOKUP(Tabla3[[#This Row],[Site]],Table35[#All],5,FALSE) -> - | P2: =VLOOKUP(Tabla3[[#This Row],[Site]],Table35[#All],6,FALSE) -> 1, 3, 9, 10, 14 | Q2: =VLOOKUP(Tabla3[[#This Row],[Site]],Table35[#All],8,FALSE) -> 305
A3: =+Tabla3[[#This Row],[Site]]&Tabla3[[#This Row],[Split]] -> (AS) Coggin BMW Ft. Pierce (NO TOURS)1 | B3: 1 | C3: 1 | D3: (AS) Coggin BMW Ft. Pierce (NO TOURS) | E3: =VLOOKUP(Tabla3[[#This Row],[Site]],Table35[],10,FALSE) -> 9:00 P.M. | F3: =VLOOKUP(Tabla3[[#This Row],[Site]],Table35[],11,FALSE) -> ET | G3: =VLOOKUP(Tabla3[[#This Row],[Site]],Table35[],12,FALSE) -> 5:00 A.M. | H3: =HYPERLINK(VLOOKUP(Tabla3[[#This Row],[Site]],Table35[#All],9,FALSE)) -> https://tools.sig.systems/site/details/119 | I3: =VLOOKUP(Tabla3[[#This Row],[Site]],Table35[],13,FALSE) -> https://www.google.com/maps/d/viewer?mid=1AyViBuyeq7iwDua1SVudJ2A1BYi3IBA&ll=27.38181516363982%2C-80.32568845000002&z=18 | J3: =VLOOKUP(Tabla3[[#This Row],[Site]],Table35[],14,FALSE) -> - | L3: =VLOOKUP(Tabla3[[#This Row],[Site]],Table35[#All],2,FALSE) -> 3, 10, 13 | M3: =VLOOKUP(Tabla3[[#This Row],[Site]],Table35[#All],3,FALSE) -> - | N3: =VLOOKUP(Tabla3[[#This Row],[Site]],Table35[#All],4,FALSE) -> - | O3: =VLOOKUP(Tabla3[[#This Row],[Site]],Table35[#All],5,FALSE) -> 2 | P3: =VLOOKUP(Tabla3[[#This Row],[Site]],Table35[#All],6,FALSE) -> 1, 20, 27 | Q3: =VLOOKUP(Tabla3[[#This Row],[Site]],Table35[#All],8,FALSE) -> 119
A4: =+Tabla3[[#This Row],[Site]]&Tabla3[[#This Row],[Split]] -> (AS) Coggin Collision Center of Kissimmee (NO TOURS)1 | B4: 1 | C4: 1 | D4: (AS) Coggin Collision Center of Kissimmee (NO TOURS) | E4: =VLOOKUP(Tabla3[[#This Row],[Site]],Table35[],10,FALSE) -> 9:00 P.M. | F4: =VLOOKUP(Tabla3[[#This Row],[Site]],Table35[],11,FALSE) -> ET | G4: =VLOOKUP(Tabla3[[#This Row],[Site]],Table35[],12,FALSE) -> 5:00 A.M. | H4: =HYPERLINK(VLOOKUP(Tabla3[[#This Row],[Site]],Table35[#All],9,FALSE)) -> https://tools.sig.systems/site/details/331 | I4: =VLOOKUP(Tabla3[[#This Row],[Site]],Table35[],13,FALSE) -> 0 | J4: =VLOOKUP(Tabla3[[#This Row],[Site]],Table35[],14,FALSE) -> - | L4: =VLOOKUP(Tabla3[[#This Row],[Site]],Table35[#All],2,FALSE) -> 1, 12 | M4: =VLOOKUP(Tabla3[[#This Row],[Site]],Table35[#All],3,FALSE) -> - | N4: =VLOOKUP(Tabla3[[#This Row],[Site]],Table35[#All],4,FALSE) -> - | O4: =VLOOKUP(Tabla3[[#This Row],[Site]],Table35[#All],5,FALSE) -> - | P4: =VLOOKUP(Tabla3[[#This Row],[Site]],Table35[#All],6,FALSE) -> 2, 7, 9 | Q4: =VLOOKUP(Tabla3[[#This Row],[Site]],Table35[#All],8,FALSE) -> 331
A5: =+Tabla3[[#This Row],[Site]]&Tabla3[[#This Row],[Split]] -> (AS) Coggin Honda of Orlando (NO TOURS)1 | B5: 1 | C5: 1 | D5: (AS) Coggin Honda of Orlando (NO TOURS) | E5: =VLOOKUP(Tabla3[[#This Row],[Site]],Table35[],10,FALSE) -> 9:00 P.M. | F5: =VLOOKUP(Tabla3[[#This Row],[Site]],Table35[],11,FALSE) -> ET | G5: =VLOOKUP(Tabla3[[#This Row],[Site]],Table35[],12,FALSE) -> 5:00 A.M. | H5: =HYPERLINK(VLOOKUP(Tabla3[[#This Row],[Site]],Table35[#All],9,FALSE)) -> https://tools.sig.systems/site/details/324 | I5: =VLOOKUP(Tabla3[[#This Row],[Site]],Table35[],13,FALSE) -> 0 | J5: =VLOOKUP(Tabla3[[#This Row],[Site]],Table35[],14,FALSE) -> 11:00 A.M. | L5: =VLOOKUP(Tabla3[[#This Row],[Site]],Table35[#All],2,FALSE) -> 2, 10, 12B, 14, 38 | M5: =VLOOKUP(Tabla3[[#This Row],[Site]],Table35[#All],3,FALSE) -> - | N5: =VLOOKUP(Tabla3[[#This Row],[Site]],Table35[#All],4,FALSE) -> - | O5: =VLOOKUP(Tabla3[[#This Row],[Site]],Table35[#All],5,FALSE) -> 12, 31 | P5: =VLOOKUP(Tabla3[[#This Row],[Site]],Table35[#All],6,FALSE) -> 12B, 26, 37, 19 | Q5: =VLOOKUP(Tabla3[[#This Row],[Site]],Table35[#All],8,FALSE) -> 324
A6: =+Tabla3[[#This Row],[Site]]&Tabla3[[#This Row],[Split]] -> (AS) Hare Chevrolet (NO TOURS)1 | B6: 1 | C6: 1 | D6: (AS) Hare Chevrolet (NO TOURS) | E6: =VLOOKUP(Tabla3[[#This Row],[Site]],Table35[],10,FALSE) -> 9:00 P.M. | F6: =VLOOKUP(Tabla3[[#This Row],[Site]],Table35[],11,FALSE) -> ET | G6: =VLOOKUP(Tabla3[[#This Row],[Site]],Table35[],12,FALSE) -> 5:00 A.M. | H6: =HYPERLINK(VLOOKUP(Tabla3[[#This Row],[Site]],Table35[#All],9,FALSE)) -> https://tools.sig.systems/site/details/301 | I6: =VLOOKUP(Tabla3[[#This Row],[Site]],Table35[],13,FALSE) -> https://www.google.com/maps/d/edit?mid=1hsX5GGrNcCQgAuzDCDz1OWgEkhsAc78&usp=sharing | J6: =VLOOKUP(Tabla3[[#This Row],[Site]],Table35[],14,FALSE) -> - | L6: =VLOOKUP(Tabla3[[#This Row],[Site]],Table35[#All],2,FALSE) -> 18, 24 | M6: =VLOOKUP(Tabla3[[#This Row],[Site]],Table35[#All],3,FALSE) -> 2, 3 | N6: =VLOOKUP(Tabla3[[#This Row],[Site]],Table35[#All],4,FALSE) -> - | O6: =VLOOKUP(Tabla3[[#This Row],[Site]],Table35[#All],5,FALSE) -> 5 | P6: =VLOOKUP(Tabla3[[#This Row],[Site]],Table35[#All],6,FALSE) -> 1, 5, 7, 8, 21, 29 | Q6: =VLOOKUP(Tabla3[[#This Row],[Site]],Table35[#All],8,FALSE) -> 301
A7: =+Tabla3[[#This Row],[Site]]&Tabla3[[#This Row],[Split]] -> (AS) Hare Truck Center (NO TOURS)1 | B7: 1 | C7: 1 | D7: (AS) Hare Truck Center (NO TOURS) | E7: =VLOOKUP(Tabla3[[#This Row],[Site]],Table35[],10,FALSE) -> 9:00 P.M. | F7: =VLOOKUP(Tabla3[[#This Row],[Site]],Table35[],11,FALSE) -> ET | G7: =VLOOKUP(Tabla3[[#This Row],[Site]],Table35[],12,FALSE) -> 5:00 A.M. | H7: =HYPERLINK(VLOOKUP(Tabla3[[#This Row],[Site]],Table35[#All],9,FALSE)) -> https://tools.sig.systems/site/details/300 | I7: =VLOOKUP(Tabla3[[#This Row],[Site]],Table35[],13,FALSE) -> https://www.google.com/maps/d/edit?mid=1hsX5GGrNcCQgAuzDCDz1OWgEkhsAc78&usp=sharing | J7: =VLOOKUP(Tabla3[[#This Row],[Site]],Table35[],14,FALSE) -> - | L7: =VLOOKUP(Tabla3[[#This Row],[Site]],Table35[#All],2,FALSE) -> - | M7: =VLOOKUP(Tabla3[[#This Row],[Site]],Table35[#All],3,FALSE) -> 1, 5 | N7: =VLOOKUP(Tabla3[[#This Row],[Site]],Table35[#All],4,FALSE) -> - | O7: =VLOOKUP(Tabla3[[#This Row],[Site]],Table35[#All],5,FALSE) -> - | P7: =VLOOKUP(Tabla3[[#This Row],[Site]],Table35[#All],6,FALSE) -> 2, 6, 10, 12, 17 | Q7: =VLOOKUP(Tabla3[[#This Row],[Site]],Table35[#All],8,FALSE) -> 300
A8: =+Tabla3[[#This Row],[Site]]&Tabla3[[#This Row],[Split]] -> (AS) Kahlo CDJR (NO TOURS)1 | B8: 1 | C8: 1 | D8: (AS) Kahlo CDJR (NO TOURS) | E8: =VLOOKUP(Tabla3[[#This Row],[Site]],Table35[],10,FALSE) -> 9:00 P.M. | F8: =VLOOKUP(Tabla3[[#This Row],[Site]],Table35[],11,FALSE) -> ET | G8: =VLOOKUP(Tabla3[[#This Row],[Site]],Table35[],12,FALSE) -> 5:00 A.M. | H8: =HYPERLINK(VLOOKUP(Tabla3[[#This Row],[Site]],Table35[#All],9,FALSE)) -> https://tools.sig.systems/site/details/282 | I8: =VLOOKUP(Tabla3[[#This Row],[Site]],Table35[],13,FALSE) -> https://www.google.com/maps/d/edit?mid=1hsX5GGrNcCQgAuzDCDz1OWgEkhsAc78&usp=sharing | J8: =VLOOKUP(Tabla3[[#This Row],[Site]],Table35[],14,FALSE) -> - | L8: =VLOOKUP(Tabla3[[#This Row],[Site]],Table35[#All],2,FALSE) -> - | M8: =VLOOKUP(Tabla3[[#This Row],[Site]],Table35[#All],3,FALSE) -> 12, 25 | N8: =VLOOKUP(Tabla3[[#This Row],[Site]],Table35[#All],4,FALSE) -> 15, 16 | O8: =VLOOKUP(Tabla3[[#This Row],[Site]],Table35[#All],5,FALSE) -> 20 | P8: =VLOOKUP(Tabla3[[#This Row],[Site]],Table35[#All],6,FALSE) -> 1, 2, 9, 22, 31, 57 | Q8: =VLOOKUP(Tabla3[[#This Row],[Site]],Table35[#All],8,FALSE) -> 282
A9: =+Tabla3[[#This Row],[Site]]&Tabla3[[#This Row],[Split]] -> (AS) Koons Annapolis Toyota (NO TOURS)1 | B9: 1 | C9: 1 | D9: (AS) Koons Annapolis Toyota (NO TOURS) | E9: =VLOOKUP(Tabla3[[#This Row],[Site]],Table35[],10,FALSE) -> 9:00 P.M. | F9: =VLOOKUP(Tabla3[[#This Row],[Site]],Table35[],11,FALSE) -> ET | G9: =VLOOKUP(Tabla3[[#This Row],[Site]],Table35[],12,FALSE) -> 5:00 A.M. | H9: =HYPERLINK(VLOOKUP(Tabla3[[#This Row],[Site]],Table35[#All],9,FALSE)) -> https://tools.sig.systems/site/details/337 | I9: =VLOOKUP(Tabla3[[#This Row],[Site]],Table35[],13,FALSE) -> 0 | J9: =VLOOKUP(Tabla3[[#This Row],[Site]],Table35[],14,FALSE) -> - | L9: =VLOOKUP(Tabla3[[#This Row],[Site]],Table35[#All],2,FALSE) -> 6 | M9: =VLOOKUP(Tabla3[[#This Row],[Site]],Table35[#All],3,FALSE) -> 1, 6, 21 | N9: =VLOOKUP(Tabla3[[#This Row],[Site]],Table35[#All],4,FALSE) -> - | O9: =VLOOKUP(Tabla3[[#This Row],[Site]],Table35[#All],5,FALSE) -> - | P9: =VLOOKUP(Tabla3[[#This Row],[Site]],Table35[#All],6,FALSE) -> 3, 5, 7, 19 | Q9: =VLOOKUP(Tabla3[[#This Row],[Site]],Table35[#All],8,FALSE) -> 337
A10: =+Tabla3[[#This Row],[Site]]&Tabla3[[#This Row],[Split]] -> (AS) Koons Arlington Toyota - New Car (NO TOURS)1 | B10: 1 | C10: 1 | D10: (AS) Koons Arlington Toyota - New Car (NO TOURS) | E10: =VLOOKUP(Tabla3[[#This Row],[Site]],Table35[],10,FALSE) -> 9:00 P.M. | F10: =VLOOKUP(Tabla3[[#This Row],[Site]],Table35[],11,FALSE) -> ET | G10: =VLOOKUP(Tabla3[[#This Row],[Site]],Table35[],12,FALSE) -> 5:00 A.M. | H10: =HYPERLINK(VLOOKUP(Tabla3[[#This Row],[Site]],Table35[#All],9,FALSE)) -> https://tools.sig.systems/site/details/334 | I10: =VLOOKUP(Tabla3[[#This Row],[Site]],Table35[],13,FALSE) -> 0 | J10: =VLOOKUP(Tabla3[[#This Row],[Site]],Table35[],14,FALSE) -> 10:00 A.M. | L10: =VLOOKUP(Tabla3[[#This Row],[Site]],Table35[#All],2,FALSE) -> - | M10: =VLOOKUP(Tabla3[[#This Row],[Site]],Table35[#All],3,FALSE) -> 1, 3, 12, 15, 17 | N10: =VLOOKUP(Tabla3[[#This Row],[Site]],Table35[#All],4,FALSE) -> - | O10: =VLOOKUP(Tabla3[[#This Row],[Site]],Table35[#All],5,FALSE) -> - | P10: =VLOOKUP(Tabla3[[#This Row],[Site]],Table35[#All],6,FALSE) -> 2, 6, 18, 20 | Q10: =VLOOKUP(Tabla3[[#This Row],[Site]],Table35[#All],8,FALSE) -> 334
A11: =+Tabla3[[#This Row],[Site]]&Tabla3[[#This Row],[Split]] -> (AS) Koons Baltimore Ford - Main Dealership (NO TOURS)1 | B11: 1 | C11: 1 | D11: (AS) Koons Baltimore Ford - Main Dealership (NO TOURS) | E11: =VLOOKUP(Tabla3[[#This Row],[Site]],Table35[],10,FALSE) -> 9:00 P.M. | F11: =VLOOKUP(Tabla3[[#This Row],[Site]],Table35[],11,FALSE) -> ET | G11: =VLOOKUP(Tabla3[[#This Row],[Site]],Table35[],12,FALSE) -> 5:00 A.M. | H11: =HYPERLINK(VLOOKUP(Tabla3[[#This Row],[Site]],Table35[#All],9,FALSE)) -> https://tools.sig.systems/site/details/335 | I11: =VLOOKUP(Tabla3[[#This Row],[Site]],Table35[],13,FALSE) -> - | J11: =VLOOKUP(Tabla3[[#This Row],[Site]],Table35[],14,FALSE) -> - | L11: =VLOOKUP(Tabla3[[#This Row],[Site]],Table35[#All],2,FALSE) -> 21, 22, 24, 32, 45 | M11: =VLOOKUP(Tabla3[[#This Row],[Site]],Table35[#All],3,FALSE) -> 1 | N11: =VLOOKUP(Tabla3[[#This Row],[Site]],Table35[#All],4,FALSE) -> - | O11: =VLOOKUP(Tabla3[[#This Row],[Site]],Table35[#All],5,FALSE) -> 1, 8 | P11: =VLOOKUP(Tabla3[[#This Row],[Site]],Table35[#All],6,FALSE) -> 5, 28, 38 | Q11: 335
A12: =+Tabla3[[#This Row],[Site]]&Tabla3[[#This Row],[Split]] -> (AS) Koons Chevrolet Buick GMC - Clarksville (NO TOURS)1 | B12: 1 | C12: 1 | D12: (AS) Koons Chevrolet Buick GMC - Clarksville (NO TOURS) | E12: =VLOOKUP(Tabla3[[#This Row],[Site]],Table35[],10,FALSE) -> 9:00 P.M. | F12: =VLOOKUP(Tabla3[[#This Row],[Site]],Table35[],11,FALSE) -> ET | G12: =VLOOKUP(Tabla3[[#This Row],[Site]],Table35[],12,FALSE) -> 5:00 A.M. | H12: =HYPERLINK(VLOOKUP(Tabla3[[#This Row],[Site]],Table35[#All],9,FALSE)) -> https://tools.sig.systems/site/details/306 | I12: =VLOOKUP(Tabla3[[#This Row],[Site]],Table35[],13,FALSE) -> https://www.google.com/maps/d/edit?hl=es&mid=11XB1lTSP7EcDCDvzypdUPWP6bWCNAEI&ll=39.21145022420528%2C-76.94003711910554&z=17 | J12: =VLOOKUP(Tabla3[[#This Row],[Site]],Table35[],14,FALSE) -> 10:00 A.M. | L12: =VLOOKUP(Tabla3[[#This Row],[Site]],Table35[#All],2,FALSE) -> - | M12: =VLOOKUP(Tabla3[[#This Row],[Site]],Table35[#All],3,FALSE) -> 1, 22, 26, 28, 29 | N12: =VLOOKUP(Tabla3[[#This Row],[Site]],Table35[#All],4,FALSE) -> - | O12: =VLOOKUP(Tabla3[[#This Row],[Site]],Table35[#All],5,FALSE) -> - | P12: =VLOOKUP(Tabla3[[#This Row],[Site]],Table35[#All],6,FALSE) -> 3, 11, 15, 23 | Q12: =VLOOKUP(Tabla3[[#This Row],[Site]],Table35[#All],8,FALSE) -> 306
A13: =+Tabla3[[#This Row],[Site]]&Tabla3[[#This Row],[Split]] -> (AS) Koons Chevrolet Buick GMC - Clarksville Remote Lot (NO TOURS)1 | B13: 1 | C13: 1 | D13: (AS) Koons Chevrolet Buick GMC - Clarksville Remote Lot (NO TOURS) | E13: =VLOOKUP(Tabla3[[#This Row],[Site]],Table35[],10,FALSE) -> 9:00 P.M. | F13: =VLOOKUP(Tabla3[[#This Row],[Site]],Table35[],11,FALSE) -> ET | G13: =VLOOKUP(Tabla3[[#This Row],[Site]],Table35[],12,FALSE) -> 5:00 A.M. | H13: =HYPERLINK(VLOOKUP(Tabla3[[#This Row],[Site]],Table35[#All],9,FALSE)) -> https://tools.sig.systems/site/details/308 | I13: =VLOOKUP(Tabla3[[#This Row],[Site]],Table35[],13,FALSE) -> https://www.google.com/maps/d/edit?hl=es&mid=11XB1lTSP7EcDCDvzypdUPWP6bWCNAEI&ll=39.21145022420528%2C-76.94003711910554&z=21 | J13: =VLOOKUP(Tabla3[[#This Row],[Site]],Table35[],14,FALSE) -> 10:00 A.M. | L13: =VLOOKUP(Tabla3[[#This Row],[Site]],Table35[#All],2,FALSE) -> - | M13: =VLOOKUP(Tabla3[[#This Row],[Site]],Table35[#All],3,FALSE) -> 1, 5 | N13: =VLOOKUP(Tabla3[[#This Row],[Site]],Table35[#All],4,FALSE) -> - | O13: =VLOOKUP(Tabla3[[#This Row],[Site]],Table35[#All],5,FALSE) -> - | P13: =VLOOKUP(Tabla3[[#This Row],[Site]],Table35[#All],6,FALSE) -> 14, 16 | Q13: =VLOOKUP(Tabla3[[#This Row],[Site]],Table35[#All],8,FALSE) -> 308
A14: =+Tabla3[[#This Row],[Site]]&Tabla3[[#This Row],[Split]] -> (AS) Koons Chevrolet Buick GMC - Tysons (NO TOURS)1 | B14: 1 | C14: 1 | D14: (AS) Koons Chevrolet Buick GMC - Tysons (NO TOURS) | E14: =VLOOKUP(Tabla3[[#This Row],[Site]],Table35[],10,FALSE) -> 9:00 P.M. | F14: =VLOOKUP(Tabla3[[#This Row],[Site]],Table35[],11,FALSE) -> ET | G14: =VLOOKUP(Tabla3[[#This Row],[Site]],Table35[],12,FALSE) -> 5:00 A.M. | H14: =HYPERLINK(VLOOKUP(Tabla3[[#This Row],[Site]],Table35[#All],9,FALSE)) -> https://tools.sig.systems/site/details/352 | I14: =VLOOKUP(Tabla3[[#This Row],[Site]],Table35[],13,FALSE) -> - | J14: =VLOOKUP(Tabla3[[#This Row],[Site]],Table35[],14,FALSE) -> 10:00 A.M. | L14: =VLOOKUP(Tabla3[[#This Row],[Site]],Table35[#All],2,FALSE) -> 4, 6 | M14: =VLOOKUP(Tabla3[[#This Row],[Site]],Table35[#All],3,FALSE) -> - | N14: =VLOOKUP(Tabla3[[#This Row],[Site]],Table35[#All],4,FALSE) -> - | O14: =VLOOKUP(Tabla3[[#This Row],[Site]],Table35[#All],5,FALSE) -> 4 | P14: =VLOOKUP(Tabla3[[#This Row],[Site]],Table35[#All],6,FALSE) -> 6, 12, 15 | Q14: =VLOOKUP(Tabla3[[#This Row],[Site]],Table35[#All],8,FALSE) -> 352
A15: =+Tabla3[[#This Row],[Site]]&Tabla3[[#This Row],[Split]] -> (AS) Koons Chevrolet Buick GMC - Tysons Remote Lot (NO TOURS)1 | B15: 1 | C15: 1 | D15: (AS) Koons Chevrolet Buick GMC - Tysons Remote Lot (NO TOURS) | E15: =VLOOKUP(Tabla3[[#This Row],[Site]],Table35[],10,FALSE) -> 9:00 P.M. | F15: =VLOOKUP(Tabla3[[#This Row],[Site]],Table35[],11,FALSE) -> ET | G15: =VLOOKUP(Tabla3[[#This Row],[Site]],Table35[],12,FALSE) -> 5:00 A.M. | H15: =HYPERLINK(VLOOKUP(Tabla3[[#This Row],[Site]],Table35[#All],9,FALSE)) -> https://tools.sig.systems/site/details/333 | I15: =VLOOKUP(Tabla3[[#This Row],[Site]],Table35[],13,FALSE) -> - | J15: =VLOOKUP(Tabla3[[#This Row],[Site]],Table35[],14,FALSE) -> - | L15: =VLOOKUP(Tabla3[[#This Row],[Site]],Table35[#All],2,FALSE) -> - | M15: =VLOOKUP(Tabla3[[#This Row],[Site]],Table35[#All],3,FALSE) -> 6 | N15: =VLOOKUP(Tabla3[[#This Row],[Site]],Table35[#All],4,FALSE) -> 1, 2, 3 | O15: =VLOOKUP(Tabla3[[#This Row],[Site]],Table35[#All],5,FALSE) -> 7, 10, 16, 29 | P15: =VLOOKUP(Tabla3[[#This Row],[Site]],Table35[#All],6,FALSE) -> 14, 17, 30 | Q15: =VLOOKUP(Tabla3[[#This Row],[Site]],Table35[#All],8,FALSE) -> 333
A16: =+Tabla3[[#This Row],[Site]]&Tabla3[[#This Row],[Split]] -> (AS) Koons Easton Toyota - Main Dealership (NO TOURS)1 | B16: 1 | C16: 1 | D16: (AS) Koons Easton Toyota - Main Dealership (NO TOURS) | E16: =VLOOKUP(Tabla3[[#This Row],[Site]],Table35[],10,FALSE) -> 9:00 P.M. | F16: =VLOOKUP(Tabla3[[#This Row],[Site]],Table35[],11,FALSE) -> ET | G16: =VLOOKUP(Tabla3[[#This Row],[Site]],Table35[],12,FALSE) -> 5:00 A.M. | H16: =HYPERLINK(VLOOKUP(Tabla3[[#This Row],[Site]],Table35[#All],9,FALSE)) -> https://tools.sig.systems/site/details/340 | I16: =VLOOKUP(Tabla3[[#This Row],[Site]],Table35[],13,FALSE) -> - | J16: =VLOOKUP(Tabla3[[#This Row],[Site]],Table35[],14,FALSE) -> - | L16: =VLOOKUP(Tabla3[[#This Row],[Site]],Table35[#All],2,FALSE) -> - | M16: =VLOOKUP(Tabla3[[#This Row],[Site]],Table35[#All],3,FALSE) -> 4, 5 | N16: =VLOOKUP(Tabla3[[#This Row],[Site]],Table35[#All],4,FALSE) -> - | O16: =VLOOKUP(Tabla3[[#This Row],[Site]],Table35[#All],5,FALSE) -> - | P16: =VLOOKUP(Tabla3[[#This Row],[Site]],Table35[#All],6,FALSE) -> 8, 15 | Q16: =VLOOKUP(Tabla3[[#This Row],[Site]],Table35[#All],8,FALSE) -> 340
A17: =+Tabla3[[#This Row],[Site]]&Tabla3[[#This Row],[Split]] -> (AS) Koons Falls Church Ford (NO TOURS)1 | B17: 1 | C17: 1 | D17: (AS) Koons Falls Church Ford (NO TOURS) | E17: =VLOOKUP(Tabla3[[#This Row],[Site]],Table35[],10,FALSE) -> 9:00 P.M. | F17: =VLOOKUP(Tabla3[[#This Row],[Site]],Table35[],11,FALSE) -> ET | G17: =VLOOKUP(Tabla3[[#This Row],[Site]],Table35[],12,FALSE) -> 5:00 A.M. | H17: =HYPERLINK(VLOOKUP(Tabla3[[#This Row],[Site]],Table35[#All],9,FALSE)) -> https://tools.sig.systems/site/details/345 | I17: =VLOOKUP(Tabla3[[#This Row],[Site]],Table35[],13,FALSE) -> - | J17: =VLOOKUP(Tabla3[[#This Row],[Site]],Table35[],14,FALSE) -> 10:00 A.M. | L17: =VLOOKUP(Tabla3[[#This Row],[Site]],Table35[#All],2,FALSE) -> - | M17: =VLOOKUP(Tabla3[[#This Row],[Site]],Table35[#All],3,FALSE) -> 1 | N17: =VLOOKUP(Tabla3[[#This Row],[Site]],Table35[#All],4,FALSE) -> - | O17: =VLOOKUP(Tabla3[[#This Row],[Site]],Table35[#All],5,FALSE) -> - | P17: =VLOOKUP(Tabla3[[#This Row],[Site]],Table35[#All],6,FALSE) -> - | Q17: =VLOOKUP(Tabla3[[#This Row],[Site]],Table35[#All],8,FALSE) -> 345
A18: =+Tabla3[[#This Row],[Site]]&Tabla3[[#This Row],[Split]] -> (AS) Koons MB of Catonsville (NO TOURS)1 | B18: 1 | C18: 1 | D18: (AS) Koons MB of Catonsville (NO TOURS) | E18: =VLOOKUP(Tabla3[[#This Row],[Site]],Table35[],10,FALSE) -> 9:00 P.M. | F18: =VLOOKUP(Tabla3[[#This Row],[Site]],Table35[],11,FALSE) -> ET | G18: =VLOOKUP(Tabla3[[#This Row],[Site]],Table35[],12,FALSE) -> 5:00 A.M. | H18: =HYPERLINK(VLOOKUP(Tabla3[[#This Row],[Site]],Table35[#All],9,FALSE)) -> https://tools.sig.systems/site/details/303 | I18: =VLOOKUP(Tabla3[[#This Row],[Site]],Table35[],13,FALSE) -> 0 | J18: =VLOOKUP(Tabla3[[#This Row],[Site]],Table35[],14,FALSE) -> - | L18: =VLOOKUP(Tabla3[[#This Row],[Site]],Table35[#All],2,FALSE) -> - | M18: =VLOOKUP(Tabla3[[#This Row],[Site]],Table35[#All],3,FALSE) -> 15, 16, 17, 29 | N18: =VLOOKUP(Tabla3[[#This Row],[Site]],Table35[#All],4,FALSE) -> 29 | O18: =VLOOKUP(Tabla3[[#This Row],[Site]],Table35[#All],5,FALSE) -> 5 | P18: =VLOOKUP(Tabla3[[#This Row],[Site]],Table35[#All],6,FALSE) -> 1, 7, 8, 12, 19, 32 | Q18: =VLOOKUP(Tabla3[[#This Row],[Site]],Table35[#All],8,FALSE) -> 303
A19: =+Tabla3[[#This Row],[Site]]&Tabla3[[#This Row],[Split]] -> (AS) Koons Owings Mills Kia (NO TOURS)1 | B19: 1 | C19: 1 | D19: (AS) Koons Owings Mills Kia (NO TOURS) | E19: =VLOOKUP(Tabla3[[#This Row],[Site]],Table35[],10,FALSE) -> 9:00 P.M. | F19: =VLOOKUP(Tabla3[[#This Row],[Site]],Table35[],11,FALSE) -> ET | G19: =VLOOKUP(Tabla3[[#This Row],[Site]],Table35[],12,FALSE) -> 5:00 A.M. | H19: =HYPERLINK(VLOOKUP(Tabla3[[#This Row],[Site]],Table35[#All],9,FALSE)) -> https://tools.sig.systems/site/details/336 | I19: =VLOOKUP(Tabla3[[#This Row],[Site]],Table35[],13,FALSE) -> - | J19: =VLOOKUP(Tabla3[[#This Row],[Site]],Table35[],14,FALSE) -> - | Q19: 336
A20: =+Tabla3[[#This Row],[Site]]&Tabla3[[#This Row],[Split]] -> (AS) Koons Sterling Ford - Main Dealership (NO TOURS)1 | B20: 1 | C20: 1 | D20: (AS) Koons Sterling Ford - Main Dealership (NO TOURS) | E20: =VLOOKUP(Tabla3[[#This Row],[Site]],Table35[],10,FALSE) -> 9:00 P.M. | F20: =VLOOKUP(Tabla3[[#This Row],[Site]],Table35[],11,FALSE) -> ET | G20: =VLOOKUP(Tabla3[[#This Row],[Site]],Table35[],12,FALSE) -> 5:00 A.M. | H20: =HYPERLINK(VLOOKUP(Tabla3[[#This Row],[Site]],Table35[#All],9,FALSE)) -> https://tools.sig.systems/site/details/348 | I20: =VLOOKUP(Tabla3[[#This Row],[Site]],Table35[],13,FALSE) -> - | J20: =VLOOKUP(Tabla3[[#This Row],[Site]],Table35[],14,FALSE) -> 10:00 A.M. | L20: =VLOOKUP(Tabla3[[#This Row],[Site]],Table35[#All],2,FALSE) -> 19 | M20: =VLOOKUP(Tabla3[[#This Row],[Site]],Table35[#All],3,FALSE) -> 3 | N20: =VLOOKUP(Tabla3[[#This Row],[Site]],Table35[#All],4,FALSE) -> - | O20: =VLOOKUP(Tabla3[[#This Row],[Site]],Table35[#All],5,FALSE) -> 4, 21 | P20: =VLOOKUP(Tabla3[[#This Row],[Site]],Table35[#All],6,FALSE) -> 7, 8 | Q20: =VLOOKUP(Tabla3[[#This Row],[Site]],Table35[#All],8,FALSE) -> 348
A21: =+Tabla3[[#This Row],[Site]]&Tabla3[[#This Row],[Split]] -> (AS) Koons Tysons Toyota - Main Dealership (NO TOURS)1 | B21: 1 | C21: 1 | D21: (AS) Koons Tysons Toyota - Main Dealership (NO TOURS) | E21: =VLOOKUP(Tabla3[[#This Row],[Site]],Table35[],10,FALSE) -> 9:00 P.M. | F21: =VLOOKUP(Tabla3[[#This Row],[Site]],Table35[],11,FALSE) -> ET | G21: =VLOOKUP(Tabla3[[#This Row],[Site]],Table35[],12,FALSE) -> 5:00 A.M. | H21: =HYPERLINK(VLOOKUP(Tabla3[[#This Row],[Site]],Table35[#All],9,FALSE)) -> https://tools.sig.systems/site/details/344 | I21: =VLOOKUP(Tabla3[[#This Row],[Site]],Table35[],13,FALSE) -> - | J21: =VLOOKUP(Tabla3[[#This Row],[Site]],Table35[],14,FALSE) -> - | L21: =VLOOKUP(Tabla3[[#This Row],[Site]],Table35[#All],2,FALSE) -> - | M21: =VLOOKUP(Tabla3[[#This Row],[Site]],Table35[#All],3,FALSE) -> 1, 25 | N21: =VLOOKUP(Tabla3[[#This Row],[Site]],Table35[#All],4,FALSE) -> - | O21: =VLOOKUP(Tabla3[[#This Row],[Site]],Table35[#All],5,FALSE) -> - | P21: =VLOOKUP(Tabla3[[#This Row],[Site]],Table35[#All],6,FALSE) -> 13, 22, 27 | Q21: =VLOOKUP(Tabla3[[#This Row],[Site]],Table35[#All],8,FALSE) -> 344
A22: =+Tabla3[[#This Row],[Site]]&Tabla3[[#This Row],[Split]] -> (AS) Koons Volvo Cars White Marsh (NO TOURS)1 | B22: 1 | C22: 1 | D22: (AS) Koons Volvo Cars White Marsh (NO TOURS) | E22: =VLOOKUP(Tabla3[[#This Row],[Site]],Table35[],10,FALSE) -> 9:00 P.M. | F22: =VLOOKUP(Tabla3[[#This Row],[Site]],Table35[],11,FALSE) -> ET | G22: =VLOOKUP(Tabla3[[#This Row],[Site]],Table35[],12,FALSE) -> 5:00 A.M. | H22: =HYPERLINK(VLOOKUP(Tabla3[[#This Row],[Site]],Table35[#All],9,FALSE)) -> https://tools.sig.systems/site/details/338 | I22: =VLOOKUP(Tabla3[[#This Row],[Site]],Table35[],13,FALSE) -> 0 | J22: =VLOOKUP(Tabla3[[#This Row],[Site]],Table35[],14,FALSE) -> - | L22: =VLOOKUP(Tabla3[[#This Row],[Site]],Table35[#All],2,FALSE) -> - | M22: =VLOOKUP(Tabla3[[#This Row],[Site]],Table35[#All],3,FALSE) -> 5, 7, 9 | N22: =VLOOKUP(Tabla3[[#This Row],[Site]],Table35[#All],4,FALSE) -> - | O22: =VLOOKUP(Tabla3[[#This Row],[Site]],Table35[#All],5,FALSE) -> - | P22: =VLOOKUP(Tabla3[[#This Row],[Site]],Table35[#All],6,FALSE) -> 6, 10, 1 | Q22: =VLOOKUP(Tabla3[[#This Row],[Site]],Table35[#All],8,FALSE) -> 338
A23: =+Tabla3[[#This Row],[Site]]&Tabla3[[#This Row],[Split]] -> (AS) Koons Westminster Toyota (NO TOURS)1 | B23: 1 | C23: 1 | D23: (AS) Koons Westminster Toyota (NO TOURS) | E23: =VLOOKUP(Tabla3[[#This Row],[Site]],Table35[],10,FALSE) -> 9:00 P.M. | F23: =VLOOKUP(Tabla3[[#This Row],[Site]],Table35[],11,FALSE) -> ET | G23: =VLOOKUP(Tabla3[[#This Row],[Site]],Table35[],12,FALSE) -> 5:00 A.M. | H23: =HYPERLINK(VLOOKUP(Tabla3[[#This Row],[Site]],Table35[#All],9,FALSE)) -> https://tools.sig.systems/site/details/341 | I23: =VLOOKUP(Tabla3[[#This Row],[Site]],Table35[],13,FALSE) -> - | J23: =VLOOKUP(Tabla3[[#This Row],[Site]],Table35[],14,FALSE) -> - | L23: =VLOOKUP(Tabla3[[#This Row],[Site]],Table35[#All],2,FALSE) -> - | M23: =VLOOKUP(Tabla3[[#This Row],[Site]],Table35[#All],3,FALSE) -> 1, 7, 9, 18, 25 | N23: =VLOOKUP(Tabla3[[#This Row],[Site]],Table35[#All],4,FALSE) -> - | O23: =VLOOKUP(Tabla3[[#This Row],[Site]],Table35[#All],5,FALSE) -> - | P23: =VLOOKUP(Tabla3[[#This Row],[Site]],Table35[#All],6,FALSE) -> 8, 14, 16 | Q23: 341
A24: =+Tabla3[[#This Row],[Site]]&Tabla3[[#This Row],[Split]] -> (AS) Koons White Marsh Chevrolet (NO TOURS)1 | B24: 1 | C24: 1 | D24: (AS) Koons White Marsh Chevrolet (NO TOURS) | E24: =VLOOKUP(Tabla3[[#This Row],[Site]],Table35[],10,FALSE) -> 9:00 P.M. | F24: =VLOOKUP(Tabla3[[#This Row],[Site]],Table35[],11,FALSE) -> ET | G24: =VLOOKUP(Tabla3[[#This Row],[Site]],Table35[],12,FALSE) -> 5:00 A.M. | H24: =HYPERLINK(VLOOKUP(Tabla3[[#This Row],[Site]],Table35[#All],9,FALSE)) -> https://tools.sig.systems/site/details/339 | I24: =VLOOKUP(Tabla3[[#This Row],[Site]],Table35[],13,FALSE) -> - | J24: =VLOOKUP(Tabla3[[#This Row],[Site]],Table35[],14,FALSE) -> - | L24: =VLOOKUP(Tabla3[[#This Row],[Site]],Table35[#All],2,FALSE) -> 25 | M24: =VLOOKUP(Tabla3[[#This Row],[Site]],Table35[#All],3,FALSE) -> 10 | N24: =VLOOKUP(Tabla3[[#This Row],[Site]],Table35[#All],4,FALSE) -> - | O24: =VLOOKUP(Tabla3[[#This Row],[Site]],Table35[#All],5,FALSE) -> - | P24: =VLOOKUP(Tabla3[[#This Row],[Site]],Table35[#All],6,FALSE) -> 12 | Q24: =VLOOKUP(Tabla3[[#This Row],[Site]],Table35[#All],8,FALSE) -> 339
A25: =+Tabla3[[#This Row],[Site]]&Tabla3[[#This Row],[Split]] -> (AS) Koons Woodbridge Ford (NO TOURS)1 | B25: 1 | C25: 1 | D25: (AS) Koons Woodbridge Ford (NO TOURS) | E25: =VLOOKUP(Tabla3[[#This Row],[Site]],Table35[],10,FALSE) -> 9:00 P.M. | F25: =VLOOKUP(Tabla3[[#This Row],[Site]],Table35[],11,FALSE) -> ET | G25: =VLOOKUP(Tabla3[[#This Row],[Site]],Table35[],12,FALSE) -> 5:00 A.M. | H25: =HYPERLINK(VLOOKUP(Tabla3[[#This Row],[Site]],Table35[#All],9,FALSE)) -> https://tools.sig.systems/site/details/342 | I25: =VLOOKUP(Tabla3[[#This Row],[Site]],Table35[],13,FALSE) -> 0 | J25: =VLOOKUP(Tabla3[[#This Row],[Site]],Table35[],14,FALSE) -> 9:00 A.M. | L25: =VLOOKUP(Tabla3[[#This Row],[Site]],Table35[#All],2,FALSE) -> - | M25: =VLOOKUP(Tabla3[[#This Row],[Site]],Table35[#All],3,FALSE) -> 3, 24, 26, 27, 31, 36 | N25: =VLOOKUP(Tabla3[[#This Row],[Site]],Table35[#All],4,FALSE) -> - | O25: =VLOOKUP(Tabla3[[#This Row],[Site]],Table35[#All],5,FALSE) -> - | P25: =VLOOKUP(Tabla3[[#This Row],[Site]],Table35[#All],6,FALSE) -> 13, 26, 29 | Q25: =VLOOKUP(Tabla3[[#This Row],[Site]],Table35[#All],8,FALSE) -> 342
A26: =+Tabla3[[#This Row],[Site]]&Tabla3[[#This Row],[Split]] -> (AS) Koons Woodbridge GMC (NO TOURS)1 | B26: 1 | C26: 1 | D26: (AS) Koons Woodbridge GMC (NO TOURS) | E26: =VLOOKUP(Tabla3[[#This Row],[Site]],Table35[],10,FALSE) -> 9:00 P.M. | F26: =VLOOKUP(Tabla3[[#This Row],[Site]],Table35[],11,FALSE) -> ET | G26: =VLOOKUP(Tabla3[[#This Row],[Site]],Table35[],12,FALSE) -> 5:00 A.M. | H26: =HYPERLINK(VLOOKUP(Tabla3[[#This Row],[Site]],Table35[#All],9,FALSE)) -> https://tools.sig.systems/site/details/343 | I26: =VLOOKUP(Tabla3[[#This Row],[Site]],Table35[],13,FALSE) -> 0 | J26: =VLOOKUP(Tabla3[[#This Row],[Site]],Table35[],14,FALSE) -> 10:00 A.M. | L26: =VLOOKUP(Tabla3[[#This Row],[Site]],Table35[#All],2,FALSE) -> - | M26: =VLOOKUP(Tabla3[[#This Row],[Site]],Table35[#All],3,FALSE) -> 1 | N26: =VLOOKUP(Tabla3[[#This Row],[Site]],Table35[#All],4,FALSE) -> - | O26: =VLOOKUP(Tabla3[[#This Row],[Site]],Table35[#All],5,FALSE) -> 11 | P26: =VLOOKUP(Tabla3[[#This Row],[Site]],Table35[#All],6,FALSE) -> 2, 7 | Q26: =VLOOKUP(Tabla3[[#This Row],[Site]],Table35[#All],8,FALSE) -> 343
A27: =+Tabla3[[#This Row],[Site]]&Tabla3[[#This Row],[Split]] -> (AS) Koons Woodbridge Hyundai (NO TOURS)1 | B27: 1 | C27: 1 | D27: (AS) Koons Woodbridge Hyundai (NO TOURS) | E27: =VLOOKUP(Tabla3[[#This Row],[Site]],Table35[],10,FALSE) -> 9:00 P.M. | F27: =VLOOKUP(Tabla3[[#This Row],[Site]],Table35[],11,FALSE) -> ET | G27: =VLOOKUP(Tabla3[[#This Row],[Site]],Table35[],12,FALSE) -> 5:00 A.M. | H27: =HYPERLINK(VLOOKUP(Tabla3[[#This Row],[Site]],Table35[#All],9,FALSE)) -> https://tools.sig.systems/site/details/347 | I27: =VLOOKUP(Tabla3[[#This Row],[Site]],Table35[],13,FALSE) -> - | J27: =VLOOKUP(Tabla3[[#This Row],[Site]],Table35[],14,FALSE) -> 8:00 A.M. | L27: =VLOOKUP(Tabla3[[#This Row],[Site]],Table35[#All],2,FALSE) -> - | M27: =VLOOKUP(Tabla3[[#This Row],[Site]],Table35[#All],3,FALSE) -> 1, 17 | N27: =VLOOKUP(Tabla3[[#This Row],[Site]],Table35[#All],4,FALSE) -> - | O27: =VLOOKUP(Tabla3[[#This Row],[Site]],Table35[#All],5,FALSE) -> - | P27: =VLOOKUP(Tabla3[[#This Row],[Site]],Table35[#All],6,FALSE) -> 4, 14, 22 | Q27: =VLOOKUP(Tabla3[[#This Row],[Site]],Table35[#All],8,FALSE) -> 347
A28: =+Tabla3[[#This Row],[Site]]&Tabla3[[#This Row],[Split]] -> (AS) Koons Woodbridge Kia (NO TOURS)1 | B28: 1 | C28: 1 | D28: (AS) Koons Woodbridge Kia (NO TOURS) | E28: =VLOOKUP(Tabla3[[#This Row],[Site]],Table35[],10,FALSE) -> 9:00 P.M. | F28: =VLOOKUP(Tabla3[[#This Row],[Site]],Table35[],11,FALSE) -> ET | G28: =VLOOKUP(Tabla3[[#This Row],[Site]],Table35[],12,FALSE) -> 5:00 A.M. | H28: =HYPERLINK(VLOOKUP(Tabla3[[#This Row],[Site]],Table35[#All],9,FALSE)) -> https://tools.sig.systems/site/details/346 | I28: =VLOOKUP(Tabla3[[#This Row],[Site]],Table35[],13,FALSE) -> - | J28: =VLOOKUP(Tabla3[[#This Row],[Site]],Table35[],14,FALSE) -> 10:00 A.M. | L28: =VLOOKUP(Tabla3[[#This Row],[Site]],Table35[#All],2,FALSE) -> - | M28: =VLOOKUP(Tabla3[[#This Row],[Site]],Table35[#All],3,FALSE) -> 2 | N28: =VLOOKUP(Tabla3[[#This Row],[Site]],Table35[#All],4,FALSE) -> - | O28: =VLOOKUP(Tabla3[[#This Row],[Site]],Table35[#All],5,FALSE) -> - | P28: =VLOOKUP(Tabla3[[#This Row],[Site]],Table35[#All],6,FALSE) -> 5 | Q28: =VLOOKUP(Tabla3[[#This Row],[Site]],Table35[#All],8,FALSE) -> 346
A29: =+Tabla3[[#This Row],[Site]]&Tabla3[[#This Row],[Split]] -> (AS) Larry H Miller CDJR Fiat (NO TOURS)1 | B29: 1 | C29: 1 | D29: (AS) Larry H Miller CDJR Fiat (NO TOURS) | E29: =VLOOKUP(Tabla3[[#This Row],[Site]],Table35[],10,FALSE) -> 11:00 P.M. | F29: =VLOOKUP(Tabla3[[#This Row],[Site]],Table35[],11,FALSE) -> MT | G29: =VLOOKUP(Tabla3[[#This Row],[Site]],Table35[],12,FALSE) -> 7:00 A.M. | H29: =HYPERLINK(VLOOKUP(Tabla3[[#This Row],[Site]],Table35[#All],9,FALSE)) -> https://tools.sig.systems/site/details/298 | I29: =VLOOKUP(Tabla3[[#This Row],[Site]],Table35[],13,FALSE) -> 0 | J29: =VLOOKUP(Tabla3[[#This Row],[Site]],Table35[],14,FALSE) -> - | L29: =VLOOKUP(Tabla3[[#This Row],[Site]],Table35[#All],2,FALSE) -> 7, 11 | M29: =VLOOKUP(Tabla3[[#This Row],[Site]],Table35[#All],3,FALSE) -> 2, 3 | N29: =VLOOKUP(Tabla3[[#This Row],[Site]],Table35[#All],4,FALSE) -> - | O29: =VLOOKUP(Tabla3[[#This Row],[Site]],Table35[#All],5,FALSE) -> - | P29: =VLOOKUP(Tabla3[[#This Row],[Site]],Table35[#All],6,FALSE) -> 2, 6, 10, 15, 18 | Q29: =VLOOKUP(Tabla3[[#This Row],[Site]],Table35[#All],8,FALSE) -> 298
A30: =+Tabla3[[#This Row],[Site]]&Tabla3[[#This Row],[Split]] -> (AS) Plaza Collision ST Louis (NO TOURS)1 | B30: 1 | C30: 1 | D30: (AS) Plaza Collision ST Louis (NO TOURS) | E30: =VLOOKUP(Tabla3[[#This Row],[Site]],Table35[],10,FALSE) -> 10:00 P.M. | F30: =VLOOKUP(Tabla3[[#This Row],[Site]],Table35[],11,FALSE) -> CT | G30: =VLOOKUP(Tabla3[[#This Row],[Site]],Table35[],12,FALSE) -> 6:00 A.M. | H30: =HYPERLINK(VLOOKUP(Tabla3[[#This Row],[Site]],Table35[#All],9,FALSE)) -> https://tools.sig.systems/site/details/350 | I30: =VLOOKUP(Tabla3[[#This Row],[Site]],Table35[],13,FALSE) -> - | J30: =VLOOKUP(Tabla3[[#This Row],[Site]],Table35[],14,FALSE) -> - | L30: =VLOOKUP(Tabla3[[#This Row],[Site]],Table35[#All],2,FALSE) -> 2, 6 | M30: =VLOOKUP(Tabla3[[#This Row],[Site]],Table35[#All],3,FALSE) -> 1 | N30: =VLOOKUP(Tabla3[[#This Row],[Site]],Table35[#All],4,FALSE) -> - | O30: =VLOOKUP(Tabla3[[#This Row],[Site]],Table35[#All],5,FALSE) -> - | P30: =VLOOKUP(Tabla3[[#This Row],[Site]],Table35[#All],6,FALSE) -> 3 | Q30: =VLOOKUP(Tabla3[[#This Row],[Site]],Table35[#All],8,FALSE) -> 350
A31: =+Tabla3[[#This Row],[Site]]&Tabla3[[#This Row],[Split]] -> (AS) Plaza Mercedes Benz West (NO TOURS)1 | B31: 1 | C31: 1 | D31: (AS) Plaza Mercedes Benz West (NO TOURS) | E31: =VLOOKUP(Tabla3[[#This Row],[Site]],Table35[],10,FALSE) -> 10:00 P.M. | F31: =VLOOKUP(Tabla3[[#This Row],[Site]],Table35[],11,FALSE) -> CT | G31: =VLOOKUP(Tabla3[[#This Row],[Site]],Table35[],12,FALSE) -> 6:00 A.M. | H31: =HYPERLINK(VLOOKUP(Tabla3[[#This Row],[Site]],Table35[#All],9,FALSE)) -> https://tools.sig.systems/site/details/349 | I31: =VLOOKUP(Tabla3[[#This Row],[Site]],Table35[],13,FALSE) -> 0 | J31: =VLOOKUP(Tabla3[[#This Row],[Site]],Table35[],14,FALSE) -> - | L31: =VLOOKUP(Tabla3[[#This Row],[Site]],Table35[#All],2,FALSE) -> - | M31: =VLOOKUP(Tabla3[[#This Row],[Site]],Table35[#All],3,FALSE) -> 1, 7 | N31: =VLOOKUP(Tabla3[[#This Row],[Site]],Table35[#All],4,FALSE) -> - | O31: =VLOOKUP(Tabla3[[#This Row],[Site]],Table35[#All],5,FALSE) -> 17 | P31: =VLOOKUP(Tabla3[[#This Row],[Site]],Table35[#All],6,FALSE) -> 6, 21 | Q31: =VLOOKUP(Tabla3[[#This Row],[Site]],Table35[#All],8,FALSE) -> 349
A32: =+Tabla3[[#This Row],[Site]]&Tabla3[[#This Row],[Split]] -> (BRL) Fort Pierce1 | B32: 1 | C32: 1 | D32: (BRL) Fort Pierce | E32: =VLOOKUP(Tabla3[[#This Row],[Site]],Table35[],10,FALSE) -> 24H | F32: =VLOOKUP(Tabla3[[#This Row],[Site]],Table35[],11,FALSE) -> ET | G32: =VLOOKUP(Tabla3[[#This Row],[Site]],Table35[],12,FALSE) -> - | H32: =HYPERLINK(VLOOKUP(Tabla3[[#This Row],[Site]],Table35[#All],9,FALSE)) -> https://tools.sig.systems/site/details/326 | I32: =VLOOKUP(Tabla3[[#This Row],[Site]],Table35[],13,FALSE) -> - | J32: =VLOOKUP(Tabla3[[#This Row],[Site]],Table35[],14,FALSE) -> - | L32: =VLOOKUP(Tabla3[[#This Row],[Site]],Table35[#All],2,FALSE) -> - | M32: =VLOOKUP(Tabla3[[#This Row],[Site]],Table35[#All],3,FALSE) -> 1 | N32: =VLOOKUP(Tabla3[[#This Row],[Site]],Table35[#All],4,FALSE) -> - | O32: =VLOOKUP(Tabla3[[#This Row],[Site]],Table35[#All],5,FALSE) -> 2 | P32: =VLOOKUP(Tabla3[[#This Row],[Site]],Table35[#All],6,FALSE) -> 15, 18 | Q32: =VLOOKUP(Tabla3[[#This Row],[Site]],Table35[#All],8,FALSE) -> 326
A33: =+Tabla3[[#This Row],[Site]]&Tabla3[[#This Row],[Split]] -> (BRL) Shoemakersville1 | B33: 1 | C33: 1 | D33: (BRL) Shoemakersville | E33: =VLOOKUP(Tabla3[[#This Row],[Site]],Table35[],10,FALSE) -> 24H | F33: =VLOOKUP(Tabla3[[#This Row],[Site]],Table35[],11,FALSE) -> ET | G33: =VLOOKUP(Tabla3[[#This Row],[Site]],Table35[],12,FALSE) -> - | H33: =HYPERLINK(VLOOKUP(Tabla3[[#This Row],[Site]],Table35[#All],9,FALSE)) -> https://tools.sig.systems/site/details/302 | I33: =VLOOKUP(Tabla3[[#This Row],[Site]],Table35[],13,FALSE) -> 0 | J33: =VLOOKUP(Tabla3[[#This Row],[Site]],Table35[],14,FALSE) -> - | L33: =VLOOKUP(Tabla3[[#This Row],[Site]],Table35[#All],2,FALSE) -> - | M33: =VLOOKUP(Tabla3[[#This Row],[Site]],Table35[#All],3,FALSE) -> 8, 11 | N33: =VLOOKUP(Tabla3[[#This Row],[Site]],Table35[#All],4,FALSE) -> - | O33: =VLOOKUP(Tabla3[[#This Row],[Site]],Table35[#All],5,FALSE) -> 1, 6, 13A, 15, 18A | P33: =VLOOKUP(Tabla3[[#This Row],[Site]],Table35[#All],6,FALSE) -> 13B, 23 | Q33: =VLOOKUP(Tabla3[[#This Row],[Site]],Table35[#All],8,FALSE) -> 302
A34: =+Tabla3[[#This Row],[Site]]&Tabla3[[#This Row],[Split]] -> (DT) Arlington1 | B34: 1 | C34: 1 | D34: (DT) Arlington | E34: =VLOOKUP(Tabla3[[#This Row],[Site]],Table35[],10,FALSE) -> 10:00 P.M. | F34: =VLOOKUP(Tabla3[[#This Row],[Site]],Table35[],11,FALSE) -> CT | G34: =VLOOKUP(Tabla3[[#This Row],[Site]],Table35[],12,FALSE) -> 6:00 A.M. | H34: =HYPERLINK(VLOOKUP(Tabla3[[#This Row],[Site]],Table35[#All],9,FALSE)) -> https://tools.sig.systems/site/details/199 | I34: =VLOOKUP(Tabla3[[#This Row],[Site]],Table35[],13,FALSE) -> 0 | J34: =VLOOKUP(Tabla3[[#This Row],[Site]],Table35[],14,FALSE) -> - | L34: =VLOOKUP(Tabla3[[#This Row],[Site]],Table35[#All],2,FALSE) -> 8 | M34: =VLOOKUP(Tabla3[[#This Row],[Site]],Table35[#All],3,FALSE) -> 3 | N34: =VLOOKUP(Tabla3[[#This Row],[Site]],Table35[#All],4,FALSE) -> - | O34: =VLOOKUP(Tabla3[[#This Row],[Site]],Table35[#All],5,FALSE) -> - | P34: =VLOOKUP(Tabla3[[#This Row],[Site]],Table35[#All],6,FALSE) -> 3, 8, 9 | Q34: 334
A35: =+Tabla3[[#This Row],[Site]]&Tabla3[[#This Row],[Split]] -> (DT) Charlotte1 | B35: 1 | C35: 1 | D35: (DT) Charlotte | E35: =VLOOKUP(Tabla3[[#This Row],[Site]],Table35[],10,FALSE) -> 9:00 P.M. | F35: =VLOOKUP(Tabla3[[#This Row],[Site]],Table35[],11,FALSE) -> ET | G35: =VLOOKUP(Tabla3[[#This Row],[Site]],Table35[],12,FALSE) -> 5:00 A.M. | H35: =HYPERLINK(VLOOKUP(Tabla3[[#This Row],[Site]],Table35[#All],9,FALSE)) -> https://tools.sig.systems/site/details/299 | I35: =VLOOKUP(Tabla3[[#This Row],[Site]],Table35[],13,FALSE) -> 0 | J35: =VLOOKUP(Tabla3[[#This Row],[Site]],Table35[],14,FALSE) -> - | L35: =VLOOKUP(Tabla3[[#This Row],[Site]],Table35[#All],2,FALSE) -> 4, 25, 41 | M35: =VLOOKUP(Tabla3[[#This Row],[Site]],Table35[#All],3,FALSE) -> - | N35: =VLOOKUP(Tabla3[[#This Row],[Site]],Table35[#All],4,FALSE) -> - | O35: =VLOOKUP(Tabla3[[#This Row],[Site]],Table35[#All],5,FALSE) -> 11, 32, 35 | P35: =VLOOKUP(Tabla3[[#This Row],[Site]],Table35[#All],6,FALSE) -> 6, 11, 18, 29, 34, 38, 39 | Q35: =VLOOKUP(Tabla3[[#This Row],[Site]],Table35[#All],8,FALSE) -> 299
A36: =+Tabla3[[#This Row],[Site]]&Tabla3[[#This Row],[Split]] -> (DT) Modesto1 | B36: 1 | C36: 1 | D36: (DT) Modesto | E36: =VLOOKUP(Tabla3[[#This Row],[Site]],Table35[],10,FALSE) -> 12:00 A.M. | F36: =VLOOKUP(Tabla3[[#This Row],[Site]],Table35[],11,FALSE) -> PT | G36: =VLOOKUP(Tabla3[[#This Row],[Site]],Table35[],12,FALSE) -> 8:00 A.M. | H36: =HYPERLINK(VLOOKUP(Tabla3[[#This Row],[Site]],Table35[#All],9,FALSE)) -> https://tools.sig.systems/site/details/267 | I36: =VLOOKUP(Tabla3[[#This Row],[Site]],Table35[],13,FALSE) -> 0 | J36: =VLOOKUP(Tabla3[[#This Row],[Site]],Table35[],14,FALSE) -> - | L36: =VLOOKUP(Tabla3[[#This Row],[Site]],Table35[#All],2,FALSE) -> 10 | M36: =VLOOKUP(Tabla3[[#This Row],[Site]],Table35[#All],3,FALSE) -> 5, 6 | N36: =VLOOKUP(Tabla3[[#This Row],[Site]],Table35[#All],4,FALSE) -> - | O36: =VLOOKUP(Tabla3[[#This Row],[Site]],Table35[#All],5,FALSE) -> - | P36: =VLOOKUP(Tabla3[[#This Row],[Site]],Table35[#All],6,FALSE) -> 2, 3, 5, 10 | Q36: =VLOOKUP(Tabla3[[#This Row],[Site]],Table35[#All],8,FALSE) -> 267
A37: =+Tabla3[[#This Row],[Site]]&Tabla3[[#This Row],[Split]] -> (KG) Big Star Cadillac1 | B37: 1 | C37: 1 | D37: (KG) Big Star Cadillac | E37: =VLOOKUP(Tabla3[[#This Row],[Site]],Table35[],10,FALSE) -> 10:00 P.M. | F37: =VLOOKUP(Tabla3[[#This Row],[Site]],Table35[],11,FALSE) -> CT | G37: =VLOOKUP(Tabla3[[#This Row],[Site]],Table35[],12,FALSE) -> 6:00 A.M. | H37: =HYPERLINK(VLOOKUP(Tabla3[[#This Row],[Site]],Table35[#All],9,FALSE)) -> https://tools.sig.systems/site/details/316 | I37: =VLOOKUP(Tabla3[[#This Row],[Site]],Table35[],13,FALSE) -> https://www.google.com/maps/d/edit?mid=1jIRkMUnWNPuTgDjQgDP-f33LClT85NU&usp=sharing | J37: =VLOOKUP(Tabla3[[#This Row],[Site]],Table35[],14,FALSE) -> - | L37: =VLOOKUP(Tabla3[[#This Row],[Site]],Table35[#All],2,FALSE) -> 1, 4, 16 | M37: =VLOOKUP(Tabla3[[#This Row],[Site]],Table35[#All],3,FALSE) -> - | N37: =VLOOKUP(Tabla3[[#This Row],[Site]],Table35[#All],4,FALSE) -> - | O37: =VLOOKUP(Tabla3[[#This Row],[Site]],Table35[#All],5,FALSE) -> - | P37: =VLOOKUP(Tabla3[[#This Row],[Site]],Table35[#All],6,FALSE) -> 15, 16, 19, 20 | Q37: =VLOOKUP(Tabla3[[#This Row],[Site]],Table35[#All],8,FALSE) -> 316
A38: =+Tabla3[[#This Row],[Site]]&Tabla3[[#This Row],[Split]] -> (KG) Big Star Hyundai Houston1 | B38: 1 | C38: 1 | D38: (KG) Big Star Hyundai Houston | E38: =VLOOKUP(Tabla3[[#This Row],[Site]],Table35[],10,FALSE) -> 10:00 P.M. | F38: =VLOOKUP(Tabla3[[#This Row],[Site]],Table35[],11,FALSE) -> CT | G38: =VLOOKUP(Tabla3[[#This Row],[Site]],Table35[],12,FALSE) -> 6:00 A.M. | H38: =HYPERLINK(VLOOKUP(Tabla3[[#This Row],[Site]],Table35[#All],9,FALSE)) -> https://tools.sig.systems/site/details/287 | I38: =VLOOKUP(Tabla3[[#This Row],[Site]],Table35[],13,FALSE) -> https://www.google.com/maps/d/edit?hl=en&mid=1jIRkMUnWNPuTgDjQgDP-f33LClT85NU&ll=29.55731827236326%2C-95.1601644&z=17 | J38: =VLOOKUP(Tabla3[[#This Row],[Site]],Table35[],14,FALSE) -> - | L38: 3, 12, 17 | M38: 23, 35 | N38: - | O38: 1, 75 | P38: 5, 11, 16, 20, 26, 30, 32, 34 | Q38: 287
A39: =+Tabla3[[#This Row],[Site]]&Tabla3[[#This Row],[Split]] -> (KG) Ken Garff Kia of Avondale1 | B39: 1 | C39: 1 | D39: (KG) Ken Garff Kia of Avondale | E39: =VLOOKUP(Tabla3[[#This Row],[Site]],Table35[],10,FALSE) -> 12:00 A.M. | F39: =VLOOKUP(Tabla3[[#This Row],[Site]],Table35[],11,FALSE) -> MST | G39: =VLOOKUP(Tabla3[[#This Row],[Site]],Table35[],12,FALSE) -> 8:00 A.M. | H39: =HYPERLINK(VLOOKUP(Tabla3[[#This Row],[Site]],Table35[#All],9,FALSE)) -> https://tools.sig.systems/site/details/283 | I39: =VLOOKUP(Tabla3[[#This Row],[Site]],Table35[],13,FALSE) -> https://www.google.com/maps/d/viewer?mid=1bDs0QGFZwL3vEeGKxjVMk_j4azr0-lg&ll=33.4593758581648%2C-112.28793780000001&z=18 | J39: =VLOOKUP(Tabla3[[#This Row],[Site]],Table35[],14,FALSE) -> 12:00 P.M. | L39: =VLOOKUP(Tabla3[[#This Row],[Site]],Table35[#All],2,FALSE) -> 5, 19 | M39: =VLOOKUP(Tabla3[[#This Row],[Site]],Table35[#All],3,FALSE) -> - | N39: =VLOOKUP(Tabla3[[#This Row],[Site]],Table35[#All],4,FALSE) -> - | O39: =VLOOKUP(Tabla3[[#This Row],[Site]],Table35[#All],5,FALSE) -> 3, 5 | P39: =VLOOKUP(Tabla3[[#This Row],[Site]],Table35[#All],6,FALSE) -> 1, 6, 7, 12, 15, 17, 21 | Q39: =VLOOKUP(Tabla3[[#This Row],[Site]],Table35[#All],8,FALSE) -> 283
A40: =+Tabla3[[#This Row],[Site]]&Tabla3[[#This Row],[Split]] -> (KG) Ken Garff Volkswagen of Gilbert1 | B40: 1 | C40: 1 | D40: (KG) Ken Garff Volkswagen of Gilbert | E40: =VLOOKUP(Tabla3[[#This Row],[Site]],Table35[],10,FALSE) -> 12:00 A.M. | F40: =VLOOKUP(Tabla3[[#This Row],[Site]],Table35[],11,FALSE) -> MST | G40: =VLOOKUP(Tabla3[[#This Row],[Site]],Table35[],12,FALSE) -> 8:00 A.M. | H40: =HYPERLINK(VLOOKUP(Tabla3[[#This Row],[Site]],Table35[#All],9,FALSE)) -> https://tools.sig.systems/site/details/284 | I40: =VLOOKUP(Tabla3[[#This Row],[Site]],Table35[],13,FALSE) -> https://www.google.com/maps/d/viewer?hl=es&mid=19SU7XE9Cg8jhVFpEI21Vi9Zfgdih9Ds&ll=33.29158262977276%2C-111.75783630000002&z=17 | J40: =VLOOKUP(Tabla3[[#This Row],[Site]],Table35[],14,FALSE) -> 12:00 P.M. | L40: =VLOOKUP(Tabla3[[#This Row],[Site]],Table35[#All],2,FALSE) -> 4, 6 | M40: =VLOOKUP(Tabla3[[#This Row],[Site]],Table35[#All],3,FALSE) -> - | N40: =VLOOKUP(Tabla3[[#This Row],[Site]],Table35[#All],4,FALSE) -> - | O40: =VLOOKUP(Tabla3[[#This Row],[Site]],Table35[#All],5,FALSE) -> 2, 14 | P40: =VLOOKUP(Tabla3[[#This Row],[Site]],Table35[#All],6,FALSE) -> 1, 5, 8, 9, 17, 19, 21 | Q40: =VLOOKUP(Tabla3[[#This Row],[Site]],Table35[#All],8,FALSE) -> 284
...

Sheet Important Info!
A1: SITES | B1: GATES | C1: ENTRANCES | D1: LPR GATES | E1: PTZ | F1: IMPORTANT CAMERAS | G1: BLIND SPOTS | H1: ID | I1: SIG TOOLS | J1: HOUR | K1: TIME | L1: DROP TIME | M1: MAP | N1: SUNDAY D.T.
